Workbook

Sheet history
A1: snapshot_date | B1: snapshot_ts | C1: carrier | D1: category | E1: state | F1: plan_name | G1: plan_id | H1: price_brl | I1: price_promo_brl | J1: price_note | K1: payment_method | L1: data_gb | M1: data_note | N1: validity_days | O1: unlimited_apps | P1: voice | Q1: sms | R1: streaming | S1: loyalty_months | T1: extra_benefits | U1: source_url | V1: raw_ref
A2: 2026-06-22 | B2: 2026-06-22T22:45:24 | C2: claro | D2: control | E2: SP | F2: Controle 25GB | G2: claro:plano-controle-25gb | H2: 59.9 | I2: 54.9 | J2: De R$ 59,90 Por: | L2: 25 | O2: WhatsApp | T2: Para uso livre; Para redes sociais e vídeos; Bônus exclusivo; Aproveite na sua franquia; WhatsApp e ligações ilimitadas | U2: https://www.claro.com.br/celular/controle | V2: data/raw/claro_control_SP.json
A3: 2026-06-22 | B3: 2026-06-22T22:45:24 | C3: claro | D3: control | E3: SP | F3: Controle 30GB | G3: claro:plano-controle-30gb | H3: 69.9 | L3: 30 | O3: WhatsApp | T3: Para uso livre; Bônus do Hexa para uso livre; Bônus para redes sociais e apps; Redes sociais e apps; WhatsApp ilimitado | U3: https://www.claro.com.br/celular/controle | V3: data/raw/claro_control_SP.json
A4: 2026-06-22 | B4: 2026-06-22T22:45:24 | C4: claro | D4: control | E4: SP | F4: Controle 30GB | G4: claro:plano-controle-30gb-gaming | H4: 99.9 | L4: 30 | O4: WhatsApp | T4: Para uso livre; Bônus para redes sociais e apps; Bônus uso livre; Redes sociais e apps; WhatsApp ilimitado | U4: https://www.claro.com.br/celular/controle | V4: data/raw/claro_control_SP.json
A5: 2026-06-22 | B5: 2026-06-22T22:45:24 | C5: claro | D5: flex | E5: SP | F5: Flex 15GB | G5: claro:plano-flex-15gb | H5: 44.9 | L5: 15 | O5: WhatsApp | T5: Para uso livre; Bônus do Hexa para uso livre; Para redes sociais e apps; Bônus extra nos apps; WhatsApp ilimitado | U5: https://www.claro.com.br/celular/flex | V5: data/raw/claro_flex_SP.json
A6: 2026-06-22 | B6: 2026-06-22T22:45:24 | C6: claro | D6: flex | E6: SP | F6: Flex 20GB | G6: claro:plano-flex-20gb | H6: 59.9 | L6: 20 | O6: WhatsApp | T6: Para uso livre; Bônus do Hexa para uso livre; Para redes sociais e apps; Bônus extra nos apps; WhatsApp ilimitado | U6: https://www.claro.com.br/celular/flex | V6: data/raw/claro_flex_SP.json
A7: 2026-06-22 | B7: 2026-06-22T22:45:24 | C7: claro | D7: flex | E7: SP | F7: Flex 30GB | G7: claro:plano-flex-30gb | H7: 69.9 | L7: 30 | O7: WhatsApp | T7: Para uso livre; Bônus do Hexa para uso livre; Para redes sociais e apps; Bônus extra nos apps; WhatsApp ilimitado; Assinatura Claro musica inclusa | U7: https://www.claro.com.br/celular/flex | V7: data/raw/claro_flex_SP.json
A8: 2026-06-22 | B8: 2026-06-22T22:45:24 | C8: claro | D8: flex | E8: SP | F8: Flex 40GB | G8: claro:plano-flex-40gb | H8: 119.9 | L8: 40 | O8: WhatsApp | T8: Para uso livre; Para redes sociais e apps; Bônus uso livre; Bônus extra nos apps; WhatsApp ilimitado; Assinatura Claro musica inclusa | U8: https://www.claro.com.br/celular/flex | V8: data/raw/claro_flex_SP.json
A9: 2026-06-22 | B9: 2026-06-22T22:45:24 | C9: claro | D9: postpaid | E9: SP | F9: Pós 100GB | G9: claro:plano-pos-100gb | H9: 179.9 | L9: 100 | O9: WhatsApp | T9: Armazenamento na nuvem:; Google One ou iCloud+; WhatsApp ilimitado; Roaming: Passaporte Américas; Claro Sync: Smartwatch conectado | U9: https://www.claro.com.br/celular/pos | V9: data/raw/claro_postpaid_SP.json
A10: 2026-06-22 | B10: 2026-06-22T22:45:24 | C10: claro | D10: postpaid | E10: SP | F10: Pós 150GB | G10: claro:plano-pos-150gb | H10: 239.9 | L10: 150 | O10: WhatsApp | T10: Armazenamento na nuvem:; Google One ou iCloud+; WhatsApp ilimitado; Roaming: Passaporte Américas e Europa; Claro Sync: Smartwatch conectado | U10: https://www.claro.com.br/celular/pos | V10: data/raw/claro_postpaid_SP.json
A11: 2026-06-22 | B11: 2026-06-22T22:45:24 | C11: claro | D11: postpaid | E11: SP | F11: Pós 200GB | G11: claro:plano-pos-200gb | H11: 339.9 | L11: 200 | O11: WhatsApp | T11: Armazenamento na nuvem:; Google One ou iCloud+; WhatsApp ilimitado; Roaming: Passaporte Mundo; Claro Sync: Smartwatch conectado | U11: https://www.claro.com.br/celular/pos | V11: data/raw/claro_postpaid_SP.json
A12: 2026-06-22 | B12: 2026-06-22T22:45:24 | C12: claro | D12: postpaid | E12: SP | F12: Pós 50GB com GeForce NOW | G12: claro:plano-pos-60gb-geforce | H12: 164.9 | L12: 50 | O12: WhatsApp | T12: Armazenamento na nuvem:; Google One ou iCloud+; WhatsApp ilimitado; Roaming: Passaporte Américas; Claro Sync: Smartwatch conectado; Inclusa assinatura GeForce NOW | U12: https://www.claro.com.br/celular/pos | V12: data/raw/claro_postpaid_SP.json
A13: 2026-06-22 | B13: 2026-06-22T22:45:24 | C13: claro | D13: postpaid | E13: SP | F13: Pós 60GB | G13: claro:plano-pos-60gb | H13: 124.9 | L13: 60 | O13: WhatsApp | T13: Armazenamento na nuvem:; Google One ou iCloud+; WhatsApp ilimitado; Roaming: Passaporte Américas; Claro Sync: Smartwatch conectado | U13: https://www.claro.com.br/celular/pos | V13: data/raw/claro_postpaid_SP.json
A14: 2026-06-22 | B14: 2026-06-22T22:45:24 | C14: claro | D14: prepaid | E14: SP | F14: Prezão R$1 por dia | G14: claro:prez-o-r-1-por-dia | H14: 1 | J14: prepaid Prezão — preço por dia; recargas a partir de R$15 | L14: 12 | U14: https://www.claro.com.br/celular/planos-pre/prezao | V14: data/raw/claro_prepaid_SP.json
A15: 2026-06-22 | B15: 2026-06-22T22:45:24 | C15: tim | D15: control | E15: SP | F15: TIM Controle 41GB | G15: tim:162901 | H15: 58.99 | L15: 41 | U15: https://www.tim.com.br/sp/para-voce/planos/controle | V15: data/raw/tim_control_SP.html
A16: 2026-06-22 | B16: 2026-06-22T22:45:24 | C16: tim | D16: control | E16: SP | F16: TIM Controle Light Express 31GB | G16: tim:143536 | H16: 60.99 | L16: 31 | U16: https://www.tim.com.br/sp/para-voce/planos/controle | V16: data/raw/tim_control_SP.html
A17: 2026-06-22 | B17: 2026-06-22T22:45:24 | C17: tim | D17: control | E17: SP | F17: TIM Controle Plus 45GB | G17: tim:155891 | H17: 64.99 | L17: 45 | U17: https://www.tim.com.br/sp/para-voce/planos/controle | V17: data/raw/tim_control_SP.html
A18: 2026-06-22 | B18: 2026-06-22T22:45:24 | C18: tim | D18: control | E18: SP | F18: TIM Controle Premium 53GB | G18: tim:162896 | H18: 84.99 | L18: 53 | U18: https://www.tim.com.br/sp/para-voce/planos/controle | V18: data/raw/tim_control_SP.html
A19: 2026-06-22 | B19: 2026-06-22T22:45:24 | C19: tim | D19: control | E19: SP | F19: TIM Controle Pro Express | G19: tim:143576 | H19: 64.99 | U19: https://www.tim.com.br/sp/para-voce/planos/controle | V19: data/raw/tim_control_SP.html
A20: 2026-06-22 | B20: 2026-06-22T22:45:24 | C20: tim | D20: postpaid | E20: SP | F20: TIM Black 70GB | G20: tim:54206 | H20: 129.99 | L20: 70 | U20: https://www.tim.com.br/sp/para-voce/planos/pos-pago/tim-black | V20: data/raw/tim_postpaid_SP.html
A21: 2026-06-22 | B21: 2026-06-22T22:45:24 | C21: tim | D21: postpaid | E21: SP | F21: TIM Black A Express 67GB | G21: tim:55121 | H21: 119.99 | L21: 67 | U21: https://www.tim.com.br/sp/para-voce/planos/pos-pago/tim-black | V21: data/raw/tim_postpaid_SP.html
A22: 2026-06-22 | B22: 2026-06-22T22:45:24 | C22: tim | D22: postpaid | E22: SP | F22: TIM Black B Express 82GB | G22: tim:52146 | H22: 144.99 | L22: 82 | U22: https://www.tim.com.br/sp/para-voce/planos/pos-pago/tim-black | V22: data/raw/tim_postpaid_SP.html
A23: 2026-06-22 | B23: 2026-06-22T22:45:24 | C23: tim | D23: postpaid | E23: SP | F23: TIM Black C Express 107GB | G23: tim:52151 | H23: 164.99 | L23: 107 | U23: https://www.tim.com.br/sp/para-voce/planos/pos-pago/tim-black | V23: data/raw/tim_postpaid_SP.html
A24: 2026-06-22 | B24: 2026-06-22T22:45:24 | C24: tim | D24: postpaid | E24: SP | F24: TIM Black C Ultra 95GB | G24: tim:100581 | H24: 159.99 | L24: 95 | U24: https://www.tim.com.br/sp/para-voce/planos/pos-pago/tim-black | V24: data/raw/tim_postpaid_SP.html
A25: 2026-06-22 | B25: 2026-06-22T22:45:24 | C25: tim | D25: postpaid | E25: SP | F25: TIM Black Plus 80GB | G25: tim:54256 | H25: 149.99 | L25: 80 | U25: https://www.tim.com.br/sp/para-voce/planos/pos-pago/tim-black | V25: data/raw/tim_postpaid_SP.html
A26: 2026-06-22 | B26: 2026-06-22T22:45:24 | C26: tim | D26: postpaid | E26: SP | F26: TIM Black Premium 110GB | G26: tim:54261 | H26: 159.99 | L26: 110 | U26: https://www.tim.com.br/sp/para-voce/planos/pos-pago/tim-black | V26: data/raw/tim_postpaid_SP.html
A27: 2026-06-22 | B27: 2026-06-22T22:45:24 | C27: tim | D27: prepaid | E27: SP | F27: TIM Pré XIP Plus 16GB | G27: tim:106306 | H27: 30 | L27: 16 | U27: https://www.tim.com.br/sp/para-voce/planos/pre-pago | V27: data/raw/tim_prepaid_SP.html
A28: 2026-06-22 | B28: 2026-06-22T22:45:24 | C28: tim | D28: prepaid | E28: SP | F28: TIM Pré XIP Plus 6GB | G28: tim:59906 | H28: 20 | L28: 6 | U28: https://www.tim.com.br/sp/para-voce/planos/pre-pago | V28: data/raw/tim_prepaid_SP.html
A29: 2026-06-22 | B29: 2026-06-22T22:45:24 | C29: tim | D29: prepaid | E29: SP | F29: TIM Pré XIP Plus 8GB | G29: tim:59901 | H29: 25 | L29: 8 | U29: https://www.tim.com.br/sp/para-voce/planos/pre-pago | V29: data/raw/tim_prepaid_SP.html
A30: 2026-06-22 | B30: 2026-06-22T22:45:24 | C30: vivo | D30: control | E30: SP | F30: Vivo Controle | G30: vivo:VIV202600029270-46gb | H30: 59 | L30: 46 | M30: 15 GB de franquia 31 GB de bônus | T30: 6 meses grátis de Gemini com AI Plus | U30: https://vivo.com.br/para-voce/produtos-e-servicos/para-o-celular/planos-controle | V30: data/raw/vivo_control_SP.html
A31: 2026-06-22 | B31: 2026-06-22T22:45:24 | C31: vivo | D31: control | E31: SP | F31: Vivo Controle | G31: vivo:VIV202600029300-61gb | H31: 80 | L31: 61 | M31: 20 GB de franquia 31 GB de bônus | T31: 6 meses grátis de Gemini com AI Plus | U31: https://vivo.com.br/para-voce/produtos-e-servicos/para-o-celular/planos-controle | V31: data/raw/vivo_control_SP.html
A32: 2026-06-22 | B32: 2026-06-22T22:45:24 | C32: vivo | D32: control | E32: SP | F32: Vivo Controle Educação | G32: vivo:VIV202600029273-61gb | H32: 90 | L32: 61 | M32: 20 GB de franquia 31 GB de bônus | T32: Assinatura Vivae inclusa | U32: https://vivo.com.br/para-voce/produtos-e-servicos/para-o-celular/planos-controle | V32: data/raw/vivo_control_SP.html
A33: 2026-06-22 | B33: 2026-06-22T22:45:24 | C33: vivo | D33: control | E33: SP | F33: Vivo Controle Entretenimento | G33: vivo:VIV202600029307-61gb | H33: 110 | L33: 61 | M33: 20 GB de franquia 31 GB de bônus | T33: Assinatura Vivo TV Inicial inclusa | U33: https://vivo.com.br/para-voce/produtos-e-servicos/para-o-celular/planos-controle | V33: data/raw/vivo_control_SP.html
A34: 2026-06-22 | B34: 2026-06-22T22:45:24 | C34: vivo | D34: control | E34: SP | F34: Vivo Controle Música | G34: vivo:VIV202600029313-61gb | H34: 95 | L34: 61 | M34: 20 GB de franquia 31 GB de bônus | T34: Apple Music Individual | U34: https://vivo.com.br/para-voce/produtos-e-servicos/para-o-celular/planos-controle | V34: data/raw/vivo_control_SP.html
A35: 2026-06-22 | B35: 2026-06-22T22:45:24 | C35: vivo | D35: control | E35: SP | F35: Vivo Controle Netflix | G35: vivo:VIV202600029308-61gb | H35: 95 | L35: 61 | M35: 20 GB de franquia 31 GB de bônus | T35: Assinatura Netflix Padrão com anúncios | U35: https://vivo.com.br/para-voce/produtos-e-servicos/para-o-celular/planos-controle | V35: data/raw/vivo_control_SP.html
A36: 2026-06-22 | B36: 2026-06-22T22:45:24 | C36: vivo | D36: control | E36: SP | F36: Vivo Controle Saúde | G36: vivo:VIV202600029301-61gb | H36: 90 | L36: 61 | M36: 20 GB de franquia 31 GB de bônus | T36: Assinatura Vale Saúde Sempre inclusa | U36: https://vivo.com.br/para-voce/produtos-e-servicos/para-o-celular/planos-controle | V36: data/raw/vivo_control_SP.html
A37: 2026-06-22 | B37: 2026-06-22T22:45:24 | C37: vivo | D37: lite | E37: SP | F37: Easy Lite | G37: vivo:VIV202600005312-30gb | H37: 30 | L37: 30 | M37: 30 GB de franquia 2 Meses de YouTube ilimitado | U37: https://vivo.com.br/para-voce/produtos-e-servicos/para-o-celular/easy-lite | V37: data/raw/vivo_lite_SP.html
A38: 2026-06-22 | B38: 2026-06-22T22:45:24 | C38: vivo | D38: lite | E38: SP | F38: Easy Lite | G38: vivo:VIV202600019134-40gb | H38: 40 | L38: 40 | M38: 40 GB de franquia 2 Meses de YouTube ilimitado | U38: https://vivo.com.br/para-voce/produtos-e-servicos/para-o-celular/easy-lite | V38: data/raw/vivo_lite_SP.html
A39: 2026-06-22 | B39: 2026-06-22T22:45:24 | C39: vivo | D39: lite | E39: SP | F39: Easy Lite | G39: vivo:VIV202600019132-20gb | H39: 35 | L39: 20 | M39: 20 GB de franquia 2 Meses de YouTube ilimitado | U39: https://vivo.com.br/para-voce/produtos-e-servicos/para-o-celular/easy-lite | V39: data/raw/vivo_lite_SP.html
A40: 2026-06-22 | B40: 2026-06-22T22:45:24 | C40: vivo | D40: lite | E40: SP | F40: Easy Lite | G40: vivo:VIV202600019127-30gb | H40: 40 | L40: 30 | U40: https://vivo.com.br/para-voce/produtos-e-servicos/para-o-celular/easy-lite | V40: data/raw/vivo_lite_SP.html
...

Sheet latest
A1: snapshot_date | B1: snapshot_ts | C1: carrier | D1: category | E1: state | F1: plan_name | G1: plan_id | H1: price_brl | I1: price_promo_brl | J1: price_note | K1: payment_method | L1: data_gb | M1: data_note | N1: validity_days | O1: unlimited_apps | P1: voice | Q1: sms | R1: streaming | S1: loyalty_months | T1: extra_benefits | U1: source_url | V1: raw_ref
A2: 2026-07-13 | B2: 2026-07-13T14:56:28 | C2: claro | D2: control | E2: SP | F2: Controle 25GB | G2: claro:plano-controle-25gb | H2: 59.9 | I2: 54.9 | J2: De R$ 59,90 Por: | L2: 25 | O2: WhatsApp | T2: Para uso livre; Para redes sociais e vídeos; Bônus exclusivo; Aproveite na sua franquia; WhatsApp e ligações ilimitadas | U2: https://www.claro.com.br/celular/controle | V2: data/raw/claro_control_SP.json
A3: 2026-07-13 | B3: 2026-07-13T14:56:28 | C3: claro | D3: control | E3: SP | F3: Controle 30GB | G3: claro:plano-controle-30gb | H3: 69.9 | L3: 30 | O3: WhatsApp | T3: Para uso livre; Bônus especial para uso livre; Bônus para redes sociais e apps; Redes sociais e apps; WhatsApp ilimitado | U3: https://www.claro.com.br/celular/controle | V3: data/raw/claro_control_SP.json
A4: 2026-07-13 | B4: 2026-07-13T14:56:28 | C4: claro | D4: control | E4: SP | F4: Controle 30GB | G4: claro:plano-controle-30gb-gaming | H4: 99.9 | L4: 30 | O4: WhatsApp | T4: Para uso livre; Bônus para redes sociais e apps; Bônus uso livre; Redes sociais e apps; WhatsApp ilimitado | U4: https://www.claro.com.br/celular/controle | V4: data/raw/claro_control_SP.json
A5: 2026-07-13 | B5: 2026-07-13T14:56:28 | C5: claro | D5: flex | E5: SP | F5: Flex 15GB | G5: claro:plano-flex-15gb | H5: 44.9 | L5: 15 | O5: WhatsApp | T5: Para uso livre; Bônus especial para uso livre; Para redes sociais e apps; Bônus extra nos apps; WhatsApp ilimitado | U5: https://www.claro.com.br/celular/flex | V5: data/raw/claro_flex_SP.json
A6: 2026-07-13 | B6: 2026-07-13T14:56:28 | C6: claro | D6: flex | E6: SP | F6: Flex 20GB | G6: claro:plano-flex-20gb | H6: 59.9 | L6: 20 | O6: WhatsApp | T6: Para uso livre; Bônus especial para uso livre; Para redes sociais e apps; Bônus extra nos apps; WhatsApp ilimitado | U6: https://www.claro.com.br/celular/flex | V6: data/raw/claro_flex_SP.json
A7: 2026-07-13 | B7: 2026-07-13T14:56:28 | C7: claro | D7: flex | E7: SP | F7: Flex 30GB | G7: claro:plano-flex-30gb | H7: 69.9 | L7: 30 | O7: WhatsApp | T7: Para uso livre; Bônus especial para uso livre; Para redes sociais e apps; Bônus extra nos apps; WhatsApp ilimitado; Assinatura Claro musica inclusa | U7: https://www.claro.com.br/celular/flex | V7: data/raw/claro_flex_SP.json
A8: 2026-07-13 | B8: 2026-07-13T14:56:28 | C8: claro | D8: flex | E8: SP | F8: Flex 40GB | G8: claro:plano-flex-40gb | H8: 119.9 | L8: 40 | O8: WhatsApp | T8: Para uso livre; Para redes sociais e apps; Bônus uso livre; Bônus extra nos apps; WhatsApp ilimitado; Assinatura Claro musica inclusa | U8: https://www.claro.com.br/celular/flex | V8: data/raw/claro_flex_SP.json
A9: 2026-07-13 | B9: 2026-07-13T14:56:28 | C9: claro | D9: postpaid | E9: SP | F9: Pós 100GB | G9: claro:plano-pos-100gb | H9: 179.9 | L9: 100 | O9: WhatsApp | T9: Armazenamento na nuvem:; Google One ou iCloud+; WhatsApp ilimitado; Roaming: Passaporte Américas; Claro Sync: Smartwatch conectado | U9: https://www.claro.com.br/celular/pos | V9: data/raw/claro_postpaid_SP.json
A10: 2026-07-13 | B10: 2026-07-13T14:56:28 | C10: claro | D10: postpaid | E10: SP | F10: Pós 150GB | G10: claro:plano-pos-150gb | H10: 239.9 | L10: 150 | O10: WhatsApp | T10: Armazenamento na nuvem:; Google One ou iCloud+; WhatsApp ilimitado; Roaming: Passaporte Américas e Europa; Claro Sync: Smartwatch conectado | U10: https://www.claro.com.br/celular/pos | V10: data/raw/claro_postpaid_SP.json
A11: 2026-07-13 | B11: 2026-07-13T14:56:28 | C11: claro | D11: postpaid | E11: SP | F11: Pós 200GB | G11: claro:plano-pos-200gb | H11: 339.9 | L11: 200 | O11: WhatsApp | T11: Armazenamento na nuvem:; Google One ou iCloud+; WhatsApp ilimitado; Roaming: Passaporte Mundo; Claro Sync: Smartwatch conectado | U11: https://www.claro.com.br/celular/pos | V11: data/raw/claro_postpaid_SP.json
A12: 2026-07-13 | B12: 2026-07-13T14:56:28 | C12: claro | D12: postpaid | E12: SP | F12: Pós 50GB com GeForce NOW | G12: claro:plano-pos-60gb-geforce | H12: 164.9 | L12: 50 | O12: WhatsApp | T12: Armazenamento na nuvem:; Google One ou iCloud+; WhatsApp ilimitado; Roaming: Passaporte Américas; Claro Sync: Smartwatch conectado; Inclusa assinatura GeForce NOW | U12: https://www.claro.com.br/celular/pos | V12: data/raw/claro_postpaid_SP.json
A13: 2026-07-13 | B13: 2026-07-13T14:56:28 | C13: claro | D13: postpaid | E13: SP | F13: Pós 60GB | G13: claro:plano-pos-60gb | H13: 124.9 | L13: 60 | O13: WhatsApp | T13: Armazenamento na nuvem:; Google One ou iCloud+; WhatsApp ilimitado; Roaming: Passaporte Américas; Claro Sync: Smartwatch conectado | U13: https://www.claro.com.br/celular/pos | V13: data/raw/claro_postpaid_SP.json
A14: 2026-07-13 | B14: 2026-07-13T14:56:28 | C14: claro | D14: prepaid | E14: SP | F14: Prezão 10GB (25 dias) | G14: claro:prezao-25d-10gb | H14: 25 | J14: recarga Prezão R$25 — validade 25 dias | L14: 10 | N14: 25 | U14: https://www.claro.com.br/celular/planos-pre/prezao | V14: data/raw/claro_prepaid_SP.json
A15: 2026-07-13 | B15: 2026-07-13T14:56:28 | C15: claro | D15: prepaid | E15: SP | F15: Prezão 12GB (30 dias) | G15: claro:prezao-30d-12gb | H15: 30 | J15: recarga Prezão R$30 — validade 30 dias | L15: 12 | N15: 30 | U15: https://www.claro.com.br/celular/planos-pre/prezao | V15: data/raw/claro_prepaid_SP.json
A16: 2026-07-13 | B16: 2026-07-13T14:56:28 | C16: claro | D16: prepaid | E16: SP | F16: Prezão 4GB (12 dias) | G16: claro:prezao-12d-4gb | H16: 15 | J16: recarga Prezão R$15 — validade 12 dias | L16: 4 | N16: 12 | U16: https://www.claro.com.br/celular/planos-pre/prezao | V16: data/raw/claro_prepaid_SP.json
A17: 2026-07-13 | B17: 2026-07-13T14:56:28 | C17: claro | D17: prepaid | E17: SP | F17: Prezão 5GB (15 dias) | G17: claro:prezao-15d-5gb | H17: 15 | J17: recarga Prezão R$15 — validade 15 dias | L17: 5 | N17: 15 | U17: https://www.claro.com.br/celular/planos-pre/prezao | V17: data/raw/claro_prepaid_SP.json
A18: 2026-07-13 | B18: 2026-07-13T14:56:28 | C18: claro | D18: prepaid | E18: SP | F18: Prezão 6GB (20 dias) | G18: claro:prezao-20d-6gb | H18: 20 | J18: recarga Prezão R$20 — validade 20 dias | L18: 6 | N18: 20 | U18: https://www.claro.com.br/celular/planos-pre/prezao | V18: data/raw/claro_prepaid_SP.json
A19: 2026-07-13 | B19: 2026-07-13T14:56:28 | C19: claro | D19: prepaid | E19: SP | F19: Prezão 8GB (20 dias) | G19: claro:prezao-20d-8gb | H19: 20 | J19: recarga Prezão R$20 — validade 20 dias | L19: 8 | N19: 20 | U19: https://www.claro.com.br/celular/planos-pre/prezao | V19: data/raw/claro_prepaid_SP.json
A20: 2026-07-13 | B20: 2026-07-13T14:56:28 | C20: claro | D20: prepaid | E20: SP | F20: Prezão 9GB (25 dias) | G20: claro:prezao-25d-9gb | H20: 25 | J20: recarga Prezão R$25 — validade 25 dias | L20: 9 | N20: 25 | U20: https://www.claro.com.br/celular/planos-pre/prezao | V20: data/raw/claro_prepaid_SP.json
A21: 2026-07-13 | B21: 2026-07-13T14:56:28 | C21: tim | D21: control | E21: SP | F21: TIM Controle 41GB | G21: tim:167036 | H21: 49.99 | L21: 41 | U21: https://www.tim.com.br/sp/para-voce/planos/controle | V21: data/raw/tim_control_SP.html
A22: 2026-07-13 | B22: 2026-07-13T14:56:28 | C22: tim | D22: control | E22: SP | F22: TIM Controle Light Express 31GB | G22: tim:167046 | H22: 60.99 | L22: 31 | U22: https://www.tim.com.br/sp/para-voce/planos/controle | V22: data/raw/tim_control_SP.html
A23: 2026-07-13 | B23: 2026-07-13T14:56:28 | C23: tim | D23: control | E23: SP | F23: TIM Controle Plus 45GB | G23: tim:167031 | H23: 59.99 | L23: 45 | U23: https://www.tim.com.br/sp/para-voce/planos/controle | V23: data/raw/tim_control_SP.html
A24: 2026-07-13 | B24: 2026-07-13T14:56:28 | C24: tim | D24: control | E24: SP | F24: TIM Controle Premium 53GB | G24: tim:167041 | H24: 69.99 | L24: 53 | U24: https://www.tim.com.br/sp/para-voce/planos/controle | V24: data/raw/tim_control_SP.html
A25: 2026-07-13 | B25: 2026-07-13T14:56:28 | C25: tim | D25: control | E25: SP | F25: TIM Controle Pro Express | G25: tim:167051 | H25: 64.99 | U25: https://www.tim.com.br/sp/para-voce/planos/controle | V25: data/raw/tim_control_SP.html
A26: 2026-07-13 | B26: 2026-07-13T14:56:28 | C26: tim | D26: fit | E26: SP | F26: TIM Controle Fit Anual | G26: tim:TIM202600000271 | H26: 30 | J26: plano anual 12x no cartão de crédito; prazo de permanência 12m | K26: credit_card | L26: 30 | S26: 12 | U26: https://www.tim.com.br/sp/para-voce/planos/controle | V26: data/raw/tim_fit_SP.html
A27: 2026-07-13 | B27: 2026-07-13T14:56:28 | C27: tim | D27: fit | E27: SP | F27: TIM Controle Fit Mensal | G27: tim:TIM202600000270 | H27: 35 | J27: plano mensal, sem prazo de permanência | L27: 20 | U27: https://www.tim.com.br/sp/para-voce/planos/controle | V27: data/raw/tim_fit_SP.html
A28: 2026-07-13 | B28: 2026-07-13T14:56:28 | C28: tim | D28: postpaid | E28: SP | F28: TIM Black 70GB | G28: tim:54206 | H28: 129.99 | K28: bill | L28: 70 | U28: https://www.tim.com.br/sp/para-voce/planos/pos-pago/tim-black | V28: data/raw/tim_postpaid_SP.html
A29: 2026-07-13 | B29: 2026-07-13T14:56:28 | C29: tim | D29: postpaid | E29: SP | F29: TIM Black A Express 67GB | G29: tim:55121 | H29: 119.99 | K29: credit_card | L29: 67 | U29: https://www.tim.com.br/sp/para-voce/planos/pos-pago/tim-black | V29: data/raw/tim_postpaid_SP.html
A30: 2026-07-13 | B30: 2026-07-13T14:56:28 | C30: tim | D30: postpaid | E30: SP | F30: TIM Black B Express 82GB | G30: tim:52146 | H30: 144.99 | K30: credit_card | L30: 82 | U30: https://www.tim.com.br/sp/para-voce/planos/pos-pago/tim-black | V30: data/raw/tim_postpaid_SP.html
A31: 2026-07-13 | B31: 2026-07-13T14:56:28 | C31: tim | D31: postpaid | E31: SP | F31: TIM Black C Express 107GB | G31: tim:52151 | H31: 164.99 | K31: credit_card | L31: 107 | U31: https://www.tim.com.br/sp/para-voce/planos/pos-pago/tim-black | V31: data/raw/tim_postpaid_SP.html
A32: 2026-07-13 | B32: 2026-07-13T14:56:28 | C32: tim | D32: postpaid | E32: SP | F32: TIM Black C Ultra 95GB | G32: tim:100581 | H32: 159.99 | K32: bill | L32: 95 | U32: https://www.tim.com.br/sp/para-voce/planos/pos-pago/tim-black | V32: data/raw/tim_postpaid_SP.html
A33: 2026-07-13 | B33: 2026-07-13T14:56:28 | C33: tim | D33: postpaid | E33: SP | F33: TIM Black Plus 80GB | G33: tim:54256 | H33: 149.99 | K33: bill | L33: 80 | U33: https://www.tim.com.br/sp/para-voce/planos/pos-pago/tim-black | V33: data/raw/tim_postpaid_SP.html
A34: 2026-07-13 | B34: 2026-07-13T14:56:28 | C34: tim | D34: postpaid | E34: SP | F34: TIM Black Premium 110GB | G34: tim:54261 | H34: 159.99 | K34: bill | L34: 110 | U34: https://www.tim.com.br/sp/para-voce/planos/pos-pago/tim-black | V34: data/raw/tim_postpaid_SP.html
A35: 2026-07-13 | B35: 2026-07-13T14:56:28 | C35: tim | D35: prepaid | E35: SP | F35: TIM Pré XIP Plus 16GB | G35: tim:106306 | H35: 30 | L35: 16 | N35: 30 | U35: https://www.tim.com.br/sp/para-voce/planos/pre-pago | V35: data/raw/tim_prepaid_SP.html
A36: 2026-07-13 | B36: 2026-07-13T14:56:28 | C36: tim | D36: prepaid | E36: SP | F36: TIM Pré XIP Plus 6GB | G36: tim:59906 | H36: 20 | L36: 6 | N36: 17 | U36: https://www.tim.com.br/sp/para-voce/planos/pre-pago | V36: data/raw/tim_prepaid_SP.html
A37: 2026-07-13 | B37: 2026-07-13T14:56:28 | C37: tim | D37: prepaid | E37: SP | F37: TIM Pré XIP Plus 8GB | G37: tim:59901 | H37: 25 | L37: 8 | N37: 22 | U37: https://www.tim.com.br/sp/para-voce/planos/pre-pago | V37: data/raw/tim_prepaid_SP.html
A38: 2026-07-13 | B38: 2026-07-13T14:56:28 | C38: vivo | D38: control | E38: SP | F38: Vivo Controle | G38: vivo:VIV202600029270-46gb | H38: 59 | L38: 46 | M38: 15 GB de franquia 31 GB de bônus | T38: 2 meses de YouTube sem consumo no plano | U38: https://vivo.com.br/para-voce/produtos-e-servicos/para-o-celular/planos-controle | V38: data/raw/vivo_control_SP.html
A39: 2026-07-13 | B39: 2026-07-13T14:56:28 | C39: vivo | D39: control | E39: SP | F39: Vivo Controle | G39: vivo:VIV202600029300-61gb | H39: 80 | L39: 61 | M39: 20 GB de franquia 31 GB de bônus | T39: 2 meses de YouTube sem consumo no plano | U39: https://vivo.com.br/para-voce/produtos-e-servicos/para-o-celular/planos-controle | V39: data/raw/vivo_control_SP.html
A40: 2026-07-13 | B40: 2026-07-13T14:56:28 | C40: vivo | D40: control | E40: SP | F40: Vivo Controle Educação | G40: vivo:VIV202600029273-61gb | H40: 90 | L40: 61 | M40: 20 GB de franquia 31 GB de bônus | T40: Assinatura Vivae inclusa | U40: https://vivo.com.br/para-voce/produtos-e-servicos/para-o-celular/planos-controle | V40: data/raw/vivo_control_SP.html
...

Sheet changes
A1: change_type | B1: carrier | C1: category | D1: state | E1: plan_id | F1: plan_name | G1: old_price_brl | H1: new_price_brl | I1: delta_brl
A2: new | B2: tim | C2: fit | D2: SP | E2: tim:TIM202600000270 | F2: TIM Controle Fit Mensal | H2: 35
A3: new | B3: tim | C3: fit | D3: SP | E3: tim:TIM202600000271 | F3: TIM Controle Fit Anual | H3: 30
A4: price_change | B4: vivo | C4: control | D4: SP | E4: vivo:VIV202600029273-61gb | F4: Vivo Controle Educação | G4: 85 | H4: 90 | I4: 5
A5: price_change | B5: vivo | C5: control | D5: SP | E5: vivo:VIV202600029300-61gb | F5: Vivo Controle | G5: 75 | H5: 80 | I5: 5
A6: price_change | B6: vivo | C6: control | D6: SP | E6: vivo:VIV202600029301-61gb | F6: Vivo Controle Saúde | G6: 85 | H6: 90 | I6: 5
A7: price_change | B7: vivo | C7: control | D7: SP | E7: vivo:VIV202600029307-61gb | F7: Vivo Controle Entretenimento | G7: 105 | H7: 110 | I7: 5
A8: price_change | B8: vivo | C8: control | D8: SP | E8: vivo:VIV202600029308-61gb | F8: Vivo Controle Netflix | G8: 90 | H8: 95 | I8: 5
A9: price_change | B9: vivo | C9: control | D9: SP | E9: vivo:VIV202600029313-61gb | F9: Vivo Controle Música | G9: 85 | H9: 90 | I9: 5
A10: price_change | B10: vivo | C10: lite | D10: SP | E10: vivo:VIV202600032594-30gb | F10: Easy Lite | G10: 30 | H10: 45 | I10: 15
A11: price_change | B11: vivo | C11: lite | D11: SP | E11: vivo:VIV202600032596-40gb | F11: Easy Lite | G11: 40 | H11: 55 | I11: 15

Sheet summary
A1: Mobile Price Tracker — Summary
A3: Run timestamp | B3: 2026-07-13T14:56:28
A4: Latest snapshot | B4: 2026-07-13
A5: Plans in latest | B5: 57
A6: Snapshots in history | B6: 22
A8: carrier | B8: # plans | C8: min price | D8: avg price | E8: max price
A9: vivo | B9: =COUNTIF(latest!$C$2:$C$2000,$A$9) -> 21 | C9: =IFERROR(_xlfn.MINIFS(latest!$H$2:$H$2000,latest!$C$2:$C$2000,$A$9),"-") -> 17 | D9: =IFERROR(AVERAGEIFS(latest!$H$2:$H$2000,latest!$C$2:$C$2000,$A$9),"-") -> 98.86 | E9: =IFERROR(_xlfn.MAXIFS(latest!$H$2:$H$2000,latest!$C$2:$C$2000,$A$9),"-") -> 215
A10: claro | B10: =COUNTIF(latest!$C$2:$C$2000,$A$10) -> 19 | C10: =IFERROR(_xlfn.MINIFS(latest!$H$2:$H$2000,latest!$C$2:$C$2000,$A$10),"-") -> 15 | D10: =IFERROR(AVERAGEIFS(latest!$H$2:$H$2000,latest!$C$2:$C$2000,$A$10),"-") -> 90.73 | E10: =IFERROR(_xlfn.MAXIFS(latest!$H$2:$H$2000,latest!$C$2:$C$2000,$A$10),"-") -> 339.9
A11: tim | B11: =COUNTIF(latest!$C$2:$C$2000,$A$11) -> 17 | C11: =IFERROR(_xlfn.MINIFS(latest!$H$2:$H$2000,latest!$C$2:$C$2000,$A$11),"-") -> 20 | D11: =IFERROR(AVERAGEIFS(latest!$H$2:$H$2000,latest!$C$2:$C$2000,$A$11),"-") -> 86.82 | E11: =IFERROR(_xlfn.MAXIFS(latest!$H$2:$H$2000,latest!$C$2:$C$2000,$A$11),"-") -> 164.99

Sheet comparison
A1: Date | B1: Control (R$/mo) | E1: Post (R$/mo) | H1: Pre (R$/mo, 30-day) | K1: Digital (R$/mo)
B2: TIM | C2: Vivo | D2: Claro | E2: TIM | F2: Vivo | G2: Claro | H2: TIM | I2: Vivo | J2: Claro | K2: TIM | L2: Vivo | M2: Claro
A3: 46195 | B3: =IFERROR(IF(_xlfn.MINIFS(history!$H:$H,history!$C:$C,"tim",history!$D:$D,"control",history!$A:$A,YEAR($A3)&"-"&TEXT(MONTH($A3),"00")&"-"&TEXT(DAY($A3),"00"))=0,"",_xlfn.MINIFS(history!$H:$H,history!$C:$C,"tim",history!$D:$D,"control",history!$A:$A,YEAR($A3)&"-"&TEXT(MONTH($A3),"00")&"-"&TEXT(DAY($A3),"00"))),"") -> 58.99 | C3: =IFERROR(IF(_xlfn.MINIFS(history!$H:$H,history!$C:$C,"vivo",history!$D:$D,"control",history!$A:$A,YEAR($A3)&"-"&TEXT(MONTH($A3),"00")&"-"&TEXT(DAY($A3),"00"))=0,"",_xlfn.MINIFS(history!$H:$H,history!$C:$C,"vivo",history!$D:$D,"control",history!$A:$A,YEAR($A3)&"-"&TEXT(MONTH($A3),"00")&"-"&TEXT(DAY($A3),"00"))),"") -> 59 | D3: =IFERROR(IF(_xlfn.MINIFS(history!$H:$H,history!$C:$C,"claro",history!$D:$D,"control",history!$A:$A,YEAR($A3)&"-"&TEXT(MONTH($A3),"00")&"-"&TEXT(DAY($A3),"00"))=0,"",_xlfn.MINIFS(history!$H:$H,history!$C:$C,"claro",history!$D:$D,"control",history!$A:$A,YEAR($A3)&"-"&TEXT(MONTH($A3),"00")&"-"&TEXT(DAY($A3),"00"))),"") -> 59.9 | E3: =IFERROR(IF(_xlfn.MINIFS(history!$H:$H,history!$C:$C,"tim",history!$D:$D,"postpaid",history!$A:$A,YEAR($A3)&"-"&TEXT(MONTH($A3),"00")&"-"&TEXT(DAY($A3),"00"))=0,"",_xlfn.MINIFS(history!$H:$H,history!$C:$C,"tim",history!$D:$D,"postpaid",history!$A:$A,YEAR($A3)&"-"&TEXT(MONTH($A3),"00")&"-"&TEXT(DAY($A3),"00"))),"") -> 119.99 | F3: =IFERROR(IF(_xlfn.MINIFS(history!$H:$H,history!$C:$C,"vivo",history!$D:$D,"postpaid",history!$A:$A,YEAR($A3)&"-"&TEXT(MONTH($A3),"00")&"-"&TEXT(DAY($A3),"00"))=0,"",_xlfn.MINIFS(history!$H:$H,history!$C:$C,"vivo",history!$D:$D,"postpaid",history!$A:$A,YEAR($A3)&"-"&TEXT(MONTH($A3),"00")&"-"&TEXT(DAY($A3),"00"))),"") -> 150 | G3: =IFERROR(IF(_xlfn.MINIFS(history!$H:$H,history!$C:$C,"claro",history!$D:$D,"postpaid",history!$A:$A,YEAR($A3)&"-"&TEXT(MONTH($A3),"00")&"-"&TEXT(DAY($A3),"00"))=0,"",_xlfn.MINIFS(history!$H:$H,history!$C:$C,"claro",history!$D:$D,"postpaid",history!$A:$A,YEAR($A3)&"-"&TEXT(MONTH($A3),"00")&"-"&TEXT(DAY($A3),"00"))),"") -> 124.9 | H3: =IFERROR(IF(_xlfn.MINIFS(history!$H:$H,history!$C:$C,"tim",history!$D:$D,"prepaid",history!$A:$A,YEAR($A3)&"-"&TEXT(MONTH($A3),"00")&"-"&TEXT(DAY($A3),"00"),history!$N:$N,">=28")=0,"",_xlfn.MINIFS(history!$H:$H,history!$C:$C,"tim",history!$D:$D,"prepaid",history!$A:$A,YEAR($A3)&"-"&TEXT(MONTH($A3),"00")&"-"&TEXT(DAY($A3),"00"),history!$N:$N,">=28")),"") | I3: =IFERROR(IF(_xlfn.MINIFS(history!$H:$H,history!$C:$C,"vivo",history!$D:$D,"prepaid",history!$A:$A,YEAR($A3)&"-"&TEXT(MONTH($A3),"00")&"-"&TEXT(DAY($A3),"00"),history!$N:$N,">=28")=0,"",_xlfn.MINIFS(history!$H:$H,history!$C:$C,"vivo",history!$D:$D,"prepaid",history!$A:$A,YEAR($A3)&"-"&TEXT(MONTH($A3),"00")&"-"&TEXT(DAY($A3),"00"),history!$N:$N,">=28")),"") | J3: =IFERROR(IF(_xlfn.MINIFS(history!$H:$H,history!$C:$C,"claro",history!$D:$D,"prepaid",history!$A:$A,YEAR($A3)&"-"&TEXT(MONTH($A3),"00")&"-"&TEXT(DAY($A3),"00"),history!$N:$N,">=28")=0,"",_xlfn.MINIFS(history!$H:$H,history!$C:$C,"claro",history!$D:$D,"prepaid",history!$A:$A,YEAR($A3)&"-"&TEXT(MONTH($A3),"00")&"-"&TEXT(DAY($A3),"00"),history!$N:$N,">=28")),"") | K3: =IFERROR(1/MAX(IFERROR(1/_xlfn.MINIFS(history!$H:$H,history!$C:$C,"tim",history!$D:$D,"lite",history!$A:$A,YEAR($A3)&"-"&TEXT(MONTH($A3),"00")&"-"&TEXT(DAY($A3),"00"),history!$S:$S,">0"),0),IFERROR(1/_xlfn.MINIFS(history!$H:$H,history!$C:$C,"tim",history!$D:$D,"flex",history!$A:$A,YEAR($A3)&"-"&TEXT(MONTH($A3),"00")&"-"&TEXT(DAY($A3),"00")),0),IFERROR(1/_xlfn.MINIFS(history!$H:$H,history!$C:$C,"tim",history!$D:$D,"fit",history!$A:$A,YEAR($A3)&"-"&TEXT(MONTH($A3),"00")&"-"&TEXT(DAY($A3),"00"),history!$S:$S,"="),0)),"") | L3: =IFERROR(1/MAX(IFERROR(1/_xlfn.MINIFS(history!$H:$H,history!$C:$C,"vivo",history!$D:$D,"lite",history!$A:$A,YEAR($A3)&"-"&TEXT(MONTH($A3),"00")&"-"&TEXT(DAY($A3),"00"),history!$S:$S,">0"),0),IFERROR(1/_xlfn.MINIFS(history!$H:$H,history!$C:$C,"vivo",history!$D:$D,"flex",history!$A:$A,YEAR($A3)&"-"&TEXT(MONTH($A3),"00")&"-"&TEXT(DAY($A3),"00")),0),IFERROR(1/_xlfn.MINIFS(history!$H:$H,history!$C:$C,"vivo",history!$D:$D,"fit",history!$A:$A,YEAR($A3)&"-"&TEXT(MONTH($A3),"00")&"-"&TEXT(DAY($A3),"00"),history!$S:$S,"="),0)),"") | M3: =IFERROR(1/MAX(IFERROR(1/_xlfn.MINIFS(history!$H:$H,history!$C:$C,"claro",history!$D:$D,"lite",history!$A:$A,YEAR($A3)&"-"&TEXT(MONTH($A3),"00")&"-"&TEXT(DAY($A3),"00"),history!$S:$S,">0"),0),IFERROR(1/_xlfn.MINIFS(history!$H:$H,history!$C:$C,"claro",history!$D:$D,"flex",history!$A:$A,YEAR($A3)&"-"&TEXT(MONTH($A3),"00")&"-"&TEXT(DAY($A3),"00")),0),IFERROR(1/_xlfn.MINIFS(history!$H:$H,history!$C:$C,"claro",history!$D:$D,"fit",history!$A:$A,YEAR($A3)&"-"&TEXT(MONTH($A3),"00")&"-"&TEXT(DAY($A3),"00"),history!$S:$S,"="),0)),"") -> 44.9
A4: 46196 | B4: =IFERROR(IF(_xlfn.MINIFS(history!$H:$H,history!$C:$C,"tim",history!$D:$D,"control",history!$A:$A,YEAR($A4)&"-"&TEXT(MONTH($A4),"00")&"-"&TEXT(DAY($A4),"00"))=0,"",_xlfn.MINIFS(history!$H:$H,history!$C:$C,"tim",history!$D:$D,"control",history!$A:$A,YEAR($A4)&"-"&TEXT(MONTH($A4),"00")&"-"&TEXT(DAY($A4),"00"))),"") -> 58.99 | C4: =IFERROR(IF(_xlfn.MINIFS(history!$H:$H,history!$C:$C,"vivo",history!$D:$D,"control",history!$A:$A,YEAR($A4)&"-"&TEXT(MONTH($A4),"00")&"-"&TEXT(DAY($A4),"00"))=0,"",_xlfn.MINIFS(history!$H:$H,history!$C:$C,"vivo",history!$D:$D,"control",history!$A:$A,YEAR($A4)&"-"&TEXT(MONTH($A4),"00")&"-"&TEXT(DAY($A4),"00"))),"") -> 59 | D4: =IFERROR(IF(_xlfn.MINIFS(history!$H:$H,history!$C:$C,"claro",history!$D:$D,"control",history!$A:$A,YEAR($A4)&"-"&TEXT(MONTH($A4),"00")&"-"&TEXT(DAY($A4),"00"))=0,"",_xlfn.MINIFS(history!$H:$H,history!$C:$C,"claro",history!$D:$D,"control",history!$A:$A,YEAR($A4)&"-"&TEXT(MONTH($A4),"00")&"-"&TEXT(DAY($A4),"00"))),"") -> 59.9 | E4: =IFERROR(IF(_xlfn.MINIFS(history!$H:$H,history!$C:$C,"tim",history!$D:$D,"postpaid",history!$A:$A,YEAR($A4)&"-"&TEXT(MONTH($A4),"00")&"-"&TEXT(DAY($A4),"00"))=0,"",_xlfn.MINIFS(history!$H:$H,history!$C:$C,"tim",history!$D:$D,"postpaid",history!$A:$A,YEAR($A4)&"-"&TEXT(MONTH($A4),"00")&"-"&TEXT(DAY($A4),"00"))),"") -> 119.99 | F4: =IFERROR(IF(_xlfn.MINIFS(history!$H:$H,history!$C:$C,"vivo",history!$D:$D,"postpaid",history!$A:$A,YEAR($A4)&"-"&TEXT(MONTH($A4),"00")&"-"&TEXT(DAY($A4),"00"))=0,"",_xlfn.MINIFS(history!$H:$H,history!$C:$C,"vivo",history!$D:$D,"postpaid",history!$A:$A,YEAR($A4)&"-"&TEXT(MONTH($A4),"00")&"-"&TEXT(DAY($A4),"00"))),"") -> 150 | G4: =IFERROR(IF(_xlfn.MINIFS(history!$H:$H,history!$C:$C,"claro",history!$D:$D,"postpaid",history!$A:$A,YEAR($A4)&"-"&TEXT(MONTH($A4),"00")&"-"&TEXT(DAY($A4),"00"))=0,"",_xlfn.MINIFS(history!$H:$H,history!$C:$C,"claro",history!$D:$D,"postpaid",history!$A:$A,YEAR($A4)&"-"&TEXT(MONTH($A4),"00")&"-"&TEXT(DAY($A4),"00"))),"") -> 124.9 | H4: =IFERROR(IF(_xlfn.MINIFS(history!$H:$H,history!$C:$C,"tim",history!$D:$D,"prepaid",history!$A:$A,YEAR($A4)&"-"&TEXT(MONTH($A4),"00")&"-"&TEXT(DAY($A4),"00"),history!$N:$N,">=28")=0,"",_xlfn.MINIFS(history!$H:$H,history!$C:$C,"tim",history!$D:$D,"prepaid",history!$A:$A,YEAR($A4)&"-"&TEXT(MONTH($A4),"00")&"-"&TEXT(DAY($A4),"00"),history!$N:$N,">=28")),"") | I4: =IFERROR(IF(_xlfn.MINIFS(history!$H:$H,history!$C:$C,"vivo",history!$D:$D,"prepaid",history!$A:$A,YEAR($A4)&"-"&TEXT(MONTH($A4),"00")&"-"&TEXT(DAY($A4),"00"),history!$N:$N,">=28")=0,"",_xlfn.MINIFS(history!$H:$H,history!$C:$C,"vivo",history!$D:$D,"prepaid",history!$A:$A,YEAR($A4)&"-"&TEXT(MONTH($A4),"00")&"-"&TEXT(DAY($A4),"00"),history!$N:$N,">=28")),"") | J4: =IFERROR(IF(_xlfn.MINIFS(history!$H:$H,history!$C:$C,"claro",history!$D:$D,"prepaid",history!$A:$A,YEAR($A4)&"-"&TEXT(MONTH($A4),"00")&"-"&TEXT(DAY($A4),"00"),history!$N:$N,">=28")=0,"",_xlfn.MINIFS(history!$H:$H,history!$C:$C,"claro",history!$D:$D,"prepaid",history!$A:$A,YEAR($A4)&"-"&TEXT(MONTH($A4),"00")&"-"&TEXT(DAY($A4),"00"),history!$N:$N,">=28")),"") | K4: =IFERROR(1/MAX(IFERROR(1/_xlfn.MINIFS(history!$H:$H,history!$C:$C,"tim",history!$D:$D,"lite",history!$A:$A,YEAR($A4)&"-"&TEXT(MONTH($A4),"00")&"-"&TEXT(DAY($A4),"00"),history!$S:$S,">0"),0),IFERROR(1/_xlfn.MINIFS(history!$H:$H,history!$C:$C,"tim",history!$D:$D,"flex",history!$A:$A,YEAR($A4)&"-"&TEXT(MONTH($A4),"00")&"-"&TEXT(DAY($A4),"00")),0),IFERROR(1/_xlfn.MINIFS(history!$H:$H,history!$C:$C,"tim",history!$D:$D,"fit",history!$A:$A,YEAR($A4)&"-"&TEXT(MONTH($A4),"00")&"-"&TEXT(DAY($A4),"00"),history!$S:$S,"="),0)),"") | L4: =IFERROR(1/MAX(IFERROR(1/_xlfn.MINIFS(history!$H:$H,history!$C:$C,"vivo",history!$D:$D,"lite",history!$A:$A,YEAR($A4)&"-"&TEXT(MONTH($A4),"00")&"-"&TEXT(DAY($A4),"00"),history!$S:$S,">0"),0),IFERROR(1/_xlfn.MINIFS(history!$H:$H,history!$C:$C,"vivo",history!$D:$D,"flex",history!$A:$A,YEAR($A4)&"-"&TEXT(MONTH($A4),"00")&"-"&TEXT(DAY($A4),"00")),0),IFERROR(1/_xlfn.MINIFS(history!$H:$H,history!$C:$C,"vivo",history!$D:$D,"fit",history!$A:$A,YEAR($A4)&"-"&TEXT(MONTH($A4),"00")&"-"&TEXT(DAY($A4),"00"),history!$S:$S,"="),0)),"") | M4: =IFERROR(1/MAX(IFERROR(1/_xlfn.MINIFS(history!$H:$H,history!$C:$C,"claro",history!$D:$D,"lite",history!$A:$A,YEAR($A4)&"-"&TEXT(MONTH($A4),"00")&"-"&TEXT(DAY($A4),"00"),history!$S:$S,">0"),0),IFERROR(1/_xlfn.MINIFS(history!$H:$H,history!$C:$C,"claro",history!$D:$D,"flex",history!$A:$A,YEAR($A4)&"-"&TEXT(MONTH($A4),"00")&"-"&TEXT(DAY($A4),"00")),0),IFERROR(1/_xlfn.MINIFS(history!$H:$H,history!$C:$C,"claro",history!$D:$D,"fit",history!$A:$A,YEAR($A4)&"-"&TEXT(MONTH($A4),"00")&"-"&TEXT(DAY($A4),"00"),history!$S:$S,"="),0)),"") -> 44.9
A5: 46197 | B5: =IFERROR(IF(_xlfn.MINIFS(history!$H:$H,history!$C:$C,"tim",history!$D:$D,"control",history!$A:$A,YEAR($A5)&"-"&TEXT(MONTH($A5),"00")&"-"&TEXT(DAY($A5),"00"))=0,"",_xlfn.MINIFS(history!$H:$H,history!$C:$C,"tim",history!$D:$D,"control",history!$A:$A,YEAR($A5)&"-"&TEXT(MONTH($A5),"00")&"-"&TEXT(DAY($A5),"00"))),"") -> 58.99 | C5: =IFERROR(IF(_xlfn.MINIFS(history!$H:$H,history!$C:$C,"vivo",history!$D:$D,"control",history!$A:$A,YEAR($A5)&"-"&TEXT(MONTH($A5),"00")&"-"&TEXT(DAY($A5),"00"))=0,"",_xlfn.MINIFS(history!$H:$H,history!$C:$C,"vivo",history!$D:$D,"control",history!$A:$A,YEAR($A5)&"-"&TEXT(MONTH($A5),"00")&"-"&TEXT(DAY($A5),"00"))),"") -> 59 | D5: =IFERROR(IF(_xlfn.MINIFS(history!$H:$H,history!$C:$C,"claro",history!$D:$D,"control",history!$A:$A,YEAR($A5)&"-"&TEXT(MONTH($A5),"00")&"-"&TEXT(DAY($A5),"00"))=0,"",_xlfn.MINIFS(history!$H:$H,history!$C:$C,"claro",history!$D:$D,"control",history!$A:$A,YEAR($A5)&"-"&TEXT(MONTH($A5),"00")&"-"&TEXT(DAY($A5),"00"))),"") -> 59.9 | E5: =IFERROR(IF(_xlfn.MINIFS(history!$H:$H,history!$C:$C,"tim",history!$D:$D,"postpaid",history!$A:$A,YEAR($A5)&"-"&TEXT(MONTH($A5),"00")&"-"&TEXT(DAY($A5),"00"))=0,"",_xlfn.MINIFS(history!$H:$H,history!$C:$C,"tim",history!$D:$D,"postpaid",history!$A:$A,YEAR($A5)&"-"&TEXT(MONTH($A5),"00")&"-"&TEXT(DAY($A5),"00"))),"") -> 119.99 | F5: =IFERROR(IF(_xlfn.MINIFS(history!$H:$H,history!$C:$C,"vivo",history!$D:$D,"postpaid",history!$A:$A,YEAR($A5)&"-"&TEXT(MONTH($A5),"00")&"-"&TEXT(DAY($A5),"00"))=0,"",_xlfn.MINIFS(history!$H:$H,history!$C:$C,"vivo",history!$D:$D,"postpaid",history!$A:$A,YEAR($A5)&"-"&TEXT(MONTH($A5),"00")&"-"&TEXT(DAY($A5),"00"))),"") -> 150 | G5: =IFERROR(IF(_xlfn.MINIFS(history!$H:$H,history!$C:$C,"claro",history!$D:$D,"postpaid",history!$A:$A,YEAR($A5)&"-"&TEXT(MONTH($A5),"00")&"-"&TEXT(DAY($A5),"00"))=0,"",_xlfn.MINIFS(history!$H:$H,history!$C:$C,"claro",history!$D:$D,"postpaid",history!$A:$A,YEAR($A5)&"-"&TEXT(MONTH($A5),"00")&"-"&TEXT(DAY($A5),"00"))),"") -> 124.9 | H5: =IFERROR(IF(_xlfn.MINIFS(history!$H:$H,history!$C:$C,"tim",history!$D:$D,"prepaid",history!$A:$A,YEAR($A5)&"-"&TEXT(MONTH($A5),"00")&"-"&TEXT(DAY($A5),"00"),history!$N:$N,">=28")=0,"",_xlfn.MINIFS(history!$H:$H,history!$C:$C,"tim",history!$D:$D,"prepaid",history!$A:$A,YEAR($A5)&"-"&TEXT(MONTH($A5),"00")&"-"&TEXT(DAY($A5),"00"),history!$N:$N,">=28")),"") | I5: =IFERROR(IF(_xlfn.MINIFS(history!$H:$H,history!$C:$C,"vivo",history!$D:$D,"prepaid",history!$A:$A,YEAR($A5)&"-"&TEXT(MONTH($A5),"00")&"-"&TEXT(DAY($A5),"00"),history!$N:$N,">=28")=0,"",_xlfn.MINIFS(history!$H:$H,history!$C:$C,"vivo",history!$D:$D,"prepaid",history!$A:$A,YEAR($A5)&"-"&TEXT(MONTH($A5),"00")&"-"&TEXT(DAY($A5),"00"),history!$N:$N,">=28")),"") | J5: =IFERROR(IF(_xlfn.MINIFS(history!$H:$H,history!$C:$C,"claro",history!$D:$D,"prepaid",history!$A:$A,YEAR($A5)&"-"&TEXT(MONTH($A5),"00")&"-"&TEXT(DAY($A5),"00"),history!$N:$N,">=28")=0,"",_xlfn.MINIFS(history!$H:$H,history!$C:$C,"claro",history!$D:$D,"prepaid",history!$A:$A,YEAR($A5)&"-"&TEXT(MONTH($A5),"00")&"-"&TEXT(DAY($A5),"00"),history!$N:$N,">=28")),"") | K5: =IFERROR(1/MAX(IFERROR(1/_xlfn.MINIFS(history!$H:$H,history!$C:$C,"tim",history!$D:$D,"lite",history!$A:$A,YEAR($A5)&"-"&TEXT(MONTH($A5),"00")&"-"&TEXT(DAY($A5),"00"),history!$S:$S,">0"),0),IFERROR(1/_xlfn.MINIFS(history!$H:$H,history!$C:$C,"tim",history!$D:$D,"flex",history!$A:$A,YEAR($A5)&"-"&TEXT(MONTH($A5),"00")&"-"&TEXT(DAY($A5),"00")),0),IFERROR(1/_xlfn.MINIFS(history!$H:$H,history!$C:$C,"tim",history!$D:$D,"fit",history!$A:$A,YEAR($A5)&"-"&TEXT(MONTH($A5),"00")&"-"&TEXT(DAY($A5),"00"),history!$S:$S,"="),0)),"") | L5: =IFERROR(1/MAX(IFERROR(1/_xlfn.MINIFS(history!$H:$H,history!$C:$C,"vivo",history!$D:$D,"lite",history!$A:$A,YEAR($A5)&"-"&TEXT(MONTH($A5),"00")&"-"&TEXT(DAY($A5),"00"),history!$S:$S,">0"),0),IFERROR(1/_xlfn.MINIFS(history!$H:$H,history!$C:$C,"vivo",history!$D:$D,"flex",history!$A:$A,YEAR($A5)&"-"&TEXT(MONTH($A5),"00")&"-"&TEXT(DAY($A5),"00")),0),IFERROR(1/_xlfn.MINIFS(history!$H:$H,history!$C:$C,"vivo",history!$D:$D,"fit",history!$A:$A,YEAR($A5)&"-"&TEXT(MONTH($A5),"00")&"-"&TEXT(DAY($A5),"00"),history!$S:$S,"="),0)),"") | M5: =IFERROR(1/MAX(IFERROR(1/_xlfn.MINIFS(history!$H:$H,history!$C:$C,"claro",history!$D:$D,"lite",history!$A:$A,YEAR($A5)&"-"&TEXT(MONTH($A5),"00")&"-"&TEXT(DAY($A5),"00"),history!$S:$S,">0"),0),IFERROR(1/_xlfn.MINIFS(history!$H:$H,history!$C:$C,"claro",history!$D:$D,"flex",history!$A:$A,YEAR($A5)&"-"&TEXT(MONTH($A5),"00")&"-"&TEXT(DAY($A5),"00")),0),IFERROR(1/_xlfn.MINIFS(history!$H:$H,history!$C:$C,"claro",history!$D:$D,"fit",history!$A:$A,YEAR($A5)&"-"&TEXT(MONTH($A5),"00")&"-"&TEXT(DAY($A5),"00"),history!$S:$S,"="),0)),"") -> 44.9
A6: 46198 | B6: =IFERROR(IF(_xlfn.MINIFS(history!$H:$H,history!$C:$C,"tim",history!$D:$D,"control",history!$A:$A,YEAR($A6)&"-"&TEXT(MONTH($A6),"00")&"-"&TEXT(DAY($A6),"00"))=0,"",_xlfn.MINIFS(history!$H:$H,history!$C:$C,"tim",history!$D:$D,"control",history!$A:$A,YEAR($A6)&"-"&TEXT(MONTH($A6),"00")&"-"&TEXT(DAY($A6),"00"))),"") -> 58.99 | C6: =IFERROR(IF(_xlfn.MINIFS(history!$H:$H,history!$C:$C,"vivo",history!$D:$D,"control",history!$A:$A,YEAR($A6)&"-"&TEXT(MONTH($A6),"00")&"-"&TEXT(DAY($A6),"00"))=0,"",_xlfn.MINIFS(history!$H:$H,history!$C:$C,"vivo",history!$D:$D,"control",history!$A:$A,YEAR($A6)&"-"&TEXT(MONTH($A6),"00")&"-"&TEXT(DAY($A6),"00"))),"") -> 59 | D6: =IFERROR(IF(_xlfn.MINIFS(history!$H:$H,history!$C:$C,"claro",history!$D:$D,"control",history!$A:$A,YEAR($A6)&"-"&TEXT(MONTH($A6),"00")&"-"&TEXT(DAY($A6),"00"))=0,"",_xlfn.MINIFS(history!$H:$H,history!$C:$C,"claro",history!$D:$D,"control",history!$A:$A,YEAR($A6)&"-"&TEXT(MONTH($A6),"00")&"-"&TEXT(DAY($A6),"00"))),"") -> 59.9 | E6: =IFERROR(IF(_xlfn.MINIFS(history!$H:$H,history!$C:$C,"tim",history!$D:$D,"postpaid",history!$A:$A,YEAR($A6)&"-"&TEXT(MONTH($A6),"00")&"-"&TEXT(DAY($A6),"00"))=0,"",_xlfn.MINIFS(history!$H:$H,history!$C:$C,"tim",history!$D:$D,"postpaid",history!$A:$A,YEAR($A6)&"-"&TEXT(MONTH($A6),"00")&"-"&TEXT(DAY($A6),"00"))),"") -> 119.99 | F6: =IFERROR(IF(_xlfn.MINIFS(history!$H:$H,history!$C:$C,"vivo",history!$D:$D,"postpaid",history!$A:$A,YEAR($A6)&"-"&TEXT(MONTH($A6),"00")&"-"&TEXT(DAY($A6),"00"))=0,"",_xlfn.MINIFS(history!$H:$H,history!$C:$C,"vivo",history!$D:$D,"postpaid",history!$A:$A,YEAR($A6)&"-"&TEXT(MONTH($A6),"00")&"-"&TEXT(DAY($A6),"00"))),"") -> 150 | G6: =IFERROR(IF(_xlfn.MINIFS(history!$H:$H,history!$C:$C,"claro",history!$D:$D,"postpaid",history!$A:$A,YEAR($A6)&"-"&TEXT(MONTH($A6),"00")&"-"&TEXT(DAY($A6),"00"))=0,"",_xlfn.MINIFS(history!$H:$H,history!$C:$C,"claro",history!$D:$D,"postpaid",history!$A:$A,YEAR($A6)&"-"&TEXT(MONTH($A6),"00")&"-"&TEXT(DAY($A6),"00"))),"") -> 124.9 | H6: =IFERROR(IF(_xlfn.MINIFS(history!$H:$H,history!$C:$C,"tim",history!$D:$D,"prepaid",history!$A:$A,YEAR($A6)&"-"&TEXT(MONTH($A6),"00")&"-"&TEXT(DAY($A6),"00"),history!$N:$N,">=28")=0,"",_xlfn.MINIFS(history!$H:$H,history!$C:$C,"tim",history!$D:$D,"prepaid",history!$A:$A,YEAR($A6)&"-"&TEXT(MONTH($A6),"00")&"-"&TEXT(DAY($A6),"00"),history!$N:$N,">=28")),"") | I6: =IFERROR(IF(_xlfn.MINIFS(history!$H:$H,history!$C:$C,"vivo",history!$D:$D,"prepaid",history!$A:$A,YEAR($A6)&"-"&TEXT(MONTH($A6),"00")&"-"&TEXT(DAY($A6),"00"),history!$N:$N,">=28")=0,"",_xlfn.MINIFS(history!$H:$H,history!$C:$C,"vivo",history!$D:$D,"prepaid",history!$A:$A,YEAR($A6)&"-"&TEXT(MONTH($A6),"00")&"-"&TEXT(DAY($A6),"00"),history!$N:$N,">=28")),"") | J6: =IFERROR(IF(_xlfn.MINIFS(history!$H:$H,history!$C:$C,"claro",history!$D:$D,"prepaid",history!$A:$A,YEAR($A6)&"-"&TEXT(MONTH($A6),"00")&"-"&TEXT(DAY($A6),"00"),history!$N:$N,">=28")=0,"",_xlfn.MINIFS(history!$H:$H,history!$C:$C,"claro",history!$D:$D,"prepaid",history!$A:$A,YEAR($A6)&"-"&TEXT(MONTH($A6),"00")&"-"&TEXT(DAY($A6),"00"),history!$N:$N,">=28")),"") | K6: =IFERROR(1/MAX(IFERROR(1/_xlfn.MINIFS(history!$H:$H,history!$C:$C,"tim",history!$D:$D,"lite",history!$A:$A,YEAR($A6)&"-"&TEXT(MONTH($A6),"00")&"-"&TEXT(DAY($A6),"00"),history!$S:$S,">0"),0),IFERROR(1/_xlfn.MINIFS(history!$H:$H,history!$C:$C,"tim",history!$D:$D,"flex",history!$A:$A,YEAR($A6)&"-"&TEXT(MONTH($A6),"00")&"-"&TEXT(DAY($A6),"00")),0),IFERROR(1/_xlfn.MINIFS(history!$H:$H,history!$C:$C,"tim",history!$D:$D,"fit",history!$A:$A,YEAR($A6)&"-"&TEXT(MONTH($A6),"00")&"-"&TEXT(DAY($A6),"00"),history!$S:$S,"="),0)),"") | L6: =IFERROR(1/MAX(IFERROR(1/_xlfn.MINIFS(history!$H:$H,history!$C:$C,"vivo",history!$D:$D,"lite",history!$A:$A,YEAR($A6)&"-"&TEXT(MONTH($A6),"00")&"-"&TEXT(DAY($A6),"00"),history!$S:$S,">0"),0),IFERROR(1/_xlfn.MINIFS(history!$H:$H,history!$C:$C,"vivo",history!$D:$D,"flex",history!$A:$A,YEAR($A6)&"-"&TEXT(MONTH($A6),"00")&"-"&TEXT(DAY($A6),"00")),0),IFERROR(1/_xlfn.MINIFS(history!$H:$H,history!$C:$C,"vivo",history!$D:$D,"fit",history!$A:$A,YEAR($A6)&"-"&TEXT(MONTH($A6),"00")&"-"&TEXT(DAY($A6),"00"),history!$S:$S,"="),0)),"") | M6: =IFERROR(1/MAX(IFERROR(1/_xlfn.MINIFS(history!$H:$H,history!$C:$C,"claro",history!$D:$D,"lite",history!$A:$A,YEAR($A6)&"-"&TEXT(MONTH($A6),"00")&"-"&TEXT(DAY($A6),"00"),history!$S:$S,">0"),0),IFERROR(1/_xlfn.MINIFS(history!$H:$H,history!$C:$C,"claro",history!$D:$D,"flex",history!$A:$A,YEAR($A6)&"-"&TEXT(MONTH($A6),"00")&"-"&TEXT(DAY($A6),"00")),0),IFERROR(1/_xlfn.MINIFS(history!$H:$H,history!$C:$C,"claro",history!$D:$D,"fit",history!$A:$A,YEAR($A6)&"-"&TEXT(MONTH($A6),"00")&"-"&TEXT(DAY($A6),"00"),history!$S:$S,"="),0)),"") -> 44.9
A7: 46199 | B7: =IFERROR(IF(_xlfn.MINIFS(history!$H:$H,history!$C:$C,"tim",history!$D:$D,"control",history!$A:$A,YEAR($A7)&"-"&TEXT(MONTH($A7),"00")&"-"&TEXT(DAY($A7),"00"))=0,"",_xlfn.MINIFS(history!$H:$H,history!$C:$C,"tim",history!$D:$D,"control",history!$A:$A,YEAR($A7)&"-"&TEXT(MONTH($A7),"00")&"-"&TEXT(DAY($A7),"00"))),"") -> 58.99 | C7: =IFERROR(IF(_xlfn.MINIFS(history!$H:$H,history!$C:$C,"vivo",history!$D:$D,"control",history!$A:$A,YEAR($A7)&"-"&TEXT(MONTH($A7),"00")&"-"&TEXT(DAY($A7),"00"))=0,"",_xlfn.MINIFS(history!$H:$H,history!$C:$C,"vivo",history!$D:$D,"control",history!$A:$A,YEAR($A7)&"-"&TEXT(MONTH($A7),"00")&"-"&TEXT(DAY($A7),"00"))),"") -> 59 | D7: =IFERROR(IF(_xlfn.MINIFS(history!$H:$H,history!$C:$C,"claro",history!$D:$D,"control",history!$A:$A,YEAR($A7)&"-"&TEXT(MONTH($A7),"00")&"-"&TEXT(DAY($A7),"00"))=0,"",_xlfn.MINIFS(history!$H:$H,history!$C:$C,"claro",history!$D:$D,"control",history!$A:$A,YEAR($A7)&"-"&TEXT(MONTH($A7),"00")&"-"&TEXT(DAY($A7),"00"))),"") -> 59.9 | E7: =IFERROR(IF(_xlfn.MINIFS(history!$H:$H,history!$C:$C,"tim",history!$D:$D,"postpaid",history!$A:$A,YEAR($A7)&"-"&TEXT(MONTH($A7),"00")&"-"&TEXT(DAY($A7),"00"))=0,"",_xlfn.MINIFS(history!$H:$H,history!$C:$C,"tim",history!$D:$D,"postpaid",history!$A:$A,YEAR($A7)&"-"&TEXT(MONTH($A7),"00")&"-"&TEXT(DAY($A7),"00"))),"") -> 119.99 | F7: =IFERROR(IF(_xlfn.MINIFS(history!$H:$H,history!$C:$C,"vivo",history!$D:$D,"postpaid",history!$A:$A,YEAR($A7)&"-"&TEXT(MONTH($A7),"00")&"-"&TEXT(DAY($A7),"00"))=0,"",_xlfn.MINIFS(history!$H:$H,history!$C:$C,"vivo",history!$D:$D,"postpaid",history!$A:$A,YEAR($A7)&"-"&TEXT(MONTH($A7),"00")&"-"&TEXT(DAY($A7),"00"))),"") -> 150 | G7: =IFERROR(IF(_xlfn.MINIFS(history!$H:$H,history!$C:$C,"claro",history!$D:$D,"postpaid",history!$A:$A,YEAR($A7)&"-"&TEXT(MONTH($A7),"00")&"-"&TEXT(DAY($A7),"00"))=0,"",_xlfn.MINIFS(history!$H:$H,history!$C:$C,"claro",history!$D:$D,"postpaid",history!$A:$A,YEAR($A7)&"-"&TEXT(MONTH($A7),"00")&"-"&TEXT(DAY($A7),"00"))),"") -> 124.9 | H7: =IFERROR(IF(_xlfn.MINIFS(history!$H:$H,history!$C:$C,"tim",history!$D:$D,"prepaid",history!$A:$A,YEAR($A7)&"-"&TEXT(MONTH($A7),"00")&"-"&TEXT(DAY($A7),"00"),history!$N:$N,">=28")=0,"",_xlfn.MINIFS(history!$H:$H,history!$C:$C,"tim",history!$D:$D,"prepaid",history!$A:$A,YEAR($A7)&"-"&TEXT(MONTH($A7),"00")&"-"&TEXT(DAY($A7),"00"),history!$N:$N,">=28")),"") -> 20 | I7: =IFERROR(IF(_xlfn.MINIFS(history!$H:$H,history!$C:$C,"vivo",history!$D:$D,"prepaid",history!$A:$A,YEAR($A7)&"-"&TEXT(MONTH($A7),"00")&"-"&TEXT(DAY($A7),"00"),history!$N:$N,">=28")=0,"",_xlfn.MINIFS(history!$H:$H,history!$C:$C,"vivo",history!$D:$D,"prepaid",history!$A:$A,YEAR($A7)&"-"&TEXT(MONTH($A7),"00")&"-"&TEXT(DAY($A7),"00"),history!$N:$N,">=28")),"") -> 30 | J7: =IFERROR(IF(_xlfn.MINIFS(history!$H:$H,history!$C:$C,"claro",history!$D:$D,"prepaid",history!$A:$A,YEAR($A7)&"-"&TEXT(MONTH($A7),"00")&"-"&TEXT(DAY($A7),"00"),history!$N:$N,">=28")=0,"",_xlfn.MINIFS(history!$H:$H,history!$C:$C,"claro",history!$D:$D,"prepaid",history!$A:$A,YEAR($A7)&"-"&TEXT(MONTH($A7),"00")&"-"&TEXT(DAY($A7),"00"),history!$N:$N,">=28")),"") -> 30 | K7: =IFERROR(1/MAX(IFERROR(1/_xlfn.MINIFS(history!$H:$H,history!$C:$C,"tim",history!$D:$D,"lite",history!$A:$A,YEAR($A7)&"-"&TEXT(MONTH($A7),"00")&"-"&TEXT(DAY($A7),"00"),history!$S:$S,">0"),0),IFERROR(1/_xlfn.MINIFS(history!$H:$H,history!$C:$C,"tim",history!$D:$D,"flex",history!$A:$A,YEAR($A7)&"-"&TEXT(MONTH($A7),"00")&"-"&TEXT(DAY($A7),"00")),0),IFERROR(1/_xlfn.MINIFS(history!$H:$H,history!$C:$C,"tim",history!$D:$D,"fit",history!$A:$A,YEAR($A7)&"-"&TEXT(MONTH($A7),"00")&"-"&TEXT(DAY($A7),"00"),history!$S:$S,"="),0)),"") | L7: =IFERROR(1/MAX(IFERROR(1/_xlfn.MINIFS(history!$H:$H,history!$C:$C,"vivo",history!$D:$D,"lite",history!$A:$A,YEAR($A7)&"-"&TEXT(MONTH($A7),"00")&"-"&TEXT(DAY($A7),"00"),history!$S:$S,">0"),0),IFERROR(1/_xlfn.MINIFS(history!$H:$H,history!$C:$C,"vivo",history!$D:$D,"flex",history!$A:$A,YEAR($A7)&"-"&TEXT(MONTH($A7),"00")&"-"&TEXT(DAY($A7),"00")),0),IFERROR(1/_xlfn.MINIFS(history!$H:$H,history!$C:$C,"vivo",history!$D:$D,"fit",history!$A:$A,YEAR($A7)&"-"&TEXT(MONTH($A7),"00")&"-"&TEXT(DAY($A7),"00"),history!$S:$S,"="),0)),"") | M7: =IFERROR(1/MAX(IFERROR(1/_xlfn.MINIFS(history!$H:$H,history!$C:$C,"claro",history!$D:$D,"lite",history!$A:$A,YEAR($A7)&"-"&TEXT(MONTH($A7),"00")&"-"&TEXT(DAY($A7),"00"),history!$S:$S,">0"),0),IFERROR(1/_xlfn.MINIFS(history!$H:$H,history!$C:$C,"claro",history!$D:$D,"flex",history!$A:$A,YEAR($A7)&"-"&TEXT(MONTH($A7),"00")&"-"&TEXT(DAY($A7),"00")),0),IFERROR(1/_xlfn.MINIFS(history!$H:$H,history!$C:$C,"claro",history!$D:$D,"fit",history!$A:$A,YEAR($A7)&"-"&TEXT(MONTH($A7),"00")&"-"&TEXT(DAY($A7),"00"),history!$S:$S,"="),0)),"") -> 44.9
A8: 46200 | B8: =IFERROR(IF(_xlfn.MINIFS(history!$H:$H,history!$C:$C,"tim",history!$D:$D,"control",history!$A:$A,YEAR($A8)&"-"&TEXT(MONTH($A8),"00")&"-"&TEXT(DAY($A8),"00"))=0,"",_xlfn.MINIFS(history!$H:$H,history!$C:$C,"tim",history!$D:$D,"control",history!$A:$A,YEAR($A8)&"-"&TEXT(MONTH($A8),"00")&"-"&TEXT(DAY($A8),"00"))),"") -> 58.99 | C8: =IFERROR(IF(_xlfn.MINIFS(history!$H:$H,history!$C:$C,"vivo",history!$D:$D,"control",history!$A:$A,YEAR($A8)&"-"&TEXT(MONTH($A8),"00")&"-"&TEXT(DAY($A8),"00"))=0,"",_xlfn.MINIFS(history!$H:$H,history!$C:$C,"vivo",history!$D:$D,"control",history!$A:$A,YEAR($A8)&"-"&TEXT(MONTH($A8),"00")&"-"&TEXT(DAY($A8),"00"))),"") -> 59 | D8: =IFERROR(IF(_xlfn.MINIFS(history!$H:$H,history!$C:$C,"claro",history!$D:$D,"control",history!$A:$A,YEAR($A8)&"-"&TEXT(MONTH($A8),"00")&"-"&TEXT(DAY($A8),"00"))=0,"",_xlfn.MINIFS(history!$H:$H,history!$C:$C,"claro",history!$D:$D,"control",history!$A:$A,YEAR($A8)&"-"&TEXT(MONTH($A8),"00")&"-"&TEXT(DAY($A8),"00"))),"") -> 59.9 | E8: =IFERROR(IF(_xlfn.MINIFS(history!$H:$H,history!$C:$C,"tim",history!$D:$D,"postpaid",history!$A:$A,YEAR($A8)&"-"&TEXT(MONTH($A8),"00")&"-"&TEXT(DAY($A8),"00"))=0,"",_xlfn.MINIFS(history!$H:$H,history!$C:$C,"tim",history!$D:$D,"postpaid",history!$A:$A,YEAR($A8)&"-"&TEXT(MONTH($A8),"00")&"-"&TEXT(DAY($A8),"00"))),"") -> 119.99 | F8: =IFERROR(IF(_xlfn.MINIFS(history!$H:$H,history!$C:$C,"vivo",history!$D:$D,"postpaid",history!$A:$A,YEAR($A8)&"-"&TEXT(MONTH($A8),"00")&"-"&TEXT(DAY($A8),"00"))=0,"",_xlfn.MINIFS(history!$H:$H,history!$C:$C,"vivo",history!$D:$D,"postpaid",history!$A:$A,YEAR($A8)&"-"&TEXT(MONTH($A8),"00")&"-"&TEXT(DAY($A8),"00"))),"") -> 150 | G8: =IFERROR(IF(_xlfn.MINIFS(history!$H:$H,history!$C:$C,"claro",history!$D:$D,"postpaid",history!$A:$A,YEAR($A8)&"-"&TEXT(MONTH($A8),"00")&"-"&TEXT(DAY($A8),"00"))=0,"",_xlfn.MINIFS(history!$H:$H,history!$C:$C,"claro",history!$D:$D,"postpaid",history!$A:$A,YEAR($A8)&"-"&TEXT(MONTH($A8),"00")&"-"&TEXT(DAY($A8),"00"))),"") -> 124.9 | H8: =IFERROR(IF(_xlfn.MINIFS(history!$H:$H,history!$C:$C,"tim",history!$D:$D,"prepaid",history!$A:$A,YEAR($A8)&"-"&TEXT(MONTH($A8),"00")&"-"&TEXT(DAY($A8),"00"),history!$N:$N,">=28")=0,"",_xlfn.MINIFS(history!$H:$H,history!$C:$C,"tim",history!$D:$D,"prepaid",history!$A:$A,YEAR($A8)&"-"&TEXT(MONTH($A8),"00")&"-"&TEXT(DAY($A8),"00"),history!$N:$N,">=28")),"") -> 20 | I8: =IFERROR(IF(_xlfn.MINIFS(history!$H:$H,history!$C:$C,"vivo",history!$D:$D,"prepaid",history!$A:$A,YEAR($A8)&"-"&TEXT(MONTH($A8),"00")&"-"&TEXT(DAY($A8),"00"),history!$N:$N,">=28")=0,"",_xlfn.MINIFS(history!$H:$H,history!$C:$C,"vivo",history!$D:$D,"prepaid",history!$A:$A,YEAR($A8)&"-"&TEXT(MONTH($A8),"00")&"-"&TEXT(DAY($A8),"00"),history!$N:$N,">=28")),"") -> 30 | J8: =IFERROR(IF(_xlfn.MINIFS(history!$H:$H,history!$C:$C,"claro",history!$D:$D,"prepaid",history!$A:$A,YEAR($A8)&"-"&TEXT(MONTH($A8),"00")&"-"&TEXT(DAY($A8),"00"),history!$N:$N,">=28")=0,"",_xlfn.MINIFS(history!$H:$H,history!$C:$C,"claro",history!$D:$D,"prepaid",history!$A:$A,YEAR($A8)&"-"&TEXT(MONTH($A8),"00")&"-"&TEXT(DAY($A8),"00"),history!$N:$N,">=28")),"") -> 30 | K8: =IFERROR(1/MAX(IFERROR(1/_xlfn.MINIFS(history!$H:$H,history!$C:$C,"tim",history!$D:$D,"lite",history!$A:$A,YEAR($A8)&"-"&TEXT(MONTH($A8),"00")&"-"&TEXT(DAY($A8),"00"),history!$S:$S,">0"),0),IFERROR(1/_xlfn.MINIFS(history!$H:$H,history!$C:$C,"tim",history!$D:$D,"flex",history!$A:$A,YEAR($A8)&"-"&TEXT(MONTH($A8),"00")&"-"&TEXT(DAY($A8),"00")),0),IFERROR(1/_xlfn.MINIFS(history!$H:$H,history!$C:$C,"tim",history!$D:$D,"fit",history!$A:$A,YEAR($A8)&"-"&TEXT(MONTH($A8),"00")&"-"&TEXT(DAY($A8),"00"),history!$S:$S,"="),0)),"") | L8: =IFERROR(1/MAX(IFERROR(1/_xlfn.MINIFS(history!$H:$H,history!$C:$C,"vivo",history!$D:$D,"lite",history!$A:$A,YEAR($A8)&"-"&TEXT(MONTH($A8),"00")&"-"&TEXT(DAY($A8),"00"),history!$S:$S,">0"),0),IFERROR(1/_xlfn.MINIFS(history!$H:$H,history!$C:$C,"vivo",history!$D:$D,"flex",history!$A:$A,YEAR($A8)&"-"&TEXT(MONTH($A8),"00")&"-"&TEXT(DAY($A8),"00")),0),IFERROR(1/_xlfn.MINIFS(history!$H:$H,history!$C:$C,"vivo",history!$D:$D,"fit",history!$A:$A,YEAR($A8)&"-"&TEXT(MONTH($A8),"00")&"-"&TEXT(DAY($A8),"00"),history!$S:$S,"="),0)),"") | M8: =IFERROR(1/MAX(IFERROR(1/_xlfn.MINIFS(history!$H:$H,history!$C:$C,"claro",history!$D:$D,"lite",history!$A:$A,YEAR($A8)&"-"&TEXT(MONTH($A8),"00")&"-"&TEXT(DAY($A8),"00"),history!$S:$S,">0"),0),IFERROR(1/_xlfn.MINIFS(history!$H:$H,history!$C:$C,"claro",history!$D:$D,"flex",history!$A:$A,YEAR($A8)&"-"&TEXT(MONTH($A8),"00")&"-"&TEXT(DAY($A8),"00")),0),IFERROR(1/_xlfn.MINIFS(history!$H:$H,history!$C:$C,"claro",history!$D:$D,"fit",history!$A:$A,YEAR($A8)&"-"&TEXT(MONTH($A8),"00")&"-"&TEXT(DAY($A8),"00"),history!$S:$S,"="),0)),"") -> 44.9
