Workbook

Sheet history
A1: snapshot_date | B1: snapshot_ts | C1: carrier | D1: category | E1: state | F1: plan_name | G1: plan_id | H1: price_brl | I1: price_promo_brl | J1: price_note | K1: data_gb | L1: data_note | M1: unlimited_apps | N1: voice | O1: sms | P1: streaming | Q1: loyalty_months | R1: extra_benefits | S1: source_url | T1: raw_ref
A2: 2026-06-22 | B2: 2026-06-22T18:35:49 | C2: claro | D2: control | E2: SP | F2: Controle 25GB | G2: claro:plano-controle-25gb | H2: 59.9 | I2: 54.9 | J2: De R$ 59,90 Por: | K2: 25 | M2: WhatsApp | R2: Para uso livre; Para redes sociais e vídeos; Bônus exclusivo; Aproveite na sua franquia; WhatsApp e ligações ilimitadas | S2: https://www.claro.com.br/celular/controle | T2: data/raw/claro_control_SP.json
A3: 2026-06-22 | B3: 2026-06-22T18:35:49 | C3: claro | D3: control | E3: SP | F3: Controle 30GB | G3: claro:plano-controle-30gb | H3: 69.9 | K3: 30 | M3: WhatsApp | R3: Para uso livre; Bônus do Hexa para uso livre; Bônus para redes sociais e apps; Redes sociais e apps; WhatsApp ilimitado | S3: https://www.claro.com.br/celular/controle | T3: data/raw/claro_control_SP.json
A4: 2026-06-22 | B4: 2026-06-22T18:35:49 | C4: claro | D4: control | E4: SP | F4: Controle 30GB | G4: claro:plano-controle-30gb-gaming | H4: 99.9 | K4: 30 | M4: WhatsApp | R4: Para uso livre; Bônus para redes sociais e apps; Bônus uso livre; Redes sociais e apps; WhatsApp ilimitado | S4: https://www.claro.com.br/celular/controle | T4: data/raw/claro_control_SP.json
A5: 2026-06-22 | B5: 2026-06-22T18:35:49 | C5: claro | D5: flex | E5: SP | F5: Flex 15GB | G5: claro:plano-flex-15gb | H5: 44.9 | K5: 15 | M5: WhatsApp | R5: Para uso livre; Bônus do Hexa para uso livre; Para redes sociais e apps; Bônus extra nos apps; WhatsApp ilimitado | S5: https://www.claro.com.br/celular/flex | T5: data/raw/claro_flex_SP.json
A6: 2026-06-22 | B6: 2026-06-22T18:35:49 | C6: claro | D6: flex | E6: SP | F6: Flex 20GB | G6: claro:plano-flex-20gb | H6: 59.9 | K6: 20 | M6: WhatsApp | R6: Para uso livre; Bônus do Hexa para uso livre; Para redes sociais e apps; Bônus extra nos apps; WhatsApp ilimitado | S6: https://www.claro.com.br/celular/flex | T6: data/raw/claro_flex_SP.json
A7: 2026-06-22 | B7: 2026-06-22T18:35:49 | C7: claro | D7: flex | E7: SP | F7: Flex 30GB | G7: claro:plano-flex-30gb | H7: 69.9 | K7: 30 | M7: WhatsApp | R7: Para uso livre; Bônus do Hexa para uso livre; Para redes sociais e apps; Bônus extra nos apps; WhatsApp ilimitado; Assinatura Claro musica inclusa | S7: https://www.claro.com.br/celular/flex | T7: data/raw/claro_flex_SP.json
A8: 2026-06-22 | B8: 2026-06-22T18:35:49 | C8: claro | D8: flex | E8: SP | F8: Flex 40GB | G8: claro:plano-flex-40gb | H8: 119.9 | K8: 40 | M8: WhatsApp | R8: Para uso livre; Para redes sociais e apps; Bônus uso livre; Bônus extra nos apps; WhatsApp ilimitado; Assinatura Claro musica inclusa | S8: https://www.claro.com.br/celular/flex | T8: data/raw/claro_flex_SP.json
A9: 2026-06-22 | B9: 2026-06-22T18:35:49 | C9: claro | D9: postpaid | E9: SP | F9: Pós 100GB | G9: claro:plano-pos-100gb | H9: 179.9 | K9: 100 | M9: WhatsApp | R9: Armazenamento na nuvem:; Google One ou iCloud+; WhatsApp ilimitado; Roaming: Passaporte Américas; Claro Sync: Smartwatch conectado | S9: https://www.claro.com.br/celular/pos | T9: data/raw/claro_postpaid_SP.json
A10: 2026-06-22 | B10: 2026-06-22T18:35:49 | C10: claro | D10: postpaid | E10: SP | F10: Pós 150GB | G10: claro:plano-pos-150gb | H10: 239.9 | K10: 150 | M10: WhatsApp | R10: Armazenamento na nuvem:; Google One ou iCloud+; WhatsApp ilimitado; Roaming: Passaporte Américas e Europa; Claro Sync: Smartwatch conectado | S10: https://www.claro.com.br/celular/pos | T10: data/raw/claro_postpaid_SP.json
A11: 2026-06-22 | B11: 2026-06-22T18:35:49 | C11: claro | D11: postpaid | E11: SP | F11: Pós 200GB | G11: claro:plano-pos-200gb | H11: 339.9 | K11: 200 | M11: WhatsApp | R11: Armazenamento na nuvem:; Google One ou iCloud+; WhatsApp ilimitado; Roaming: Passaporte Mundo; Claro Sync: Smartwatch conectado | S11: https://www.claro.com.br/celular/pos | T11: data/raw/claro_postpaid_SP.json
A12: 2026-06-22 | B12: 2026-06-22T18:35:49 | C12: claro | D12: postpaid | E12: SP | F12: Pós 50GB com GeForce NOW | G12: claro:plano-pos-60gb-geforce | H12: 164.9 | K12: 50 | M12: WhatsApp | R12: Armazenamento na nuvem:; Google One ou iCloud+; WhatsApp ilimitado; Roaming: Passaporte Américas; Claro Sync: Smartwatch conectado; Inclusa assinatura GeForce NOW | S12: https://www.claro.com.br/celular/pos | T12: data/raw/claro_postpaid_SP.json
A13: 2026-06-22 | B13: 2026-06-22T18:35:49 | C13: claro | D13: postpaid | E13: SP | F13: Pós 60GB | G13: claro:plano-pos-60gb | H13: 124.9 | K13: 60 | M13: WhatsApp | R13: Armazenamento na nuvem:; Google One ou iCloud+; WhatsApp ilimitado; Roaming: Passaporte Américas; Claro Sync: Smartwatch conectado | S13: https://www.claro.com.br/celular/pos | T13: data/raw/claro_postpaid_SP.json
A14: 2026-06-22 | B14: 2026-06-22T18:35:49 | C14: claro | D14: prepaid | E14: SP | F14: Prezão R$1 por dia | G14: claro:prez-o-r-1-por-dia | H14: 1 | J14: prepaid Prezão — preço por dia; recargas a partir de R$15 | K14: 12 | S14: https://www.claro.com.br/celular/planos-pre/prezao | T14: data/raw/claro_prepaid_SP.json
A15: 2026-06-22 | B15: 2026-06-22T18:35:49 | C15: tim | D15: control | E15: SP | F15: TIM Controle 41GB | G15: tim:162901 | H15: 58.99 | K15: 41 | S15: https://www.tim.com.br/sp/para-voce/planos/controle | T15: data/raw/tim_control_SP.html
A16: 2026-06-22 | B16: 2026-06-22T18:35:49 | C16: tim | D16: control | E16: SP | F16: TIM Controle Light Express 31GB | G16: tim:143536 | H16: 60.99 | K16: 31 | S16: https://www.tim.com.br/sp/para-voce/planos/controle | T16: data/raw/tim_control_SP.html
A17: 2026-06-22 | B17: 2026-06-22T18:35:49 | C17: tim | D17: control | E17: SP | F17: TIM Controle Plus 45GB | G17: tim:155891 | H17: 64.99 | K17: 45 | S17: https://www.tim.com.br/sp/para-voce/planos/controle | T17: data/raw/tim_control_SP.html
A18: 2026-06-22 | B18: 2026-06-22T18:35:49 | C18: tim | D18: control | E18: SP | F18: TIM Controle Premium 53GB | G18: tim:162896 | H18: 84.99 | K18: 53 | S18: https://www.tim.com.br/sp/para-voce/planos/controle | T18: data/raw/tim_control_SP.html
A19: 2026-06-22 | B19: 2026-06-22T18:35:49 | C19: tim | D19: control | E19: SP | F19: TIM Controle Pro Express | G19: tim:143576 | H19: 64.99 | S19: https://www.tim.com.br/sp/para-voce/planos/controle | T19: data/raw/tim_control_SP.html
A20: 2026-06-22 | B20: 2026-06-22T18:35:49 | C20: tim | D20: postpaid | E20: SP | F20: TIM Black 70GB | G20: tim:54206 | H20: 129.99 | K20: 70 | S20: https://www.tim.com.br/sp/para-voce/planos/pos-pago/tim-black | T20: data/raw/tim_postpaid_SP.html
A21: 2026-06-22 | B21: 2026-06-22T18:35:49 | C21: tim | D21: postpaid | E21: SP | F21: TIM Black A Express 67GB | G21: tim:55121 | H21: 119.99 | K21: 67 | S21: https://www.tim.com.br/sp/para-voce/planos/pos-pago/tim-black | T21: data/raw/tim_postpaid_SP.html
A22: 2026-06-22 | B22: 2026-06-22T18:35:49 | C22: tim | D22: postpaid | E22: SP | F22: TIM Black B Express 82GB | G22: tim:52146 | H22: 144.99 | K22: 82 | S22: https://www.tim.com.br/sp/para-voce/planos/pos-pago/tim-black | T22: data/raw/tim_postpaid_SP.html
A23: 2026-06-22 | B23: 2026-06-22T18:35:49 | C23: tim | D23: postpaid | E23: SP | F23: TIM Black C Express 107GB | G23: tim:52151 | H23: 164.99 | K23: 107 | S23: https://www.tim.com.br/sp/para-voce/planos/pos-pago/tim-black | T23: data/raw/tim_postpaid_SP.html
A24: 2026-06-22 | B24: 2026-06-22T18:35:49 | C24: tim | D24: postpaid | E24: SP | F24: TIM Black C Ultra 95GB | G24: tim:100581 | H24: 159.99 | K24: 95 | S24: https://www.tim.com.br/sp/para-voce/planos/pos-pago/tim-black | T24: data/raw/tim_postpaid_SP.html
A25: 2026-06-22 | B25: 2026-06-22T18:35:49 | C25: tim | D25: postpaid | E25: SP | F25: TIM Black Plus 80GB | G25: tim:54256 | H25: 149.99 | K25: 80 | S25: https://www.tim.com.br/sp/para-voce/planos/pos-pago/tim-black | T25: data/raw/tim_postpaid_SP.html
A26: 2026-06-22 | B26: 2026-06-22T18:35:49 | C26: tim | D26: postpaid | E26: SP | F26: TIM Black Premium 110GB | G26: tim:54261 | H26: 159.99 | K26: 110 | S26: https://www.tim.com.br/sp/para-voce/planos/pos-pago/tim-black | T26: data/raw/tim_postpaid_SP.html
A27: 2026-06-22 | B27: 2026-06-22T18:35:49 | C27: tim | D27: prepaid | E27: SP | F27: TIM Pré XIP Plus 16GB | G27: tim:106306 | H27: 30 | K27: 16 | S27: https://www.tim.com.br/sp/para-voce/planos/pre-pago | T27: data/raw/tim_prepaid_SP.html
A28: 2026-06-22 | B28: 2026-06-22T18:35:49 | C28: tim | D28: prepaid | E28: SP | F28: TIM Pré XIP Plus 6GB | G28: tim:59906 | H28: 20 | K28: 6 | S28: https://www.tim.com.br/sp/para-voce/planos/pre-pago | T28: data/raw/tim_prepaid_SP.html
A29: 2026-06-22 | B29: 2026-06-22T18:35:49 | C29: tim | D29: prepaid | E29: SP | F29: TIM Pré XIP Plus 8GB | G29: tim:59901 | H29: 25 | K29: 8 | S29: https://www.tim.com.br/sp/para-voce/planos/pre-pago | T29: data/raw/tim_prepaid_SP.html
A30: 2026-06-22 | B30: 2026-06-22T18:35:49 | C30: vivo | D30: control | E30: SP | F30: Vivo Controle | G30: vivo:VIV202600029270-46gb | H30: 59 | K30: 46 | L30: 15 GB de franquia 31 GB de bônus | R30: 6 meses grátis de Gemini com AI Plus | S30: https://vivo.com.br/para-voce/produtos-e-servicos/para-o-celular/planos-controle | T30: data/raw/vivo_control_SP.html
A31: 2026-06-22 | B31: 2026-06-22T18:35:49 | C31: vivo | D31: control | E31: SP | F31: Vivo Controle | G31: vivo:VIV202600029300-61gb | H31: 80 | K31: 61 | L31: 20 GB de franquia 31 GB de bônus | R31: 6 meses grátis de Gemini com AI Plus | S31: https://vivo.com.br/para-voce/produtos-e-servicos/para-o-celular/planos-controle | T31: data/raw/vivo_control_SP.html
A32: 2026-06-22 | B32: 2026-06-22T18:35:49 | C32: vivo | D32: control | E32: SP | F32: Vivo Controle Educação | G32: vivo:VIV202600029273-61gb | H32: 90 | K32: 61 | L32: 20 GB de franquia 31 GB de bônus | R32: Assinatura Vivae inclusa | S32: https://vivo.com.br/para-voce/produtos-e-servicos/para-o-celular/planos-controle | T32: data/raw/vivo_control_SP.html
A33: 2026-06-22 | B33: 2026-06-22T18:35:49 | C33: vivo | D33: control | E33: SP | F33: Vivo Controle Entretenimento | G33: vivo:VIV202600029307-61gb | H33: 110 | K33: 61 | L33: 20 GB de franquia 31 GB de bônus | R33: Assinatura Vivo TV Inicial inclusa | S33: https://vivo.com.br/para-voce/produtos-e-servicos/para-o-celular/planos-controle | T33: data/raw/vivo_control_SP.html
A34: 2026-06-22 | B34: 2026-06-22T18:35:49 | C34: vivo | D34: control | E34: SP | F34: Vivo Controle Música | G34: vivo:VIV202600029313-61gb | H34: 95 | K34: 61 | L34: 20 GB de franquia 31 GB de bônus | R34: Apple Music Individual | S34: https://vivo.com.br/para-voce/produtos-e-servicos/para-o-celular/planos-controle | T34: data/raw/vivo_control_SP.html
A35: 2026-06-22 | B35: 2026-06-22T18:35:49 | C35: vivo | D35: control | E35: SP | F35: Vivo Controle Netflix | G35: vivo:VIV202600029308-61gb | H35: 95 | K35: 61 | L35: 20 GB de franquia 31 GB de bônus | R35: Assinatura Netflix Padrão com anúncios | S35: https://vivo.com.br/para-voce/produtos-e-servicos/para-o-celular/planos-controle | T35: data/raw/vivo_control_SP.html
A36: 2026-06-22 | B36: 2026-06-22T18:35:49 | C36: vivo | D36: control | E36: SP | F36: Vivo Controle Saúde | G36: vivo:VIV202600029301-61gb | H36: 90 | K36: 61 | L36: 20 GB de franquia 31 GB de bônus | R36: Assinatura Vale Saúde Sempre inclusa | S36: https://vivo.com.br/para-voce/produtos-e-servicos/para-o-celular/planos-controle | T36: data/raw/vivo_control_SP.html
A37: 2026-06-22 | B37: 2026-06-22T18:35:49 | C37: vivo | D37: lite | E37: SP | F37: Easy Lite | G37: vivo:VIV202600005312-30gb | H37: 30 | K37: 30 | L37: 30 GB de franquia 2 Meses de YouTube ilimitado | S37: https://vivo.com.br/para-voce/produtos-e-servicos/para-o-celular/easy-lite | T37: data/raw/vivo_lite_SP.html
A38: 2026-06-22 | B38: 2026-06-22T18:35:49 | C38: vivo | D38: lite | E38: SP | F38: Easy Lite | G38: vivo:VIV202600019134-40gb | H38: 40 | K38: 40 | L38: 40 GB de franquia 2 Meses de YouTube ilimitado | S38: https://vivo.com.br/para-voce/produtos-e-servicos/para-o-celular/easy-lite | T38: data/raw/vivo_lite_SP.html
A39: 2026-06-22 | B39: 2026-06-22T18:35:49 | C39: vivo | D39: lite | E39: SP | F39: Easy Lite | G39: vivo:VIV202600019132-20gb | H39: 35 | K39: 20 | L39: 20 GB de franquia 2 Meses de YouTube ilimitado | S39: https://vivo.com.br/para-voce/produtos-e-servicos/para-o-celular/easy-lite | T39: data/raw/vivo_lite_SP.html
A40: 2026-06-22 | B40: 2026-06-22T18:35:49 | C40: vivo | D40: lite | E40: SP | F40: Easy Lite | G40: vivo:VIV202600019127-30gb | H40: 40 | K40: 30 | S40: https://vivo.com.br/para-voce/produtos-e-servicos/para-o-celular/easy-lite | T40: data/raw/vivo_lite_SP.html
...

Sheet latest
A1: snapshot_date | B1: snapshot_ts | C1: carrier | D1: category | E1: state | F1: plan_name | G1: plan_id | H1: price_brl | I1: price_promo_brl | J1: price_note | K1: data_gb | L1: data_note | M1: unlimited_apps | N1: voice | O1: sms | P1: streaming | Q1: loyalty_months | R1: extra_benefits | S1: source_url | T1: raw_ref
A2: 2026-06-22 | B2: 2026-06-22T18:35:49 | C2: claro | D2: control | E2: SP | F2: Controle 25GB | G2: claro:plano-controle-25gb | H2: 59.9 | I2: 54.9 | J2: De R$ 59,90 Por: | K2: 25 | M2: WhatsApp | R2: Para uso livre; Para redes sociais e vídeos; Bônus exclusivo; Aproveite na sua franquia; WhatsApp e ligações ilimitadas | S2: https://www.claro.com.br/celular/controle | T2: data/raw/claro_control_SP.json
A3: 2026-06-22 | B3: 2026-06-22T18:35:49 | C3: claro | D3: control | E3: SP | F3: Controle 30GB | G3: claro:plano-controle-30gb | H3: 69.9 | K3: 30 | M3: WhatsApp | R3: Para uso livre; Bônus do Hexa para uso livre; Bônus para redes sociais e apps; Redes sociais e apps; WhatsApp ilimitado | S3: https://www.claro.com.br/celular/controle | T3: data/raw/claro_control_SP.json
A4: 2026-06-22 | B4: 2026-06-22T18:35:49 | C4: claro | D4: control | E4: SP | F4: Controle 30GB | G4: claro:plano-controle-30gb-gaming | H4: 99.9 | K4: 30 | M4: WhatsApp | R4: Para uso livre; Bônus para redes sociais e apps; Bônus uso livre; Redes sociais e apps; WhatsApp ilimitado | S4: https://www.claro.com.br/celular/controle | T4: data/raw/claro_control_SP.json
A5: 2026-06-22 | B5: 2026-06-22T18:35:49 | C5: claro | D5: flex | E5: SP | F5: Flex 15GB | G5: claro:plano-flex-15gb | H5: 44.9 | K5: 15 | M5: WhatsApp | R5: Para uso livre; Bônus do Hexa para uso livre; Para redes sociais e apps; Bônus extra nos apps; WhatsApp ilimitado | S5: https://www.claro.com.br/celular/flex | T5: data/raw/claro_flex_SP.json
A6: 2026-06-22 | B6: 2026-06-22T18:35:49 | C6: claro | D6: flex | E6: SP | F6: Flex 20GB | G6: claro:plano-flex-20gb | H6: 59.9 | K6: 20 | M6: WhatsApp | R6: Para uso livre; Bônus do Hexa para uso livre; Para redes sociais e apps; Bônus extra nos apps; WhatsApp ilimitado | S6: https://www.claro.com.br/celular/flex | T6: data/raw/claro_flex_SP.json
A7: 2026-06-22 | B7: 2026-06-22T18:35:49 | C7: claro | D7: flex | E7: SP | F7: Flex 30GB | G7: claro:plano-flex-30gb | H7: 69.9 | K7: 30 | M7: WhatsApp | R7: Para uso livre; Bônus do Hexa para uso livre; Para redes sociais e apps; Bônus extra nos apps; WhatsApp ilimitado; Assinatura Claro musica inclusa | S7: https://www.claro.com.br/celular/flex | T7: data/raw/claro_flex_SP.json
A8: 2026-06-22 | B8: 2026-06-22T18:35:49 | C8: claro | D8: flex | E8: SP | F8: Flex 40GB | G8: claro:plano-flex-40gb | H8: 119.9 | K8: 40 | M8: WhatsApp | R8: Para uso livre; Para redes sociais e apps; Bônus uso livre; Bônus extra nos apps; WhatsApp ilimitado; Assinatura Claro musica inclusa | S8: https://www.claro.com.br/celular/flex | T8: data/raw/claro_flex_SP.json
A9: 2026-06-22 | B9: 2026-06-22T18:35:49 | C9: claro | D9: postpaid | E9: SP | F9: Pós 100GB | G9: claro:plano-pos-100gb | H9: 179.9 | K9: 100 | M9: WhatsApp | R9: Armazenamento na nuvem:; Google One ou iCloud+; WhatsApp ilimitado; Roaming: Passaporte Américas; Claro Sync: Smartwatch conectado | S9: https://www.claro.com.br/celular/pos | T9: data/raw/claro_postpaid_SP.json
A10: 2026-06-22 | B10: 2026-06-22T18:35:49 | C10: claro | D10: postpaid | E10: SP | F10: Pós 150GB | G10: claro:plano-pos-150gb | H10: 239.9 | K10: 150 | M10: WhatsApp | R10: Armazenamento na nuvem:; Google One ou iCloud+; WhatsApp ilimitado; Roaming: Passaporte Américas e Europa; Claro Sync: Smartwatch conectado | S10: https://www.claro.com.br/celular/pos | T10: data/raw/claro_postpaid_SP.json
A11: 2026-06-22 | B11: 2026-06-22T18:35:49 | C11: claro | D11: postpaid | E11: SP | F11: Pós 200GB | G11: claro:plano-pos-200gb | H11: 339.9 | K11: 200 | M11: WhatsApp | R11: Armazenamento na nuvem:; Google One ou iCloud+; WhatsApp ilimitado; Roaming: Passaporte Mundo; Claro Sync: Smartwatch conectado | S11: https://www.claro.com.br/celular/pos | T11: data/raw/claro_postpaid_SP.json
A12: 2026-06-22 | B12: 2026-06-22T18:35:49 | C12: claro | D12: postpaid | E12: SP | F12: Pós 50GB com GeForce NOW | G12: claro:plano-pos-60gb-geforce | H12: 164.9 | K12: 50 | M12: WhatsApp | R12: Armazenamento na nuvem:; Google One ou iCloud+; WhatsApp ilimitado; Roaming: Passaporte Américas; Claro Sync: Smartwatch conectado; Inclusa assinatura GeForce NOW | S12: https://www.claro.com.br/celular/pos | T12: data/raw/claro_postpaid_SP.json
A13: 2026-06-22 | B13: 2026-06-22T18:35:49 | C13: claro | D13: postpaid | E13: SP | F13: Pós 60GB | G13: claro:plano-pos-60gb | H13: 124.9 | K13: 60 | M13: WhatsApp | R13: Armazenamento na nuvem:; Google One ou iCloud+; WhatsApp ilimitado; Roaming: Passaporte Américas; Claro Sync: Smartwatch conectado | S13: https://www.claro.com.br/celular/pos | T13: data/raw/claro_postpaid_SP.json
A14: 2026-06-22 | B14: 2026-06-22T18:35:49 | C14: claro | D14: prepaid | E14: SP | F14: Prezão R$1 por dia | G14: claro:prez-o-r-1-por-dia | H14: 1 | J14: prepaid Prezão — preço por dia; recargas a partir de R$15 | K14: 12 | S14: https://www.claro.com.br/celular/planos-pre/prezao | T14: data/raw/claro_prepaid_SP.json
A15: 2026-06-22 | B15: 2026-06-22T18:35:49 | C15: tim | D15: control | E15: SP | F15: TIM Controle 41GB | G15: tim:162901 | H15: 58.99 | K15: 41 | S15: https://www.tim.com.br/sp/para-voce/planos/controle | T15: data/raw/tim_control_SP.html
A16: 2026-06-22 | B16: 2026-06-22T18:35:49 | C16: tim | D16: control | E16: SP | F16: TIM Controle Light Express 31GB | G16: tim:143536 | H16: 60.99 | K16: 31 | S16: https://www.tim.com.br/sp/para-voce/planos/controle | T16: data/raw/tim_control_SP.html
A17: 2026-06-22 | B17: 2026-06-22T18:35:49 | C17: tim | D17: control | E17: SP | F17: TIM Controle Plus 45GB | G17: tim:155891 | H17: 64.99 | K17: 45 | S17: https://www.tim.com.br/sp/para-voce/planos/controle | T17: data/raw/tim_control_SP.html
A18: 2026-06-22 | B18: 2026-06-22T18:35:49 | C18: tim | D18: control | E18: SP | F18: TIM Controle Premium 53GB | G18: tim:162896 | H18: 84.99 | K18: 53 | S18: https://www.tim.com.br/sp/para-voce/planos/controle | T18: data/raw/tim_control_SP.html
A19: 2026-06-22 | B19: 2026-06-22T18:35:49 | C19: tim | D19: control | E19: SP | F19: TIM Controle Pro Express | G19: tim:143576 | H19: 64.99 | S19: https://www.tim.com.br/sp/para-voce/planos/controle | T19: data/raw/tim_control_SP.html
A20: 2026-06-22 | B20: 2026-06-22T18:35:49 | C20: tim | D20: postpaid | E20: SP | F20: TIM Black 70GB | G20: tim:54206 | H20: 129.99 | K20: 70 | S20: https://www.tim.com.br/sp/para-voce/planos/pos-pago/tim-black | T20: data/raw/tim_postpaid_SP.html
A21: 2026-06-22 | B21: 2026-06-22T18:35:49 | C21: tim | D21: postpaid | E21: SP | F21: TIM Black A Express 67GB | G21: tim:55121 | H21: 119.99 | K21: 67 | S21: https://www.tim.com.br/sp/para-voce/planos/pos-pago/tim-black | T21: data/raw/tim_postpaid_SP.html
A22: 2026-06-22 | B22: 2026-06-22T18:35:49 | C22: tim | D22: postpaid | E22: SP | F22: TIM Black B Express 82GB | G22: tim:52146 | H22: 144.99 | K22: 82 | S22: https://www.tim.com.br/sp/para-voce/planos/pos-pago/tim-black | T22: data/raw/tim_postpaid_SP.html
A23: 2026-06-22 | B23: 2026-06-22T18:35:49 | C23: tim | D23: postpaid | E23: SP | F23: TIM Black C Express 107GB | G23: tim:52151 | H23: 164.99 | K23: 107 | S23: https://www.tim.com.br/sp/para-voce/planos/pos-pago/tim-black | T23: data/raw/tim_postpaid_SP.html
A24: 2026-06-22 | B24: 2026-06-22T18:35:49 | C24: tim | D24: postpaid | E24: SP | F24: TIM Black C Ultra 95GB | G24: tim:100581 | H24: 159.99 | K24: 95 | S24: https://www.tim.com.br/sp/para-voce/planos/pos-pago/tim-black | T24: data/raw/tim_postpaid_SP.html
A25: 2026-06-22 | B25: 2026-06-22T18:35:49 | C25: tim | D25: postpaid | E25: SP | F25: TIM Black Plus 80GB | G25: tim:54256 | H25: 149.99 | K25: 80 | S25: https://www.tim.com.br/sp/para-voce/planos/pos-pago/tim-black | T25: data/raw/tim_postpaid_SP.html
A26: 2026-06-22 | B26: 2026-06-22T18:35:49 | C26: tim | D26: postpaid | E26: SP | F26: TIM Black Premium 110GB | G26: tim:54261 | H26: 159.99 | K26: 110 | S26: https://www.tim.com.br/sp/para-voce/planos/pos-pago/tim-black | T26: data/raw/tim_postpaid_SP.html
A27: 2026-06-22 | B27: 2026-06-22T18:35:49 | C27: tim | D27: prepaid | E27: SP | F27: TIM Pré XIP Plus 16GB | G27: tim:106306 | H27: 30 | K27: 16 | S27: https://www.tim.com.br/sp/para-voce/planos/pre-pago | T27: data/raw/tim_prepaid_SP.html
A28: 2026-06-22 | B28: 2026-06-22T18:35:49 | C28: tim | D28: prepaid | E28: SP | F28: TIM Pré XIP Plus 6GB | G28: tim:59906 | H28: 20 | K28: 6 | S28: https://www.tim.com.br/sp/para-voce/planos/pre-pago | T28: data/raw/tim_prepaid_SP.html
A29: 2026-06-22 | B29: 2026-06-22T18:35:49 | C29: tim | D29: prepaid | E29: SP | F29: TIM Pré XIP Plus 8GB | G29: tim:59901 | H29: 25 | K29: 8 | S29: https://www.tim.com.br/sp/para-voce/planos/pre-pago | T29: data/raw/tim_prepaid_SP.html
A30: 2026-06-22 | B30: 2026-06-22T18:35:49 | C30: vivo | D30: control | E30: SP | F30: Vivo Controle | G30: vivo:VIV202600029270-46gb | H30: 59 | K30: 46 | L30: 15 GB de franquia 31 GB de bônus | R30: 6 meses grátis de Gemini com AI Plus | S30: https://vivo.com.br/para-voce/produtos-e-servicos/para-o-celular/planos-controle | T30: data/raw/vivo_control_SP.html
A31: 2026-06-22 | B31: 2026-06-22T18:35:49 | C31: vivo | D31: control | E31: SP | F31: Vivo Controle | G31: vivo:VIV202600029300-61gb | H31: 80 | K31: 61 | L31: 20 GB de franquia 31 GB de bônus | R31: 6 meses grátis de Gemini com AI Plus | S31: https://vivo.com.br/para-voce/produtos-e-servicos/para-o-celular/planos-controle | T31: data/raw/vivo_control_SP.html
A32: 2026-06-22 | B32: 2026-06-22T18:35:49 | C32: vivo | D32: control | E32: SP | F32: Vivo Controle Educação | G32: vivo:VIV202600029273-61gb | H32: 90 | K32: 61 | L32: 20 GB de franquia 31 GB de bônus | R32: Assinatura Vivae inclusa | S32: https://vivo.com.br/para-voce/produtos-e-servicos/para-o-celular/planos-controle | T32: data/raw/vivo_control_SP.html
A33: 2026-06-22 | B33: 2026-06-22T18:35:49 | C33: vivo | D33: control | E33: SP | F33: Vivo Controle Entretenimento | G33: vivo:VIV202600029307-61gb | H33: 110 | K33: 61 | L33: 20 GB de franquia 31 GB de bônus | R33: Assinatura Vivo TV Inicial inclusa | S33: https://vivo.com.br/para-voce/produtos-e-servicos/para-o-celular/planos-controle | T33: data/raw/vivo_control_SP.html
A34: 2026-06-22 | B34: 2026-06-22T18:35:49 | C34: vivo | D34: control | E34: SP | F34: Vivo Controle Música | G34: vivo:VIV202600029313-61gb | H34: 95 | K34: 61 | L34: 20 GB de franquia 31 GB de bônus | R34: Apple Music Individual | S34: https://vivo.com.br/para-voce/produtos-e-servicos/para-o-celular/planos-controle | T34: data/raw/vivo_control_SP.html
A35: 2026-06-22 | B35: 2026-06-22T18:35:49 | C35: vivo | D35: control | E35: SP | F35: Vivo Controle Netflix | G35: vivo:VIV202600029308-61gb | H35: 95 | K35: 61 | L35: 20 GB de franquia 31 GB de bônus | R35: Assinatura Netflix Padrão com anúncios | S35: https://vivo.com.br/para-voce/produtos-e-servicos/para-o-celular/planos-controle | T35: data/raw/vivo_control_SP.html
A36: 2026-06-22 | B36: 2026-06-22T18:35:49 | C36: vivo | D36: control | E36: SP | F36: Vivo Controle Saúde | G36: vivo:VIV202600029301-61gb | H36: 90 | K36: 61 | L36: 20 GB de franquia 31 GB de bônus | R36: Assinatura Vale Saúde Sempre inclusa | S36: https://vivo.com.br/para-voce/produtos-e-servicos/para-o-celular/planos-controle | T36: data/raw/vivo_control_SP.html
A37: 2026-06-22 | B37: 2026-06-22T18:35:49 | C37: vivo | D37: lite | E37: SP | F37: Easy Lite | G37: vivo:VIV202600005312-30gb | H37: 30 | K37: 30 | L37: 30 GB de franquia 2 Meses de YouTube ilimitado | S37: https://vivo.com.br/para-voce/produtos-e-servicos/para-o-celular/easy-lite | T37: data/raw/vivo_lite_SP.html
A38: 2026-06-22 | B38: 2026-06-22T18:35:49 | C38: vivo | D38: lite | E38: SP | F38: Easy Lite | G38: vivo:VIV202600019134-40gb | H38: 40 | K38: 40 | L38: 40 GB de franquia 2 Meses de YouTube ilimitado | S38: https://vivo.com.br/para-voce/produtos-e-servicos/para-o-celular/easy-lite | T38: data/raw/vivo_lite_SP.html
A39: 2026-06-22 | B39: 2026-06-22T18:35:49 | C39: vivo | D39: lite | E39: SP | F39: Easy Lite | G39: vivo:VIV202600019132-20gb | H39: 35 | K39: 20 | L39: 20 GB de franquia 2 Meses de YouTube ilimitado | S39: https://vivo.com.br/para-voce/produtos-e-servicos/para-o-celular/easy-lite | T39: data/raw/vivo_lite_SP.html
A40: 2026-06-22 | B40: 2026-06-22T18:35:49 | C40: vivo | D40: lite | E40: SP | F40: Easy Lite | G40: vivo:VIV202600019127-30gb | H40: 40 | K40: 30 | S40: https://vivo.com.br/para-voce/produtos-e-servicos/para-o-celular/easy-lite | T40: data/raw/vivo_lite_SP.html
...

Sheet changes
A1: change_type | B1: carrier | C1: category | D1: state | E1: plan_id | F1: plan_name | G1: old_price_brl | H1: new_price_brl | I1: delta_brl

Sheet summary
A1: Mobile Price Tracker — Summary
A3: Run timestamp | B3: 2026-06-22T18:35:49
A4: Latest snapshot | B4: 2026-06-22
A5: Plans in latest | B5: 51
A6: Snapshots in history | B6: 1
A8: carrier | B8: # plans | C8: min price | D8: avg price | E8: max price
A9: vivo | B9: =COUNTIF(latest!$C$2:$C$2000,$A$9) | C9: =IFERROR(_xlfn.MINIFS(latest!$H$2:$H$2000,latest!$C$2:$C$2000,$A$9),"-") | D9: =IFERROR(AVERAGEIFS(latest!$H$2:$H$2000,latest!$C$2:$C$2000,$A$9),"-") | E9: =IFERROR(_xlfn.MAXIFS(latest!$H$2:$H$2000,latest!$C$2:$C$2000,$A$9),"-")
A10: claro | B10: =COUNTIF(latest!$C$2:$C$2000,$A$10) | C10: =IFERROR(_xlfn.MINIFS(latest!$H$2:$H$2000,latest!$C$2:$C$2000,$A$10),"-") | D10: =IFERROR(AVERAGEIFS(latest!$H$2:$H$2000,latest!$C$2:$C$2000,$A$10),"-") | E10: =IFERROR(_xlfn.MAXIFS(latest!$H$2:$H$2000,latest!$C$2:$C$2000,$A$10),"-")
A11: tim | B11: =COUNTIF(latest!$C$2:$C$2000,$A$11) | C11: =IFERROR(_xlfn.MINIFS(latest!$H$2:$H$2000,latest!$C$2:$C$2000,$A$11),"-") | D11: =IFERROR(AVERAGEIFS(latest!$H$2:$H$2000,latest!$C$2:$C$2000,$A$11),"-") | E11: =IFERROR(_xlfn.MAXIFS(latest!$H$2:$H$2000,latest!$C$2:$C$2000,$A$11),"-")

Sheet comparison
A1: Price evolution — cheapest R$ per carrier × category, by date
A35: Date | B35: Control (R$/mo) | E35: Post (R$/mo) | H35: Pre (R$, recarga) | K35: Digital (R$/mo)
B36: TIM | C36: Vivo | D36: Claro | E36: TIM | F36: Vivo | G36: Claro | H36: TIM | I36: Vivo | J36: Claro | K36: TIM | L36: Vivo | M36: Claro
A37: 2026-06-22 | B37: =IF(_xlfn.MINIFS(history!$H:$H,history!$C:$C,"tim",history!$D:$D,"control",history!$A:$A,$A37)=0,"",_xlfn.MINIFS(history!$H:$H,history!$C:$C,"tim",history!$D:$D,"control",history!$A:$A,$A37)) | C37: =IF(_xlfn.MINIFS(history!$H:$H,history!$C:$C,"vivo",history!$D:$D,"control",history!$A:$A,$A37)=0,"",_xlfn.MINIFS(history!$H:$H,history!$C:$C,"vivo",history!$D:$D,"control",history!$A:$A,$A37)) | D37: =IF(_xlfn.MINIFS(history!$H:$H,history!$C:$C,"claro",history!$D:$D,"control",history!$A:$A,$A37)=0,"",_xlfn.MINIFS(history!$H:$H,history!$C:$C,"claro",history!$D:$D,"control",history!$A:$A,$A37)) | E37: =IF(_xlfn.MINIFS(history!$H:$H,history!$C:$C,"tim",history!$D:$D,"postpaid",history!$A:$A,$A37)=0,"",_xlfn.MINIFS(history!$H:$H,history!$C:$C,"tim",history!$D:$D,"postpaid",history!$A:$A,$A37)) | F37: =IF(_xlfn.MINIFS(history!$H:$H,history!$C:$C,"vivo",history!$D:$D,"postpaid",history!$A:$A,$A37)=0,"",_xlfn.MINIFS(history!$H:$H,history!$C:$C,"vivo",history!$D:$D,"postpaid",history!$A:$A,$A37)) | G37: =IF(_xlfn.MINIFS(history!$H:$H,history!$C:$C,"claro",history!$D:$D,"postpaid",history!$A:$A,$A37)=0,"",_xlfn.MINIFS(history!$H:$H,history!$C:$C,"claro",history!$D:$D,"postpaid",history!$A:$A,$A37)) | H37: =IF(_xlfn.MINIFS(history!$H:$H,history!$C:$C,"tim",history!$D:$D,"prepaid",history!$A:$A,$A37)=0,"",_xlfn.MINIFS(history!$H:$H,history!$C:$C,"tim",history!$D:$D,"prepaid",history!$A:$A,$A37)) | I37: =IF(_xlfn.MINIFS(history!$H:$H,history!$C:$C,"vivo",history!$D:$D,"prepaid",history!$A:$A,$A37)=0,"",_xlfn.MINIFS(history!$H:$H,history!$C:$C,"vivo",history!$D:$D,"prepaid",history!$A:$A,$A37)) | J37: =IF(_xlfn.MINIFS(history!$H:$H,history!$C:$C,"claro",history!$D:$D,"prepaid",history!$A:$A,$A37)=0,"",_xlfn.MINIFS(history!$H:$H,history!$C:$C,"claro",history!$D:$D,"prepaid",history!$A:$A,$A37)) | K37: =IFERROR(1/MAX(IFERROR(1/_xlfn.MINIFS(history!$H:$H,history!$C:$C,"tim",history!$D:$D,"lite",history!$A:$A,$A37),0),IFERROR(1/_xlfn.MINIFS(history!$H:$H,history!$C:$C,"tim",history!$D:$D,"flex",history!$A:$A,$A37),0)),"") | L37: =IFERROR(1/MAX(IFERROR(1/_xlfn.MINIFS(history!$H:$H,history!$C:$C,"vivo",history!$D:$D,"lite",history!$A:$A,$A37),0),IFERROR(1/_xlfn.MINIFS(history!$H:$H,history!$C:$C,"vivo",history!$D:$D,"flex",history!$A:$A,$A37),0)),"") | M37: =IFERROR(1/MAX(IFERROR(1/_xlfn.MINIFS(history!$H:$H,history!$C:$C,"claro",history!$D:$D,"lite",history!$A:$A,$A37),0),IFERROR(1/_xlfn.MINIFS(history!$H:$H,history!$C:$C,"claro",history!$D:$D,"flex",history!$A:$A,$A37),0)),"")
A39: Pre = cheapest recharge amount captured (true R$/day needs validity-days we don't yet capture — CONTEXT §8). Digital = min of Vivo Lite / Claro Flex. Daily rows now; monthly roll-up is the planned next step.

Sheet Ranking
A1: Ranking (today) — within category, aligned by price rank
A3: Pure Postpaid
A4: Rank | B4: Vivo R$ | C4: Claro R$ | D4: TIM R$ | E4: Vivo plan | F4: Claro plan | G4: TIM plan
A5: 1 | B5: 150 | C5: 124.9 | D5: 119.99 | E5: Vivo Pós com Amazon (60GB) | F5: Pós 60GB (60GB) | G5: TIM Black A Express 67GB (67GB)
A6: 2 | B6: 165 | C6: 164.9 | D6: 129.99 | E6: Vivo Pós com Globoplay (60GB) | F6: Pós 50GB com GeForce NOW (50GB) | G6: TIM Black 70GB (70GB)
A7: 3 | B7: 165 | C7: 179.9 | D7: 144.99 | E7: Vivo Pós com Spotify (60GB) | F7: Pós 100GB (100GB) | G7: TIM Black B Express 82GB (82GB)
A8: 4 | B8: 180 | C8: 239.9 | D8: 149.99 | E8: Vivo Pós com Disney+ (60GB) | F8: Pós 150GB (150GB) | G8: TIM Black Plus 80GB (80GB)
A9: 5 | B9: 180 | C9: 339.9 | D9: 159.99 | E9: Vivo Pós com Netflix (60GB) | F9: Pós 200GB (200GB) | G9: TIM Black C Ultra 95GB (95GB)
A10: 6 | B10: 180 | D10: 159.99 | E10: Vivo Pós com Premiere (60GB) | G10: TIM Black Premium 110GB (110GB)
A11: 7 | B11: 215 | D11: 164.99 | E11: Vivo Pós com Travel (70GB) | G11: TIM Black C Express 107GB (107GB)
A13: Control / Hybrid
A14: Rank | B14: Vivo R$ | C14: Claro R$ | D14: TIM R$ | E14: Vivo plan | F14: Claro plan | G14: TIM plan
A15: 1 | B15: 59 | C15: 59.9 | D15: 58.99 | E15: Vivo Controle (46GB) | F15: Controle 25GB (25GB) · promo R$54.9 | G15: TIM Controle 41GB (41GB)
A16: 2 | B16: 80 | C16: 69.9 | D16: 60.99 | E16: Vivo Controle (61GB) | F16: Controle 30GB (30GB) | G16: TIM Controle Light Express 31GB (31GB)
A17: 3 | B17: 90 | C17: 99.9 | D17: 64.99 | E17: Vivo Controle Educação (61GB) | F17: Controle 30GB (30GB) | G17: TIM Controle Plus 45GB (45GB)
A18: 4 | B18: 90 | D18: 64.99 | E18: Vivo Controle Saúde (61GB) | G18: TIM Controle Pro Express
A19: 5 | B19: 95 | D19: 84.99 | E19: Vivo Controle Música (61GB) | G19: TIM Controle Premium 53GB (53GB)
A20: 6 | B20: 95 | E20: Vivo Controle Netflix (61GB)
A21: 7 | B21: 110 | E21: Vivo Controle Entretenimento (61GB)
A23: Prepaid
A24: Note: prepaid is not a clean unit — Claro Prezão is a daily fee (R$1/dia) vs Vivo/TIM recharge amounts.
A25: Rank | B25: Vivo R$ | C25: Claro R$ | D25: TIM R$ | E25: Vivo plan | F25: Claro plan | G25: TIM plan
A26: 1 | B26: 17 | C26: 1 | D26: 20 | E26: Vivo Pré (4GB) | F26: Prezão R$1 por dia (12GB) | G26: TIM Pré XIP Plus 6GB (6GB)
A27: 2 | B27: 20 | D27: 25 | E27: Vivo Pré (5GB) | G27: TIM Pré XIP Plus 8GB (8GB)
A28: 3 | B28: 25 | D28: 30 | E28: Vivo Pré (9GB) | G28: TIM Pré XIP Plus 16GB (16GB)
A29: 4 | B29: 30 | E29: Vivo Pré (25GB)
A31: Digital
A32: Digital = Vivo Lite + Claro Flex (TIM has no digital line).
A33: Rank | B33: Vivo R$ | C33: Claro R$ | D33: TIM R$ | E33: Vivo plan | F33: Claro plan | G33: TIM plan
A34: 1 | B34: 30 | C34: 44.9 | E34: Easy Lite (30GB) | F34: Flex 15GB (15GB)
A35: 2 | B35: 35 | C35: 59.9 | E35: Easy Lite (20GB) | F35: Flex 20GB (20GB)
A36: 3 | B36: 40 | C36: 69.9 | E36: Easy Lite (40GB) | F36: Flex 30GB (30GB)
A37: 4 | B37: 40 | C37: 119.9 | E37: Easy Lite (30GB) | F37: Flex 40GB (40GB)
A38: 5 | B38: 50 | E38: Easy Lite (40GB)

Sheet Vivo
A1: Plan | B1: Price R$ | C1: Promo R$ | D1: Data | E1: Voice | F1: Unlimited apps | G1: Streaming | H1: Notes
A2: Postpaid
A3: Vivo Pós com Amazon | B3: 150 | D3: 60 GB (50 GB de franquia 10 GB de bônus) | H3: Assinatura Amazon Prime inclusa
A4: Vivo Pós com Globoplay | B4: 165 | D4: 60 GB (50 GB de franquia 10 GB de bônus) | G4: Globoplay | H4: Assinatura Globoplay inclusa
A5: Vivo Pós com Spotify | B5: 165 | D5: 60 GB (50 GB de franquia 10 GB de bônus) | G5: Spotify | H5: Assinatura Spotify Premium inclusa
A6: Vivo Pós com Disney+ | B6: 180 | D6: 60 GB (50 GB de franquia 10 GB de bônus) | G6: Disney+ | H6: Assinatura Disney+ Padrão inclusa
A7: Vivo Pós com Netflix | B7: 180 | D7: 60 GB (50 GB de franquia 10 GB de bônus) | G7: Netflix | H7: Assinatura Netflix Padrão inclusa
A8: Vivo Pós com Premiere | B8: 180 | D8: 60 GB (50 GB de franquia 10 GB de bônus) | G8: Premiere | H8: Assinatura Premiere inclusa
A9: Vivo Pós com Travel | B9: 215 | D9: 70 GB (60 GB de franquia 10 GB de bônus) | H9: 6 meses grátis de Gemini com AI Plus
A10: Control
A11: Vivo Controle | B11: 59 | D11: 46 GB (15 GB de franquia 31 GB de bônus) | H11: 6 meses grátis de Gemini com AI Plus
A12: Vivo Controle | B12: 80 | D12: 61 GB (20 GB de franquia 31 GB de bônus) | H12: 6 meses grátis de Gemini com AI Plus
A13: Vivo Controle Educação | B13: 90 | D13: 61 GB (20 GB de franquia 31 GB de bônus) | H13: Assinatura Vivae inclusa
A14: Vivo Controle Saúde | B14: 90 | D14: 61 GB (20 GB de franquia 31 GB de bônus) | H14: Assinatura Vale Saúde Sempre inclusa
A15: Vivo Controle Música | B15: 95 | D15: 61 GB (20 GB de franquia 31 GB de bônus) | H15: Apple Music Individual
A16: Vivo Controle Netflix | B16: 95 | D16: 61 GB (20 GB de franquia 31 GB de bônus) | H16: Assinatura Netflix Padrão com anúncios
A17: Vivo Controle Entretenimento | B17: 110 | D17: 61 GB (20 GB de franquia 31 GB de bônus) | H17: Assinatura Vivo TV Inicial inclusa
A18: Digital
A19: Easy Lite | B19: 30 | D19: 30 GB (30 GB de franquia 2 Meses de YouTube ilimitado)
A20: Easy Lite | B20: 35 | D20: 20 GB (20 GB de franquia 2 Meses de YouTube ilimitado)
A21: Easy Lite | B21: 40 | D21: 40 GB (40 GB de franquia 2 Meses de YouTube ilimitado)
A22: Easy Lite | B22: 40 | D22: 30 GB
A23: Easy Lite | B23: 50 | D23: 40 GB
A24: Prepaid
A25: Vivo Pré | B25: 17 | D25: 4 GB (4 GB para navegar como quiser)
A26: Vivo Pré | B26: 20 | D26: 5 GB (5 GB para navegar como quiser)
A27: Vivo Pré | B27: 25 | D27: 9 GB (6 GB para navegar como quiser 3 GB para navegar no YouTube)
A28: Vivo Pré | B28: 30 | D28: 25 GB (15 GB para navegar como quiser 5 GB de bônus 5 GB para navegar no Youtube)

Sheet Claro
A1: Plan | B1: Price R$ | C1: Promo R$ | D1: Data | E1: Voice | F1: Unlimited apps | G1: Streaming | H1: Notes
A2: Postpaid
A3: Pós 60GB | B3: 124.9 | D3: 60 GB | F3: WhatsApp | H3: Armazenamento na nuvem:; Google One ou iCloud+; WhatsApp ilimitado; Roaming: Passaporte Américas; Claro Sync: Smartwatch conectado
A4: Pós 50GB com GeForce NOW | B4: 164.9 | D4: 50 GB | F4: WhatsApp | H4: Armazenamento na nuvem:; Google One ou iCloud+; WhatsApp ilimitado; Roaming: Passaporte Américas; Claro Sync: Smartwatch conectado; Inclusa assinatura GeForce NOW
A5: Pós 100GB | B5: 179.9 | D5: 100 GB | F5: WhatsApp | H5: Armazenamento na nuvem:; Google One ou iCloud+; WhatsApp ilimitado; Roaming: Passaporte Américas; Claro Sync: Smartwatch conectado
A6: Pós 150GB | B6: 239.9 | D6: 150 GB | F6: WhatsApp | H6: Armazenamento na nuvem:; Google One ou iCloud+; WhatsApp ilimitado; Roaming: Passaporte Américas e Europa; Claro Sync: Smartwatch conectado
A7: Pós 200GB | B7: 339.9 | D7: 200 GB | F7: WhatsApp | H7: Armazenamento na nuvem:; Google One ou iCloud+; WhatsApp ilimitado; Roaming: Passaporte Mundo; Claro Sync: Smartwatch conectado
A8: Control
A9: Controle 25GB | B9: 59.9 | C9: 54.9 | D9: 25 GB | F9: WhatsApp | H9: Para uso livre; Para redes sociais e vídeos; Bônus exclusivo; Aproveite na sua franquia; WhatsApp e ligações ilimitadas · De R$ 59,90 Por:
A10: Controle 30GB | B10: 69.9 | D10: 30 GB | F10: WhatsApp | H10: Para uso livre; Bônus do Hexa para uso livre; Bônus para redes sociais e apps; Redes sociais e apps; WhatsApp ilimitado
A11: Controle 30GB | B11: 99.9 | D11: 30 GB | F11: WhatsApp | H11: Para uso livre; Bônus para redes sociais e apps; Bônus uso livre; Redes sociais e apps; WhatsApp ilimitado
A12: Digital
A13: Flex 15GB | B13: 44.9 | D13: 15 GB | F13: WhatsApp | H13: Para uso livre; Bônus do Hexa para uso livre; Para redes sociais e apps; Bônus extra nos apps; WhatsApp ilimitado
A14: Flex 20GB | B14: 59.9 | D14: 20 GB | F14: WhatsApp | H14: Para uso livre; Bônus do Hexa para uso livre; Para redes sociais e apps; Bônus extra nos apps; WhatsApp ilimitado
A15: Flex 30GB | B15: 69.9 | D15: 30 GB | F15: WhatsApp | H15: Para uso livre; Bônus do Hexa para uso livre; Para redes sociais e apps; Bônus extra nos apps; WhatsApp ilimitado; Assinatura Claro musica inclusa
A16: Flex 40GB | B16: 119.9 | D16: 40 GB | F16: WhatsApp | H16: Para uso livre; Para redes sociais e apps; Bônus uso livre; Bônus extra nos apps; WhatsApp ilimitado; Assinatura Claro musica inclusa
A17: Prepaid
A18: Prezão R$1 por dia | B18: 1 | D18: 12 GB | H18: prepaid Prezão — preço por dia; recargas a partir de R$15

Sheet TIM
A1: Plan | B1: Price R$ | C1: Promo R$ | D1: Data | E1: Voice | F1: Unlimited apps | G1: Streaming | H1: Notes
A2: Postpaid
A3: TIM Black A Express 67GB | B3: 119.99 | D3: 67 GB
A4: TIM Black 70GB | B4: 129.99 | D4: 70 GB
A5: TIM Black B Express 82GB | B5: 144.99 | D5: 82 GB
A6: TIM Black Plus 80GB | B6: 149.99 | D6: 80 GB
A7: TIM Black C Ultra 95GB | B7: 159.99 | D7: 95 GB
A8: TIM Black Premium 110GB | B8: 159.99 | D8: 110 GB
A9: TIM Black C Express 107GB | B9: 164.99 | D9: 107 GB
A10: Control
A11: TIM Controle 41GB | B11: 58.99 | D11: 41 GB
A12: TIM Controle Light Express 31GB | B12: 60.99 | D12: 31 GB
A13: TIM Controle Plus 45GB | B13: 64.99 | D13: 45 GB
A14: TIM Controle Pro Express | B14: 64.99
A15: TIM Controle Premium 53GB | B15: 84.99 | D15: 53 GB
A16: Prepaid
A17: TIM Pré XIP Plus 6GB | B17: 20 | D17: 6 GB
A18: TIM Pré XIP Plus 8GB | B18: 25 | D18: 8 GB
A19: TIM Pré XIP Plus 16GB | B19: 30 | D19: 16 GB
