Workbook

Sheet history
A1: snapshot_date | B1: snapshot_ts | C1: carrier | D1: category | E1: state | F1: plan_name | G1: plan_id | H1: price_brl | I1: price_promo_brl | J1: price_note | K1: data_gb | L1: data_note | M1: validity_days | N1: unlimited_apps | O1: voice | P1: sms | Q1: streaming | R1: loyalty_months | S1: extra_benefits | T1: source_url | U1: raw_ref
A2: 2026-06-22 | B2: 2026-06-22T22:45:24 | C2: claro | D2: control | E2: SP | F2: Controle 25GB | G2: claro:plano-controle-25gb | H2: 59.9 | I2: 54.9 | J2: De R$ 59,90 Por: | K2: 25 | N2: WhatsApp | S2: Para uso livre; Para redes sociais e vídeos; Bônus exclusivo; Aproveite na sua franquia; WhatsApp e ligações ilimitadas | T2: https://www.claro.com.br/celular/controle | U2: data/raw/claro_control_SP.json
A3: 2026-06-22 | B3: 2026-06-22T22:45:24 | C3: claro | D3: control | E3: SP | F3: Controle 30GB | G3: claro:plano-controle-30gb | H3: 69.9 | K3: 30 | N3: WhatsApp | S3: Para uso livre; Bônus do Hexa para uso livre; Bônus para redes sociais e apps; Redes sociais e apps; WhatsApp ilimitado | T3: https://www.claro.com.br/celular/controle | U3: data/raw/claro_control_SP.json
A4: 2026-06-22 | B4: 2026-06-22T22:45:24 | C4: claro | D4: control | E4: SP | F4: Controle 30GB | G4: claro:plano-controle-30gb-gaming | H4: 99.9 | K4: 30 | N4: WhatsApp | S4: Para uso livre; Bônus para redes sociais e apps; Bônus uso livre; Redes sociais e apps; WhatsApp ilimitado | T4: https://www.claro.com.br/celular/controle | U4: data/raw/claro_control_SP.json
A5: 2026-06-22 | B5: 2026-06-22T22:45:24 | C5: claro | D5: flex | E5: SP | F5: Flex 15GB | G5: claro:plano-flex-15gb | H5: 44.9 | K5: 15 | N5: WhatsApp | S5: Para uso livre; Bônus do Hexa para uso livre; Para redes sociais e apps; Bônus extra nos apps; WhatsApp ilimitado | T5: https://www.claro.com.br/celular/flex | U5: data/raw/claro_flex_SP.json
A6: 2026-06-22 | B6: 2026-06-22T22:45:24 | C6: claro | D6: flex | E6: SP | F6: Flex 20GB | G6: claro:plano-flex-20gb | H6: 59.9 | K6: 20 | N6: WhatsApp | S6: Para uso livre; Bônus do Hexa para uso livre; Para redes sociais e apps; Bônus extra nos apps; WhatsApp ilimitado | T6: https://www.claro.com.br/celular/flex | U6: data/raw/claro_flex_SP.json
A7: 2026-06-22 | B7: 2026-06-22T22:45:24 | C7: claro | D7: flex | E7: SP | F7: Flex 30GB | G7: claro:plano-flex-30gb | H7: 69.9 | K7: 30 | N7: WhatsApp | S7: Para uso livre; Bônus do Hexa para uso livre; Para redes sociais e apps; Bônus extra nos apps; WhatsApp ilimitado; Assinatura Claro musica inclusa | T7: https://www.claro.com.br/celular/flex | U7: data/raw/claro_flex_SP.json
A8: 2026-06-22 | B8: 2026-06-22T22:45:24 | C8: claro | D8: flex | E8: SP | F8: Flex 40GB | G8: claro:plano-flex-40gb | H8: 119.9 | K8: 40 | N8: WhatsApp | S8: Para uso livre; Para redes sociais e apps; Bônus uso livre; Bônus extra nos apps; WhatsApp ilimitado; Assinatura Claro musica inclusa | T8: https://www.claro.com.br/celular/flex | U8: data/raw/claro_flex_SP.json
A9: 2026-06-22 | B9: 2026-06-22T22:45:24 | C9: claro | D9: postpaid | E9: SP | F9: Pós 100GB | G9: claro:plano-pos-100gb | H9: 179.9 | K9: 100 | N9: WhatsApp | S9: Armazenamento na nuvem:; Google One ou iCloud+; WhatsApp ilimitado; Roaming: Passaporte Américas; Claro Sync: Smartwatch conectado | T9: https://www.claro.com.br/celular/pos | U9: data/raw/claro_postpaid_SP.json
A10: 2026-06-22 | B10: 2026-06-22T22:45:24 | C10: claro | D10: postpaid | E10: SP | F10: Pós 150GB | G10: claro:plano-pos-150gb | H10: 239.9 | K10: 150 | N10: WhatsApp | S10: Armazenamento na nuvem:; Google One ou iCloud+; WhatsApp ilimitado; Roaming: Passaporte Américas e Europa; Claro Sync: Smartwatch conectado | T10: https://www.claro.com.br/celular/pos | U10: data/raw/claro_postpaid_SP.json
A11: 2026-06-22 | B11: 2026-06-22T22:45:24 | C11: claro | D11: postpaid | E11: SP | F11: Pós 200GB | G11: claro:plano-pos-200gb | H11: 339.9 | K11: 200 | N11: WhatsApp | S11: Armazenamento na nuvem:; Google One ou iCloud+; WhatsApp ilimitado; Roaming: Passaporte Mundo; Claro Sync: Smartwatch conectado | T11: https://www.claro.com.br/celular/pos | U11: data/raw/claro_postpaid_SP.json
A12: 2026-06-22 | B12: 2026-06-22T22:45:24 | C12: claro | D12: postpaid | E12: SP | F12: Pós 50GB com GeForce NOW | G12: claro:plano-pos-60gb-geforce | H12: 164.9 | K12: 50 | N12: WhatsApp | S12: Armazenamento na nuvem:; Google One ou iCloud+; WhatsApp ilimitado; Roaming: Passaporte Américas; Claro Sync: Smartwatch conectado; Inclusa assinatura GeForce NOW | T12: https://www.claro.com.br/celular/pos | U12: data/raw/claro_postpaid_SP.json
A13: 2026-06-22 | B13: 2026-06-22T22:45:24 | C13: claro | D13: postpaid | E13: SP | F13: Pós 60GB | G13: claro:plano-pos-60gb | H13: 124.9 | K13: 60 | N13: WhatsApp | S13: Armazenamento na nuvem:; Google One ou iCloud+; WhatsApp ilimitado; Roaming: Passaporte Américas; Claro Sync: Smartwatch conectado | T13: https://www.claro.com.br/celular/pos | U13: data/raw/claro_postpaid_SP.json
A14: 2026-06-22 | B14: 2026-06-22T22:45:24 | C14: claro | D14: prepaid | E14: SP | F14: Prezão R$1 por dia | G14: claro:prez-o-r-1-por-dia | H14: 1 | J14: prepaid Prezão — preço por dia; recargas a partir de R$15 | K14: 12 | T14: https://www.claro.com.br/celular/planos-pre/prezao | U14: data/raw/claro_prepaid_SP.json
A15: 2026-06-22 | B15: 2026-06-22T22:45:24 | C15: tim | D15: control | E15: SP | F15: TIM Controle 41GB | G15: tim:162901 | H15: 58.99 | K15: 41 | T15: https://www.tim.com.br/sp/para-voce/planos/controle | U15: data/raw/tim_control_SP.html
A16: 2026-06-22 | B16: 2026-06-22T22:45:24 | C16: tim | D16: control | E16: SP | F16: TIM Controle Light Express 31GB | G16: tim:143536 | H16: 60.99 | K16: 31 | T16: https://www.tim.com.br/sp/para-voce/planos/controle | U16: data/raw/tim_control_SP.html
A17: 2026-06-22 | B17: 2026-06-22T22:45:24 | C17: tim | D17: control | E17: SP | F17: TIM Controle Plus 45GB | G17: tim:155891 | H17: 64.99 | K17: 45 | T17: https://www.tim.com.br/sp/para-voce/planos/controle | U17: data/raw/tim_control_SP.html
A18: 2026-06-22 | B18: 2026-06-22T22:45:24 | C18: tim | D18: control | E18: SP | F18: TIM Controle Premium 53GB | G18: tim:162896 | H18: 84.99 | K18: 53 | T18: https://www.tim.com.br/sp/para-voce/planos/controle | U18: data/raw/tim_control_SP.html
A19: 2026-06-22 | B19: 2026-06-22T22:45:24 | C19: tim | D19: control | E19: SP | F19: TIM Controle Pro Express | G19: tim:143576 | H19: 64.99 | T19: https://www.tim.com.br/sp/para-voce/planos/controle | U19: data/raw/tim_control_SP.html
A20: 2026-06-22 | B20: 2026-06-22T22:45:24 | C20: tim | D20: postpaid | E20: SP | F20: TIM Black 70GB | G20: tim:54206 | H20: 129.99 | K20: 70 | T20: https://www.tim.com.br/sp/para-voce/planos/pos-pago/tim-black | U20: data/raw/tim_postpaid_SP.html
A21: 2026-06-22 | B21: 2026-06-22T22:45:24 | C21: tim | D21: postpaid | E21: SP | F21: TIM Black A Express 67GB | G21: tim:55121 | H21: 119.99 | K21: 67 | T21: https://www.tim.com.br/sp/para-voce/planos/pos-pago/tim-black | U21: data/raw/tim_postpaid_SP.html
A22: 2026-06-22 | B22: 2026-06-22T22:45:24 | C22: tim | D22: postpaid | E22: SP | F22: TIM Black B Express 82GB | G22: tim:52146 | H22: 144.99 | K22: 82 | T22: https://www.tim.com.br/sp/para-voce/planos/pos-pago/tim-black | U22: data/raw/tim_postpaid_SP.html
A23: 2026-06-22 | B23: 2026-06-22T22:45:24 | C23: tim | D23: postpaid | E23: SP | F23: TIM Black C Express 107GB | G23: tim:52151 | H23: 164.99 | K23: 107 | T23: https://www.tim.com.br/sp/para-voce/planos/pos-pago/tim-black | U23: data/raw/tim_postpaid_SP.html
A24: 2026-06-22 | B24: 2026-06-22T22:45:24 | C24: tim | D24: postpaid | E24: SP | F24: TIM Black C Ultra 95GB | G24: tim:100581 | H24: 159.99 | K24: 95 | T24: https://www.tim.com.br/sp/para-voce/planos/pos-pago/tim-black | U24: data/raw/tim_postpaid_SP.html
A25: 2026-06-22 | B25: 2026-06-22T22:45:24 | C25: tim | D25: postpaid | E25: SP | F25: TIM Black Plus 80GB | G25: tim:54256 | H25: 149.99 | K25: 80 | T25: https://www.tim.com.br/sp/para-voce/planos/pos-pago/tim-black | U25: data/raw/tim_postpaid_SP.html
A26: 2026-06-22 | B26: 2026-06-22T22:45:24 | C26: tim | D26: postpaid | E26: SP | F26: TIM Black Premium 110GB | G26: tim:54261 | H26: 159.99 | K26: 110 | T26: https://www.tim.com.br/sp/para-voce/planos/pos-pago/tim-black | U26: data/raw/tim_postpaid_SP.html
A27: 2026-06-22 | B27: 2026-06-22T22:45:24 | C27: tim | D27: prepaid | E27: SP | F27: TIM Pré XIP Plus 16GB | G27: tim:106306 | H27: 30 | K27: 16 | T27: https://www.tim.com.br/sp/para-voce/planos/pre-pago | U27: data/raw/tim_prepaid_SP.html
A28: 2026-06-22 | B28: 2026-06-22T22:45:24 | C28: tim | D28: prepaid | E28: SP | F28: TIM Pré XIP Plus 6GB | G28: tim:59906 | H28: 20 | K28: 6 | T28: https://www.tim.com.br/sp/para-voce/planos/pre-pago | U28: data/raw/tim_prepaid_SP.html
A29: 2026-06-22 | B29: 2026-06-22T22:45:24 | C29: tim | D29: prepaid | E29: SP | F29: TIM Pré XIP Plus 8GB | G29: tim:59901 | H29: 25 | K29: 8 | T29: https://www.tim.com.br/sp/para-voce/planos/pre-pago | U29: data/raw/tim_prepaid_SP.html
A30: 2026-06-22 | B30: 2026-06-22T22:45:24 | C30: vivo | D30: control | E30: SP | F30: Vivo Controle | G30: vivo:VIV202600029270-46gb | H30: 59 | K30: 46 | L30: 15 GB de franquia 31 GB de bônus | S30: 6 meses grátis de Gemini com AI Plus | T30: https://vivo.com.br/para-voce/produtos-e-servicos/para-o-celular/planos-controle | U30: data/raw/vivo_control_SP.html
A31: 2026-06-22 | B31: 2026-06-22T22:45:24 | C31: vivo | D31: control | E31: SP | F31: Vivo Controle | G31: vivo:VIV202600029300-61gb | H31: 80 | K31: 61 | L31: 20 GB de franquia 31 GB de bônus | S31: 6 meses grátis de Gemini com AI Plus | T31: https://vivo.com.br/para-voce/produtos-e-servicos/para-o-celular/planos-controle | U31: data/raw/vivo_control_SP.html
A32: 2026-06-22 | B32: 2026-06-22T22:45:24 | C32: vivo | D32: control | E32: SP | F32: Vivo Controle Educação | G32: vivo:VIV202600029273-61gb | H32: 90 | K32: 61 | L32: 20 GB de franquia 31 GB de bônus | S32: Assinatura Vivae inclusa | T32: https://vivo.com.br/para-voce/produtos-e-servicos/para-o-celular/planos-controle | U32: data/raw/vivo_control_SP.html
A33: 2026-06-22 | B33: 2026-06-22T22:45:24 | C33: vivo | D33: control | E33: SP | F33: Vivo Controle Entretenimento | G33: vivo:VIV202600029307-61gb | H33: 110 | K33: 61 | L33: 20 GB de franquia 31 GB de bônus | S33: Assinatura Vivo TV Inicial inclusa | T33: https://vivo.com.br/para-voce/produtos-e-servicos/para-o-celular/planos-controle | U33: data/raw/vivo_control_SP.html
A34: 2026-06-22 | B34: 2026-06-22T22:45:24 | C34: vivo | D34: control | E34: SP | F34: Vivo Controle Música | G34: vivo:VIV202600029313-61gb | H34: 95 | K34: 61 | L34: 20 GB de franquia 31 GB de bônus | S34: Apple Music Individual | T34: https://vivo.com.br/para-voce/produtos-e-servicos/para-o-celular/planos-controle | U34: data/raw/vivo_control_SP.html
A35: 2026-06-22 | B35: 2026-06-22T22:45:24 | C35: vivo | D35: control | E35: SP | F35: Vivo Controle Netflix | G35: vivo:VIV202600029308-61gb | H35: 95 | K35: 61 | L35: 20 GB de franquia 31 GB de bônus | S35: Assinatura Netflix Padrão com anúncios | T35: https://vivo.com.br/para-voce/produtos-e-servicos/para-o-celular/planos-controle | U35: data/raw/vivo_control_SP.html
A36: 2026-06-22 | B36: 2026-06-22T22:45:24 | C36: vivo | D36: control | E36: SP | F36: Vivo Controle Saúde | G36: vivo:VIV202600029301-61gb | H36: 90 | K36: 61 | L36: 20 GB de franquia 31 GB de bônus | S36: Assinatura Vale Saúde Sempre inclusa | T36: https://vivo.com.br/para-voce/produtos-e-servicos/para-o-celular/planos-controle | U36: data/raw/vivo_control_SP.html
A37: 2026-06-22 | B37: 2026-06-22T22:45:24 | C37: vivo | D37: lite | E37: SP | F37: Easy Lite | G37: vivo:VIV202600005312-30gb | H37: 30 | K37: 30 | L37: 30 GB de franquia 2 Meses de YouTube ilimitado | T37: https://vivo.com.br/para-voce/produtos-e-servicos/para-o-celular/easy-lite | U37: data/raw/vivo_lite_SP.html
A38: 2026-06-22 | B38: 2026-06-22T22:45:24 | C38: vivo | D38: lite | E38: SP | F38: Easy Lite | G38: vivo:VIV202600019134-40gb | H38: 40 | K38: 40 | L38: 40 GB de franquia 2 Meses de YouTube ilimitado | T38: https://vivo.com.br/para-voce/produtos-e-servicos/para-o-celular/easy-lite | U38: data/raw/vivo_lite_SP.html
A39: 2026-06-22 | B39: 2026-06-22T22:45:24 | C39: vivo | D39: lite | E39: SP | F39: Easy Lite | G39: vivo:VIV202600019132-20gb | H39: 35 | K39: 20 | L39: 20 GB de franquia 2 Meses de YouTube ilimitado | T39: https://vivo.com.br/para-voce/produtos-e-servicos/para-o-celular/easy-lite | U39: data/raw/vivo_lite_SP.html
A40: 2026-06-22 | B40: 2026-06-22T22:45:24 | C40: vivo | D40: lite | E40: SP | F40: Easy Lite | G40: vivo:VIV202600019127-30gb | H40: 40 | K40: 30 | T40: https://vivo.com.br/para-voce/produtos-e-servicos/para-o-celular/easy-lite | U40: data/raw/vivo_lite_SP.html
...

Sheet latest
A1: snapshot_date | B1: snapshot_ts | C1: carrier | D1: category | E1: state | F1: plan_name | G1: plan_id | H1: price_brl | I1: price_promo_brl | J1: price_note | K1: data_gb | L1: data_note | M1: validity_days | N1: unlimited_apps | O1: voice | P1: sms | Q1: streaming | R1: loyalty_months | S1: extra_benefits | T1: source_url | U1: raw_ref
A2: 2026-06-29 | B2: 2026-06-29T22:07:51 | C2: claro | D2: control | E2: SP | F2: Controle 25GB | G2: claro:plano-controle-25gb | H2: 59.9 | I2: 54.9 | J2: De R$ 59,90 Por: | K2: 25 | N2: WhatsApp | S2: Para uso livre; Para redes sociais e vídeos; Bônus exclusivo; Aproveite na sua franquia; WhatsApp e ligações ilimitadas | T2: https://www.claro.com.br/celular/controle | U2: data/raw/claro_control_SP.json
A3: 2026-06-29 | B3: 2026-06-29T22:07:51 | C3: claro | D3: control | E3: SP | F3: Controle 30GB | G3: claro:plano-controle-30gb | H3: 69.9 | K3: 30 | N3: WhatsApp | S3: Para uso livre; Bônus do Hexa para uso livre; Bônus para redes sociais e apps; Redes sociais e apps; WhatsApp ilimitado | T3: https://www.claro.com.br/celular/controle | U3: data/raw/claro_control_SP.json
A4: 2026-06-29 | B4: 2026-06-29T22:07:51 | C4: claro | D4: control | E4: SP | F4: Controle 30GB | G4: claro:plano-controle-30gb-gaming | H4: 99.9 | K4: 30 | N4: WhatsApp | S4: Para uso livre; Bônus para redes sociais e apps; Bônus uso livre; Redes sociais e apps; WhatsApp ilimitado | T4: https://www.claro.com.br/celular/controle | U4: data/raw/claro_control_SP.json
A5: 2026-06-29 | B5: 2026-06-29T22:07:51 | C5: claro | D5: flex | E5: SP | F5: Flex 15GB | G5: claro:plano-flex-15gb | H5: 44.9 | K5: 15 | N5: WhatsApp | S5: Para uso livre; Bônus do Hexa para uso livre; Para redes sociais e apps; Bônus extra nos apps; WhatsApp ilimitado | T5: https://www.claro.com.br/celular/flex | U5: data/raw/claro_flex_SP.json
A6: 2026-06-29 | B6: 2026-06-29T22:07:51 | C6: claro | D6: flex | E6: SP | F6: Flex 20GB | G6: claro:plano-flex-20gb | H6: 59.9 | K6: 20 | N6: WhatsApp | S6: Para uso livre; Bônus do Hexa para uso livre; Para redes sociais e apps; Bônus extra nos apps; WhatsApp ilimitado | T6: https://www.claro.com.br/celular/flex | U6: data/raw/claro_flex_SP.json
A7: 2026-06-29 | B7: 2026-06-29T22:07:51 | C7: claro | D7: flex | E7: SP | F7: Flex 30GB | G7: claro:plano-flex-30gb | H7: 69.9 | K7: 30 | N7: WhatsApp | S7: Para uso livre; Bônus do Hexa para uso livre; Para redes sociais e apps; Bônus extra nos apps; WhatsApp ilimitado; Assinatura Claro musica inclusa | T7: https://www.claro.com.br/celular/flex | U7: data/raw/claro_flex_SP.json
A8: 2026-06-29 | B8: 2026-06-29T22:07:51 | C8: claro | D8: flex | E8: SP | F8: Flex 40GB | G8: claro:plano-flex-40gb | H8: 119.9 | K8: 40 | N8: WhatsApp | S8: Para uso livre; Para redes sociais e apps; Bônus uso livre; Bônus extra nos apps; WhatsApp ilimitado; Assinatura Claro musica inclusa | T8: https://www.claro.com.br/celular/flex | U8: data/raw/claro_flex_SP.json
A9: 2026-06-29 | B9: 2026-06-29T22:07:51 | C9: claro | D9: postpaid | E9: SP | F9: Pós 100GB | G9: claro:plano-pos-100gb | H9: 179.9 | K9: 100 | N9: WhatsApp | S9: Armazenamento na nuvem:; Google One ou iCloud+; WhatsApp ilimitado; Roaming: Passaporte Américas; Claro Sync: Smartwatch conectado | T9: https://www.claro.com.br/celular/pos | U9: data/raw/claro_postpaid_SP.json
A10: 2026-06-29 | B10: 2026-06-29T22:07:51 | C10: claro | D10: postpaid | E10: SP | F10: Pós 150GB | G10: claro:plano-pos-150gb | H10: 239.9 | K10: 150 | N10: WhatsApp | S10: Armazenamento na nuvem:; Google One ou iCloud+; WhatsApp ilimitado; Roaming: Passaporte Américas e Europa; Claro Sync: Smartwatch conectado | T10: https://www.claro.com.br/celular/pos | U10: data/raw/claro_postpaid_SP.json
A11: 2026-06-29 | B11: 2026-06-29T22:07:51 | C11: claro | D11: postpaid | E11: SP | F11: Pós 200GB | G11: claro:plano-pos-200gb | H11: 339.9 | K11: 200 | N11: WhatsApp | S11: Armazenamento na nuvem:; Google One ou iCloud+; WhatsApp ilimitado; Roaming: Passaporte Mundo; Claro Sync: Smartwatch conectado | T11: https://www.claro.com.br/celular/pos | U11: data/raw/claro_postpaid_SP.json
A12: 2026-06-29 | B12: 2026-06-29T22:07:51 | C12: claro | D12: postpaid | E12: SP | F12: Pós 50GB com GeForce NOW | G12: claro:plano-pos-60gb-geforce | H12: 164.9 | K12: 50 | N12: WhatsApp | S12: Armazenamento na nuvem:; Google One ou iCloud+; WhatsApp ilimitado; Roaming: Passaporte Américas; Claro Sync: Smartwatch conectado; Inclusa assinatura GeForce NOW | T12: https://www.claro.com.br/celular/pos | U12: data/raw/claro_postpaid_SP.json
A13: 2026-06-29 | B13: 2026-06-29T22:07:51 | C13: claro | D13: postpaid | E13: SP | F13: Pós 60GB | G13: claro:plano-pos-60gb | H13: 124.9 | K13: 60 | N13: WhatsApp | S13: Armazenamento na nuvem:; Google One ou iCloud+; WhatsApp ilimitado; Roaming: Passaporte Américas; Claro Sync: Smartwatch conectado | T13: https://www.claro.com.br/celular/pos | U13: data/raw/claro_postpaid_SP.json
A14: 2026-06-29 | B14: 2026-06-29T22:07:51 | C14: claro | D14: prepaid | E14: SP | F14: Prezão 10GB (25 dias) | G14: claro:prezao-25d-10gb | H14: 25 | J14: recarga Prezão R$25 — validade 25 dias | K14: 10 | M14: 25 | T14: https://www.claro.com.br/celular/planos-pre/prezao | U14: data/raw/claro_prepaid_SP.json
A15: 2026-06-29 | B15: 2026-06-29T22:07:51 | C15: claro | D15: prepaid | E15: SP | F15: Prezão 12GB (30 dias) | G15: claro:prezao-30d-12gb | H15: 30 | J15: recarga Prezão R$30 — validade 30 dias | K15: 12 | M15: 30 | T15: https://www.claro.com.br/celular/planos-pre/prezao | U15: data/raw/claro_prepaid_SP.json
A16: 2026-06-29 | B16: 2026-06-29T22:07:51 | C16: claro | D16: prepaid | E16: SP | F16: Prezão 4GB (12 dias) | G16: claro:prezao-12d-4gb | H16: 15 | J16: recarga Prezão R$15 — validade 12 dias | K16: 4 | M16: 12 | T16: https://www.claro.com.br/celular/planos-pre/prezao | U16: data/raw/claro_prepaid_SP.json
A17: 2026-06-29 | B17: 2026-06-29T22:07:51 | C17: claro | D17: prepaid | E17: SP | F17: Prezão 5GB (15 dias) | G17: claro:prezao-15d-5gb | H17: 15 | J17: recarga Prezão R$15 — validade 15 dias | K17: 5 | M17: 15 | T17: https://www.claro.com.br/celular/planos-pre/prezao | U17: data/raw/claro_prepaid_SP.json
A18: 2026-06-29 | B18: 2026-06-29T22:07:51 | C18: claro | D18: prepaid | E18: SP | F18: Prezão 6GB (20 dias) | G18: claro:prezao-20d-6gb | H18: 20 | J18: recarga Prezão R$20 — validade 20 dias | K18: 6 | M18: 20 | T18: https://www.claro.com.br/celular/planos-pre/prezao | U18: data/raw/claro_prepaid_SP.json
A19: 2026-06-29 | B19: 2026-06-29T22:07:51 | C19: claro | D19: prepaid | E19: SP | F19: Prezão 8GB (20 dias) | G19: claro:prezao-20d-8gb | H19: 20 | J19: recarga Prezão R$20 — validade 20 dias | K19: 8 | M19: 20 | T19: https://www.claro.com.br/celular/planos-pre/prezao | U19: data/raw/claro_prepaid_SP.json
A20: 2026-06-29 | B20: 2026-06-29T22:07:51 | C20: claro | D20: prepaid | E20: SP | F20: Prezão 9GB (25 dias) | G20: claro:prezao-25d-9gb | H20: 25 | J20: recarga Prezão R$25 — validade 25 dias | K20: 9 | M20: 25 | T20: https://www.claro.com.br/celular/planos-pre/prezao | U20: data/raw/claro_prepaid_SP.json
A21: 2026-06-29 | B21: 2026-06-29T22:07:51 | C21: tim | D21: control | E21: SP | F21: TIM Controle 41GB | G21: tim:162901 | H21: 58.99 | K21: 41 | T21: https://www.tim.com.br/sp/para-voce/planos/controle | U21: data/raw/tim_control_SP.html
A22: 2026-06-29 | B22: 2026-06-29T22:07:51 | C22: tim | D22: control | E22: SP | F22: TIM Controle Light Express 31GB | G22: tim:143536 | H22: 60.99 | K22: 31 | T22: https://www.tim.com.br/sp/para-voce/planos/controle | U22: data/raw/tim_control_SP.html
A23: 2026-06-29 | B23: 2026-06-29T22:07:51 | C23: tim | D23: control | E23: SP | F23: TIM Controle Plus 45GB | G23: tim:155891 | H23: 64.99 | K23: 45 | T23: https://www.tim.com.br/sp/para-voce/planos/controle | U23: data/raw/tim_control_SP.html
A24: 2026-06-29 | B24: 2026-06-29T22:07:51 | C24: tim | D24: control | E24: SP | F24: TIM Controle Premium 53GB | G24: tim:162896 | H24: 84.99 | K24: 53 | T24: https://www.tim.com.br/sp/para-voce/planos/controle | U24: data/raw/tim_control_SP.html
A25: 2026-06-29 | B25: 2026-06-29T22:07:51 | C25: tim | D25: control | E25: SP | F25: TIM Controle Pro Express | G25: tim:143576 | H25: 64.99 | T25: https://www.tim.com.br/sp/para-voce/planos/controle | U25: data/raw/tim_control_SP.html
A26: 2026-06-29 | B26: 2026-06-29T22:07:51 | C26: tim | D26: postpaid | E26: SP | F26: TIM Black 70GB | G26: tim:54206 | H26: 129.99 | K26: 70 | T26: https://www.tim.com.br/sp/para-voce/planos/pos-pago/tim-black | U26: data/raw/tim_postpaid_SP.html
A27: 2026-06-29 | B27: 2026-06-29T22:07:51 | C27: tim | D27: postpaid | E27: SP | F27: TIM Black A Express 67GB | G27: tim:55121 | H27: 119.99 | K27: 67 | T27: https://www.tim.com.br/sp/para-voce/planos/pos-pago/tim-black | U27: data/raw/tim_postpaid_SP.html
A28: 2026-06-29 | B28: 2026-06-29T22:07:51 | C28: tim | D28: postpaid | E28: SP | F28: TIM Black B Express 82GB | G28: tim:52146 | H28: 144.99 | K28: 82 | T28: https://www.tim.com.br/sp/para-voce/planos/pos-pago/tim-black | U28: data/raw/tim_postpaid_SP.html
A29: 2026-06-29 | B29: 2026-06-29T22:07:51 | C29: tim | D29: postpaid | E29: SP | F29: TIM Black C Express 107GB | G29: tim:52151 | H29: 164.99 | K29: 107 | T29: https://www.tim.com.br/sp/para-voce/planos/pos-pago/tim-black | U29: data/raw/tim_postpaid_SP.html
A30: 2026-06-29 | B30: 2026-06-29T22:07:51 | C30: tim | D30: postpaid | E30: SP | F30: TIM Black C Ultra 95GB | G30: tim:100581 | H30: 159.99 | K30: 95 | T30: https://www.tim.com.br/sp/para-voce/planos/pos-pago/tim-black | U30: data/raw/tim_postpaid_SP.html
A31: 2026-06-29 | B31: 2026-06-29T22:07:51 | C31: tim | D31: postpaid | E31: SP | F31: TIM Black Plus 80GB | G31: tim:54256 | H31: 149.99 | K31: 80 | T31: https://www.tim.com.br/sp/para-voce/planos/pos-pago/tim-black | U31: data/raw/tim_postpaid_SP.html
A32: 2026-06-29 | B32: 2026-06-29T22:07:51 | C32: tim | D32: postpaid | E32: SP | F32: TIM Black Premium 110GB | G32: tim:54261 | H32: 159.99 | K32: 110 | T32: https://www.tim.com.br/sp/para-voce/planos/pos-pago/tim-black | U32: data/raw/tim_postpaid_SP.html
A33: 2026-06-29 | B33: 2026-06-29T22:07:51 | C33: tim | D33: prepaid | E33: SP | F33: TIM Pré XIP Plus 16GB | G33: tim:106306 | H33: 30 | K33: 16 | M33: 30 | T33: https://www.tim.com.br/sp/para-voce/planos/pre-pago | U33: data/raw/tim_prepaid_SP.html
A34: 2026-06-29 | B34: 2026-06-29T22:07:51 | C34: tim | D34: prepaid | E34: SP | F34: TIM Pré XIP Plus 6GB | G34: tim:59906 | H34: 20 | K34: 6 | M34: 30 | T34: https://www.tim.com.br/sp/para-voce/planos/pre-pago | U34: data/raw/tim_prepaid_SP.html
A35: 2026-06-29 | B35: 2026-06-29T22:07:51 | C35: tim | D35: prepaid | E35: SP | F35: TIM Pré XIP Plus 8GB | G35: tim:59901 | H35: 25 | K35: 8 | M35: 30 | T35: https://www.tim.com.br/sp/para-voce/planos/pre-pago | U35: data/raw/tim_prepaid_SP.html
A36: 2026-06-29 | B36: 2026-06-29T22:07:51 | C36: vivo | D36: control | E36: SP | F36: Vivo Controle | G36: vivo:VIV202600029270-46gb | H36: 59 | K36: 46 | L36: 15 GB de franquia 31 GB de bônus | S36: 6 meses grátis de Gemini com AI Plus | T36: https://vivo.com.br/para-voce/produtos-e-servicos/para-o-celular/planos-controle | U36: data/raw/vivo_control_SP.html
A37: 2026-06-29 | B37: 2026-06-29T22:07:51 | C37: vivo | D37: control | E37: SP | F37: Vivo Controle | G37: vivo:VIV202600029300-61gb | H37: 80 | K37: 61 | L37: 20 GB de franquia 31 GB de bônus | S37: 6 meses grátis de Gemini com AI Plus | T37: https://vivo.com.br/para-voce/produtos-e-servicos/para-o-celular/planos-controle | U37: data/raw/vivo_control_SP.html
A38: 2026-06-29 | B38: 2026-06-29T22:07:51 | C38: vivo | D38: control | E38: SP | F38: Vivo Controle Educação | G38: vivo:VIV202600029273-61gb | H38: 90 | K38: 61 | L38: 20 GB de franquia 31 GB de bônus | S38: Assinatura Vivae inclusa | T38: https://vivo.com.br/para-voce/produtos-e-servicos/para-o-celular/planos-controle | U38: data/raw/vivo_control_SP.html
A39: 2026-06-29 | B39: 2026-06-29T22:07:51 | C39: vivo | D39: control | E39: SP | F39: Vivo Controle Entretenimento | G39: vivo:VIV202600029307-61gb | H39: 110 | K39: 61 | L39: 20 GB de franquia 31 GB de bônus | S39: Assinatura Vivo TV Inicial inclusa | T39: https://vivo.com.br/para-voce/produtos-e-servicos/para-o-celular/planos-controle | U39: data/raw/vivo_control_SP.html
A40: 2026-06-29 | B40: 2026-06-29T22:07:51 | C40: vivo | D40: control | E40: SP | F40: Vivo Controle Música | G40: vivo:VIV202600029313-61gb | H40: 95 | K40: 61 | L40: 20 GB de franquia 31 GB de bônus | S40: Apple Music Individual | T40: https://vivo.com.br/para-voce/produtos-e-servicos/para-o-celular/planos-controle | U40: data/raw/vivo_control_SP.html
...

Sheet changes
A1: change_type | B1: carrier | C1: category | D1: state | E1: plan_id | F1: plan_name | G1: old_price_brl | H1: new_price_brl | I1: delta_brl

Sheet summary
A1: Mobile Price Tracker — Summary
A3: Run timestamp | B3: 2026-06-29T22:07:51
A4: Latest snapshot | B4: 2026-06-29
A5: Plans in latest | B5: 55
A6: Snapshots in history | B6: 8
A8: carrier | B8: # plans | C8: min price | D8: avg price | E8: max price
A9: vivo | B9: =COUNTIF(latest!$C$2:$C$2000,$A$9) | C9: =IFERROR(_xlfn.MINIFS(latest!$H$2:$H$2000,latest!$C$2:$C$2000,$A$9),"-") | D9: =IFERROR(AVERAGEIFS(latest!$H$2:$H$2000,latest!$C$2:$C$2000,$A$9),"-") | E9: =IFERROR(_xlfn.MAXIFS(latest!$H$2:$H$2000,latest!$C$2:$C$2000,$A$9),"-")
A10: claro | B10: =COUNTIF(latest!$C$2:$C$2000,$A$10) | C10: =IFERROR(_xlfn.MINIFS(latest!$H$2:$H$2000,latest!$C$2:$C$2000,$A$10),"-") | D10: =IFERROR(AVERAGEIFS(latest!$H$2:$H$2000,latest!$C$2:$C$2000,$A$10),"-") | E10: =IFERROR(_xlfn.MAXIFS(latest!$H$2:$H$2000,latest!$C$2:$C$2000,$A$10),"-")
A11: tim | B11: =COUNTIF(latest!$C$2:$C$2000,$A$11) | C11: =IFERROR(_xlfn.MINIFS(latest!$H$2:$H$2000,latest!$C$2:$C$2000,$A$11),"-") | D11: =IFERROR(AVERAGEIFS(latest!$H$2:$H$2000,latest!$C$2:$C$2000,$A$11),"-") | E11: =IFERROR(_xlfn.MAXIFS(latest!$H$2:$H$2000,latest!$C$2:$C$2000,$A$11),"-")

Sheet comparison
A1: Date | B1: Control (R$/mo) | E1: Post (R$/mo) | H1: Pre (R$/mo, 30-day) | K1: Digital (R$/mo)
B2: TIM | C2: Vivo | D2: Claro | E2: TIM | F2: Vivo | G2: Claro | H2: TIM | I2: Vivo | J2: Claro | K2: TIM | L2: Vivo | M2: Claro
A3: 46195 | B3: =IFERROR(IF(_xlfn.MINIFS(history!$H:$H,history!$C:$C,"tim",history!$D:$D,"control",history!$A:$A,YEAR($A3)&"-"&TEXT(MONTH($A3),"00")&"-"&TEXT(DAY($A3),"00"))=0,"",_xlfn.MINIFS(history!$H:$H,history!$C:$C,"tim",history!$D:$D,"control",history!$A:$A,YEAR($A3)&"-"&TEXT(MONTH($A3),"00")&"-"&TEXT(DAY($A3),"00"))),"") | C3: =IFERROR(IF(_xlfn.MINIFS(history!$H:$H,history!$C:$C,"vivo",history!$D:$D,"control",history!$A:$A,YEAR($A3)&"-"&TEXT(MONTH($A3),"00")&"-"&TEXT(DAY($A3),"00"))=0,"",_xlfn.MINIFS(history!$H:$H,history!$C:$C,"vivo",history!$D:$D,"control",history!$A:$A,YEAR($A3)&"-"&TEXT(MONTH($A3),"00")&"-"&TEXT(DAY($A3),"00"))),"") | D3: =IFERROR(IF(_xlfn.MINIFS(history!$H:$H,history!$C:$C,"claro",history!$D:$D,"control",history!$A:$A,YEAR($A3)&"-"&TEXT(MONTH($A3),"00")&"-"&TEXT(DAY($A3),"00"))=0,"",_xlfn.MINIFS(history!$H:$H,history!$C:$C,"claro",history!$D:$D,"control",history!$A:$A,YEAR($A3)&"-"&TEXT(MONTH($A3),"00")&"-"&TEXT(DAY($A3),"00"))),"") | E3: =IFERROR(IF(_xlfn.MINIFS(history!$H:$H,history!$C:$C,"tim",history!$D:$D,"postpaid",history!$A:$A,YEAR($A3)&"-"&TEXT(MONTH($A3),"00")&"-"&TEXT(DAY($A3),"00"))=0,"",_xlfn.MINIFS(history!$H:$H,history!$C:$C,"tim",history!$D:$D,"postpaid",history!$A:$A,YEAR($A3)&"-"&TEXT(MONTH($A3),"00")&"-"&TEXT(DAY($A3),"00"))),"") | F3: =IFERROR(IF(_xlfn.MINIFS(history!$H:$H,history!$C:$C,"vivo",history!$D:$D,"postpaid",history!$A:$A,YEAR($A3)&"-"&TEXT(MONTH($A3),"00")&"-"&TEXT(DAY($A3),"00"))=0,"",_xlfn.MINIFS(history!$H:$H,history!$C:$C,"vivo",history!$D:$D,"postpaid",history!$A:$A,YEAR($A3)&"-"&TEXT(MONTH($A3),"00")&"-"&TEXT(DAY($A3),"00"))),"") | G3: =IFERROR(IF(_xlfn.MINIFS(history!$H:$H,history!$C:$C,"claro",history!$D:$D,"postpaid",history!$A:$A,YEAR($A3)&"-"&TEXT(MONTH($A3),"00")&"-"&TEXT(DAY($A3),"00"))=0,"",_xlfn.MINIFS(history!$H:$H,history!$C:$C,"claro",history!$D:$D,"postpaid",history!$A:$A,YEAR($A3)&"-"&TEXT(MONTH($A3),"00")&"-"&TEXT(DAY($A3),"00"))),"") | H3: =IFERROR(IF(_xlfn.MINIFS(history!$H:$H,history!$C:$C,"tim",history!$D:$D,"prepaid",history!$A:$A,YEAR($A3)&"-"&TEXT(MONTH($A3),"00")&"-"&TEXT(DAY($A3),"00"),history!$M:$M,">=28")=0,"",_xlfn.MINIFS(history!$H:$H,history!$C:$C,"tim",history!$D:$D,"prepaid",history!$A:$A,YEAR($A3)&"-"&TEXT(MONTH($A3),"00")&"-"&TEXT(DAY($A3),"00"),history!$M:$M,">=28")),"") | I3: =IFERROR(IF(_xlfn.MINIFS(history!$H:$H,history!$C:$C,"vivo",history!$D:$D,"prepaid",history!$A:$A,YEAR($A3)&"-"&TEXT(MONTH($A3),"00")&"-"&TEXT(DAY($A3),"00"),history!$M:$M,">=28")=0,"",_xlfn.MINIFS(history!$H:$H,history!$C:$C,"vivo",history!$D:$D,"prepaid",history!$A:$A,YEAR($A3)&"-"&TEXT(MONTH($A3),"00")&"-"&TEXT(DAY($A3),"00"),history!$M:$M,">=28")),"") | J3: =IFERROR(IF(_xlfn.MINIFS(history!$H:$H,history!$C:$C,"claro",history!$D:$D,"prepaid",history!$A:$A,YEAR($A3)&"-"&TEXT(MONTH($A3),"00")&"-"&TEXT(DAY($A3),"00"),history!$M:$M,">=28")=0,"",_xlfn.MINIFS(history!$H:$H,history!$C:$C,"claro",history!$D:$D,"prepaid",history!$A:$A,YEAR($A3)&"-"&TEXT(MONTH($A3),"00")&"-"&TEXT(DAY($A3),"00"),history!$M:$M,">=28")),"") | K3: =IFERROR(1/MAX(IFERROR(1/_xlfn.MINIFS(history!$H:$H,history!$C:$C,"tim",history!$D:$D,"lite",history!$A:$A,YEAR($A3)&"-"&TEXT(MONTH($A3),"00")&"-"&TEXT(DAY($A3),"00")),0),IFERROR(1/_xlfn.MINIFS(history!$H:$H,history!$C:$C,"tim",history!$D:$D,"flex",history!$A:$A,YEAR($A3)&"-"&TEXT(MONTH($A3),"00")&"-"&TEXT(DAY($A3),"00")),0)),"") | L3: =IFERROR(1/MAX(IFERROR(1/_xlfn.MINIFS(history!$H:$H,history!$C:$C,"vivo",history!$D:$D,"lite",history!$A:$A,YEAR($A3)&"-"&TEXT(MONTH($A3),"00")&"-"&TEXT(DAY($A3),"00")),0),IFERROR(1/_xlfn.MINIFS(history!$H:$H,history!$C:$C,"vivo",history!$D:$D,"flex",history!$A:$A,YEAR($A3)&"-"&TEXT(MONTH($A3),"00")&"-"&TEXT(DAY($A3),"00")),0)),"") | M3: =IFERROR(1/MAX(IFERROR(1/_xlfn.MINIFS(history!$H:$H,history!$C:$C,"claro",history!$D:$D,"lite",history!$A:$A,YEAR($A3)&"-"&TEXT(MONTH($A3),"00")&"-"&TEXT(DAY($A3),"00")),0),IFERROR(1/_xlfn.MINIFS(history!$H:$H,history!$C:$C,"claro",history!$D:$D,"flex",history!$A:$A,YEAR($A3)&"-"&TEXT(MONTH($A3),"00")&"-"&TEXT(DAY($A3),"00")),0)),"")
A4: 46196 | B4: =IFERROR(IF(_xlfn.MINIFS(history!$H:$H,history!$C:$C,"tim",history!$D:$D,"control",history!$A:$A,YEAR($A4)&"-"&TEXT(MONTH($A4),"00")&"-"&TEXT(DAY($A4),"00"))=0,"",_xlfn.MINIFS(history!$H:$H,history!$C:$C,"tim",history!$D:$D,"control",history!$A:$A,YEAR($A4)&"-"&TEXT(MONTH($A4),"00")&"-"&TEXT(DAY($A4),"00"))),"") | C4: =IFERROR(IF(_xlfn.MINIFS(history!$H:$H,history!$C:$C,"vivo",history!$D:$D,"control",history!$A:$A,YEAR($A4)&"-"&TEXT(MONTH($A4),"00")&"-"&TEXT(DAY($A4),"00"))=0,"",_xlfn.MINIFS(history!$H:$H,history!$C:$C,"vivo",history!$D:$D,"control",history!$A:$A,YEAR($A4)&"-"&TEXT(MONTH($A4),"00")&"-"&TEXT(DAY($A4),"00"))),"") | D4: =IFERROR(IF(_xlfn.MINIFS(history!$H:$H,history!$C:$C,"claro",history!$D:$D,"control",history!$A:$A,YEAR($A4)&"-"&TEXT(MONTH($A4),"00")&"-"&TEXT(DAY($A4),"00"))=0,"",_xlfn.MINIFS(history!$H:$H,history!$C:$C,"claro",history!$D:$D,"control",history!$A:$A,YEAR($A4)&"-"&TEXT(MONTH($A4),"00")&"-"&TEXT(DAY($A4),"00"))),"") | E4: =IFERROR(IF(_xlfn.MINIFS(history!$H:$H,history!$C:$C,"tim",history!$D:$D,"postpaid",history!$A:$A,YEAR($A4)&"-"&TEXT(MONTH($A4),"00")&"-"&TEXT(DAY($A4),"00"))=0,"",_xlfn.MINIFS(history!$H:$H,history!$C:$C,"tim",history!$D:$D,"postpaid",history!$A:$A,YEAR($A4)&"-"&TEXT(MONTH($A4),"00")&"-"&TEXT(DAY($A4),"00"))),"") | F4: =IFERROR(IF(_xlfn.MINIFS(history!$H:$H,history!$C:$C,"vivo",history!$D:$D,"postpaid",history!$A:$A,YEAR($A4)&"-"&TEXT(MONTH($A4),"00")&"-"&TEXT(DAY($A4),"00"))=0,"",_xlfn.MINIFS(history!$H:$H,history!$C:$C,"vivo",history!$D:$D,"postpaid",history!$A:$A,YEAR($A4)&"-"&TEXT(MONTH($A4),"00")&"-"&TEXT(DAY($A4),"00"))),"") | G4: =IFERROR(IF(_xlfn.MINIFS(history!$H:$H,history!$C:$C,"claro",history!$D:$D,"postpaid",history!$A:$A,YEAR($A4)&"-"&TEXT(MONTH($A4),"00")&"-"&TEXT(DAY($A4),"00"))=0,"",_xlfn.MINIFS(history!$H:$H,history!$C:$C,"claro",history!$D:$D,"postpaid",history!$A:$A,YEAR($A4)&"-"&TEXT(MONTH($A4),"00")&"-"&TEXT(DAY($A4),"00"))),"") | H4: =IFERROR(IF(_xlfn.MINIFS(history!$H:$H,history!$C:$C,"tim",history!$D:$D,"prepaid",history!$A:$A,YEAR($A4)&"-"&TEXT(MONTH($A4),"00")&"-"&TEXT(DAY($A4),"00"),history!$M:$M,">=28")=0,"",_xlfn.MINIFS(history!$H:$H,history!$C:$C,"tim",history!$D:$D,"prepaid",history!$A:$A,YEAR($A4)&"-"&TEXT(MONTH($A4),"00")&"-"&TEXT(DAY($A4),"00"),history!$M:$M,">=28")),"") | I4: =IFERROR(IF(_xlfn.MINIFS(history!$H:$H,history!$C:$C,"vivo",history!$D:$D,"prepaid",history!$A:$A,YEAR($A4)&"-"&TEXT(MONTH($A4),"00")&"-"&TEXT(DAY($A4),"00"),history!$M:$M,">=28")=0,"",_xlfn.MINIFS(history!$H:$H,history!$C:$C,"vivo",history!$D:$D,"prepaid",history!$A:$A,YEAR($A4)&"-"&TEXT(MONTH($A4),"00")&"-"&TEXT(DAY($A4),"00"),history!$M:$M,">=28")),"") | J4: =IFERROR(IF(_xlfn.MINIFS(history!$H:$H,history!$C:$C,"claro",history!$D:$D,"prepaid",history!$A:$A,YEAR($A4)&"-"&TEXT(MONTH($A4),"00")&"-"&TEXT(DAY($A4),"00"),history!$M:$M,">=28")=0,"",_xlfn.MINIFS(history!$H:$H,history!$C:$C,"claro",history!$D:$D,"prepaid",history!$A:$A,YEAR($A4)&"-"&TEXT(MONTH($A4),"00")&"-"&TEXT(DAY($A4),"00"),history!$M:$M,">=28")),"") | K4: =IFERROR(1/MAX(IFERROR(1/_xlfn.MINIFS(history!$H:$H,history!$C:$C,"tim",history!$D:$D,"lite",history!$A:$A,YEAR($A4)&"-"&TEXT(MONTH($A4),"00")&"-"&TEXT(DAY($A4),"00")),0),IFERROR(1/_xlfn.MINIFS(history!$H:$H,history!$C:$C,"tim",history!$D:$D,"flex",history!$A:$A,YEAR($A4)&"-"&TEXT(MONTH($A4),"00")&"-"&TEXT(DAY($A4),"00")),0)),"") | L4: =IFERROR(1/MAX(IFERROR(1/_xlfn.MINIFS(history!$H:$H,history!$C:$C,"vivo",history!$D:$D,"lite",history!$A:$A,YEAR($A4)&"-"&TEXT(MONTH($A4),"00")&"-"&TEXT(DAY($A4),"00")),0),IFERROR(1/_xlfn.MINIFS(history!$H:$H,history!$C:$C,"vivo",history!$D:$D,"flex",history!$A:$A,YEAR($A4)&"-"&TEXT(MONTH($A4),"00")&"-"&TEXT(DAY($A4),"00")),0)),"") | M4: =IFERROR(1/MAX(IFERROR(1/_xlfn.MINIFS(history!$H:$H,history!$C:$C,"claro",history!$D:$D,"lite",history!$A:$A,YEAR($A4)&"-"&TEXT(MONTH($A4),"00")&"-"&TEXT(DAY($A4),"00")),0),IFERROR(1/_xlfn.MINIFS(history!$H:$H,history!$C:$C,"claro",history!$D:$D,"flex",history!$A:$A,YEAR($A4)&"-"&TEXT(MONTH($A4),"00")&"-"&TEXT(DAY($A4),"00")),0)),"")
A5: 46197 | B5: =IFERROR(IF(_xlfn.MINIFS(history!$H:$H,history!$C:$C,"tim",history!$D:$D,"control",history!$A:$A,YEAR($A5)&"-"&TEXT(MONTH($A5),"00")&"-"&TEXT(DAY($A5),"00"))=0,"",_xlfn.MINIFS(history!$H:$H,history!$C:$C,"tim",history!$D:$D,"control",history!$A:$A,YEAR($A5)&"-"&TEXT(MONTH($A5),"00")&"-"&TEXT(DAY($A5),"00"))),"") | C5: =IFERROR(IF(_xlfn.MINIFS(history!$H:$H,history!$C:$C,"vivo",history!$D:$D,"control",history!$A:$A,YEAR($A5)&"-"&TEXT(MONTH($A5),"00")&"-"&TEXT(DAY($A5),"00"))=0,"",_xlfn.MINIFS(history!$H:$H,history!$C:$C,"vivo",history!$D:$D,"control",history!$A:$A,YEAR($A5)&"-"&TEXT(MONTH($A5),"00")&"-"&TEXT(DAY($A5),"00"))),"") | D5: =IFERROR(IF(_xlfn.MINIFS(history!$H:$H,history!$C:$C,"claro",history!$D:$D,"control",history!$A:$A,YEAR($A5)&"-"&TEXT(MONTH($A5),"00")&"-"&TEXT(DAY($A5),"00"))=0,"",_xlfn.MINIFS(history!$H:$H,history!$C:$C,"claro",history!$D:$D,"control",history!$A:$A,YEAR($A5)&"-"&TEXT(MONTH($A5),"00")&"-"&TEXT(DAY($A5),"00"))),"") | E5: =IFERROR(IF(_xlfn.MINIFS(history!$H:$H,history!$C:$C,"tim",history!$D:$D,"postpaid",history!$A:$A,YEAR($A5)&"-"&TEXT(MONTH($A5),"00")&"-"&TEXT(DAY($A5),"00"))=0,"",_xlfn.MINIFS(history!$H:$H,history!$C:$C,"tim",history!$D:$D,"postpaid",history!$A:$A,YEAR($A5)&"-"&TEXT(MONTH($A5),"00")&"-"&TEXT(DAY($A5),"00"))),"") | F5: =IFERROR(IF(_xlfn.MINIFS(history!$H:$H,history!$C:$C,"vivo",history!$D:$D,"postpaid",history!$A:$A,YEAR($A5)&"-"&TEXT(MONTH($A5),"00")&"-"&TEXT(DAY($A5),"00"))=0,"",_xlfn.MINIFS(history!$H:$H,history!$C:$C,"vivo",history!$D:$D,"postpaid",history!$A:$A,YEAR($A5)&"-"&TEXT(MONTH($A5),"00")&"-"&TEXT(DAY($A5),"00"))),"") | G5: =IFERROR(IF(_xlfn.MINIFS(history!$H:$H,history!$C:$C,"claro",history!$D:$D,"postpaid",history!$A:$A,YEAR($A5)&"-"&TEXT(MONTH($A5),"00")&"-"&TEXT(DAY($A5),"00"))=0,"",_xlfn.MINIFS(history!$H:$H,history!$C:$C,"claro",history!$D:$D,"postpaid",history!$A:$A,YEAR($A5)&"-"&TEXT(MONTH($A5),"00")&"-"&TEXT(DAY($A5),"00"))),"") | H5: =IFERROR(IF(_xlfn.MINIFS(history!$H:$H,history!$C:$C,"tim",history!$D:$D,"prepaid",history!$A:$A,YEAR($A5)&"-"&TEXT(MONTH($A5),"00")&"-"&TEXT(DAY($A5),"00"),history!$M:$M,">=28")=0,"",_xlfn.MINIFS(history!$H:$H,history!$C:$C,"tim",history!$D:$D,"prepaid",history!$A:$A,YEAR($A5)&"-"&TEXT(MONTH($A5),"00")&"-"&TEXT(DAY($A5),"00"),history!$M:$M,">=28")),"") | I5: =IFERROR(IF(_xlfn.MINIFS(history!$H:$H,history!$C:$C,"vivo",history!$D:$D,"prepaid",history!$A:$A,YEAR($A5)&"-"&TEXT(MONTH($A5),"00")&"-"&TEXT(DAY($A5),"00"),history!$M:$M,">=28")=0,"",_xlfn.MINIFS(history!$H:$H,history!$C:$C,"vivo",history!$D:$D,"prepaid",history!$A:$A,YEAR($A5)&"-"&TEXT(MONTH($A5),"00")&"-"&TEXT(DAY($A5),"00"),history!$M:$M,">=28")),"") | J5: =IFERROR(IF(_xlfn.MINIFS(history!$H:$H,history!$C:$C,"claro",history!$D:$D,"prepaid",history!$A:$A,YEAR($A5)&"-"&TEXT(MONTH($A5),"00")&"-"&TEXT(DAY($A5),"00"),history!$M:$M,">=28")=0,"",_xlfn.MINIFS(history!$H:$H,history!$C:$C,"claro",history!$D:$D,"prepaid",history!$A:$A,YEAR($A5)&"-"&TEXT(MONTH($A5),"00")&"-"&TEXT(DAY($A5),"00"),history!$M:$M,">=28")),"") | K5: =IFERROR(1/MAX(IFERROR(1/_xlfn.MINIFS(history!$H:$H,history!$C:$C,"tim",history!$D:$D,"lite",history!$A:$A,YEAR($A5)&"-"&TEXT(MONTH($A5),"00")&"-"&TEXT(DAY($A5),"00")),0),IFERROR(1/_xlfn.MINIFS(history!$H:$H,history!$C:$C,"tim",history!$D:$D,"flex",history!$A:$A,YEAR($A5)&"-"&TEXT(MONTH($A5),"00")&"-"&TEXT(DAY($A5),"00")),0)),"") | L5: =IFERROR(1/MAX(IFERROR(1/_xlfn.MINIFS(history!$H:$H,history!$C:$C,"vivo",history!$D:$D,"lite",history!$A:$A,YEAR($A5)&"-"&TEXT(MONTH($A5),"00")&"-"&TEXT(DAY($A5),"00")),0),IFERROR(1/_xlfn.MINIFS(history!$H:$H,history!$C:$C,"vivo",history!$D:$D,"flex",history!$A:$A,YEAR($A5)&"-"&TEXT(MONTH($A5),"00")&"-"&TEXT(DAY($A5),"00")),0)),"") | M5: =IFERROR(1/MAX(IFERROR(1/_xlfn.MINIFS(history!$H:$H,history!$C:$C,"claro",history!$D:$D,"lite",history!$A:$A,YEAR($A5)&"-"&TEXT(MONTH($A5),"00")&"-"&TEXT(DAY($A5),"00")),0),IFERROR(1/_xlfn.MINIFS(history!$H:$H,history!$C:$C,"claro",history!$D:$D,"flex",history!$A:$A,YEAR($A5)&"-"&TEXT(MONTH($A5),"00")&"-"&TEXT(DAY($A5),"00")),0)),"")
A6: 46198 | B6: =IFERROR(IF(_xlfn.MINIFS(history!$H:$H,history!$C:$C,"tim",history!$D:$D,"control",history!$A:$A,YEAR($A6)&"-"&TEXT(MONTH($A6),"00")&"-"&TEXT(DAY($A6),"00"))=0,"",_xlfn.MINIFS(history!$H:$H,history!$C:$C,"tim",history!$D:$D,"control",history!$A:$A,YEAR($A6)&"-"&TEXT(MONTH($A6),"00")&"-"&TEXT(DAY($A6),"00"))),"") | C6: =IFERROR(IF(_xlfn.MINIFS(history!$H:$H,history!$C:$C,"vivo",history!$D:$D,"control",history!$A:$A,YEAR($A6)&"-"&TEXT(MONTH($A6),"00")&"-"&TEXT(DAY($A6),"00"))=0,"",_xlfn.MINIFS(history!$H:$H,history!$C:$C,"vivo",history!$D:$D,"control",history!$A:$A,YEAR($A6)&"-"&TEXT(MONTH($A6),"00")&"-"&TEXT(DAY($A6),"00"))),"") | D6: =IFERROR(IF(_xlfn.MINIFS(history!$H:$H,history!$C:$C,"claro",history!$D:$D,"control",history!$A:$A,YEAR($A6)&"-"&TEXT(MONTH($A6),"00")&"-"&TEXT(DAY($A6),"00"))=0,"",_xlfn.MINIFS(history!$H:$H,history!$C:$C,"claro",history!$D:$D,"control",history!$A:$A,YEAR($A6)&"-"&TEXT(MONTH($A6),"00")&"-"&TEXT(DAY($A6),"00"))),"") | E6: =IFERROR(IF(_xlfn.MINIFS(history!$H:$H,history!$C:$C,"tim",history!$D:$D,"postpaid",history!$A:$A,YEAR($A6)&"-"&TEXT(MONTH($A6),"00")&"-"&TEXT(DAY($A6),"00"))=0,"",_xlfn.MINIFS(history!$H:$H,history!$C:$C,"tim",history!$D:$D,"postpaid",history!$A:$A,YEAR($A6)&"-"&TEXT(MONTH($A6),"00")&"-"&TEXT(DAY($A6),"00"))),"") | F6: =IFERROR(IF(_xlfn.MINIFS(history!$H:$H,history!$C:$C,"vivo",history!$D:$D,"postpaid",history!$A:$A,YEAR($A6)&"-"&TEXT(MONTH($A6),"00")&"-"&TEXT(DAY($A6),"00"))=0,"",_xlfn.MINIFS(history!$H:$H,history!$C:$C,"vivo",history!$D:$D,"postpaid",history!$A:$A,YEAR($A6)&"-"&TEXT(MONTH($A6),"00")&"-"&TEXT(DAY($A6),"00"))),"") | G6: =IFERROR(IF(_xlfn.MINIFS(history!$H:$H,history!$C:$C,"claro",history!$D:$D,"postpaid",history!$A:$A,YEAR($A6)&"-"&TEXT(MONTH($A6),"00")&"-"&TEXT(DAY($A6),"00"))=0,"",_xlfn.MINIFS(history!$H:$H,history!$C:$C,"claro",history!$D:$D,"postpaid",history!$A:$A,YEAR($A6)&"-"&TEXT(MONTH($A6),"00")&"-"&TEXT(DAY($A6),"00"))),"") | H6: =IFERROR(IF(_xlfn.MINIFS(history!$H:$H,history!$C:$C,"tim",history!$D:$D,"prepaid",history!$A:$A,YEAR($A6)&"-"&TEXT(MONTH($A6),"00")&"-"&TEXT(DAY($A6),"00"),history!$M:$M,">=28")=0,"",_xlfn.MINIFS(history!$H:$H,history!$C:$C,"tim",history!$D:$D,"prepaid",history!$A:$A,YEAR($A6)&"-"&TEXT(MONTH($A6),"00")&"-"&TEXT(DAY($A6),"00"),history!$M:$M,">=28")),"") | I6: =IFERROR(IF(_xlfn.MINIFS(history!$H:$H,history!$C:$C,"vivo",history!$D:$D,"prepaid",history!$A:$A,YEAR($A6)&"-"&TEXT(MONTH($A6),"00")&"-"&TEXT(DAY($A6),"00"),history!$M:$M,">=28")=0,"",_xlfn.MINIFS(history!$H:$H,history!$C:$C,"vivo",history!$D:$D,"prepaid",history!$A:$A,YEAR($A6)&"-"&TEXT(MONTH($A6),"00")&"-"&TEXT(DAY($A6),"00"),history!$M:$M,">=28")),"") | J6: =IFERROR(IF(_xlfn.MINIFS(history!$H:$H,history!$C:$C,"claro",history!$D:$D,"prepaid",history!$A:$A,YEAR($A6)&"-"&TEXT(MONTH($A6),"00")&"-"&TEXT(DAY($A6),"00"),history!$M:$M,">=28")=0,"",_xlfn.MINIFS(history!$H:$H,history!$C:$C,"claro",history!$D:$D,"prepaid",history!$A:$A,YEAR($A6)&"-"&TEXT(MONTH($A6),"00")&"-"&TEXT(DAY($A6),"00"),history!$M:$M,">=28")),"") | K6: =IFERROR(1/MAX(IFERROR(1/_xlfn.MINIFS(history!$H:$H,history!$C:$C,"tim",history!$D:$D,"lite",history!$A:$A,YEAR($A6)&"-"&TEXT(MONTH($A6),"00")&"-"&TEXT(DAY($A6),"00")),0),IFERROR(1/_xlfn.MINIFS(history!$H:$H,history!$C:$C,"tim",history!$D:$D,"flex",history!$A:$A,YEAR($A6)&"-"&TEXT(MONTH($A6),"00")&"-"&TEXT(DAY($A6),"00")),0)),"") | L6: =IFERROR(1/MAX(IFERROR(1/_xlfn.MINIFS(history!$H:$H,history!$C:$C,"vivo",history!$D:$D,"lite",history!$A:$A,YEAR($A6)&"-"&TEXT(MONTH($A6),"00")&"-"&TEXT(DAY($A6),"00")),0),IFERROR(1/_xlfn.MINIFS(history!$H:$H,history!$C:$C,"vivo",history!$D:$D,"flex",history!$A:$A,YEAR($A6)&"-"&TEXT(MONTH($A6),"00")&"-"&TEXT(DAY($A6),"00")),0)),"") | M6: =IFERROR(1/MAX(IFERROR(1/_xlfn.MINIFS(history!$H:$H,history!$C:$C,"claro",history!$D:$D,"lite",history!$A:$A,YEAR($A6)&"-"&TEXT(MONTH($A6),"00")&"-"&TEXT(DAY($A6),"00")),0),IFERROR(1/_xlfn.MINIFS(history!$H:$H,history!$C:$C,"claro",history!$D:$D,"flex",history!$A:$A,YEAR($A6)&"-"&TEXT(MONTH($A6),"00")&"-"&TEXT(DAY($A6),"00")),0)),"")
A7: 46199 | B7: =IFERROR(IF(_xlfn.MINIFS(history!$H:$H,history!$C:$C,"tim",history!$D:$D,"control",history!$A:$A,YEAR($A7)&"-"&TEXT(MONTH($A7),"00")&"-"&TEXT(DAY($A7),"00"))=0,"",_xlfn.MINIFS(history!$H:$H,history!$C:$C,"tim",history!$D:$D,"control",history!$A:$A,YEAR($A7)&"-"&TEXT(MONTH($A7),"00")&"-"&TEXT(DAY($A7),"00"))),"") | C7: =IFERROR(IF(_xlfn.MINIFS(history!$H:$H,history!$C:$C,"vivo",history!$D:$D,"control",history!$A:$A,YEAR($A7)&"-"&TEXT(MONTH($A7),"00")&"-"&TEXT(DAY($A7),"00"))=0,"",_xlfn.MINIFS(history!$H:$H,history!$C:$C,"vivo",history!$D:$D,"control",history!$A:$A,YEAR($A7)&"-"&TEXT(MONTH($A7),"00")&"-"&TEXT(DAY($A7),"00"))),"") | D7: =IFERROR(IF(_xlfn.MINIFS(history!$H:$H,history!$C:$C,"claro",history!$D:$D,"control",history!$A:$A,YEAR($A7)&"-"&TEXT(MONTH($A7),"00")&"-"&TEXT(DAY($A7),"00"))=0,"",_xlfn.MINIFS(history!$H:$H,history!$C:$C,"claro",history!$D:$D,"control",history!$A:$A,YEAR($A7)&"-"&TEXT(MONTH($A7),"00")&"-"&TEXT(DAY($A7),"00"))),"") | E7: =IFERROR(IF(_xlfn.MINIFS(history!$H:$H,history!$C:$C,"tim",history!$D:$D,"postpaid",history!$A:$A,YEAR($A7)&"-"&TEXT(MONTH($A7),"00")&"-"&TEXT(DAY($A7),"00"))=0,"",_xlfn.MINIFS(history!$H:$H,history!$C:$C,"tim",history!$D:$D,"postpaid",history!$A:$A,YEAR($A7)&"-"&TEXT(MONTH($A7),"00")&"-"&TEXT(DAY($A7),"00"))),"") | F7: =IFERROR(IF(_xlfn.MINIFS(history!$H:$H,history!$C:$C,"vivo",history!$D:$D,"postpaid",history!$A:$A,YEAR($A7)&"-"&TEXT(MONTH($A7),"00")&"-"&TEXT(DAY($A7),"00"))=0,"",_xlfn.MINIFS(history!$H:$H,history!$C:$C,"vivo",history!$D:$D,"postpaid",history!$A:$A,YEAR($A7)&"-"&TEXT(MONTH($A7),"00")&"-"&TEXT(DAY($A7),"00"))),"") | G7: =IFERROR(IF(_xlfn.MINIFS(history!$H:$H,history!$C:$C,"claro",history!$D:$D,"postpaid",history!$A:$A,YEAR($A7)&"-"&TEXT(MONTH($A7),"00")&"-"&TEXT(DAY($A7),"00"))=0,"",_xlfn.MINIFS(history!$H:$H,history!$C:$C,"claro",history!$D:$D,"postpaid",history!$A:$A,YEAR($A7)&"-"&TEXT(MONTH($A7),"00")&"-"&TEXT(DAY($A7),"00"))),"") | H7: =IFERROR(IF(_xlfn.MINIFS(history!$H:$H,history!$C:$C,"tim",history!$D:$D,"prepaid",history!$A:$A,YEAR($A7)&"-"&TEXT(MONTH($A7),"00")&"-"&TEXT(DAY($A7),"00"),history!$M:$M,">=28")=0,"",_xlfn.MINIFS(history!$H:$H,history!$C:$C,"tim",history!$D:$D,"prepaid",history!$A:$A,YEAR($A7)&"-"&TEXT(MONTH($A7),"00")&"-"&TEXT(DAY($A7),"00"),history!$M:$M,">=28")),"") | I7: =IFERROR(IF(_xlfn.MINIFS(history!$H:$H,history!$C:$C,"vivo",history!$D:$D,"prepaid",history!$A:$A,YEAR($A7)&"-"&TEXT(MONTH($A7),"00")&"-"&TEXT(DAY($A7),"00"),history!$M:$M,">=28")=0,"",_xlfn.MINIFS(history!$H:$H,history!$C:$C,"vivo",history!$D:$D,"prepaid",history!$A:$A,YEAR($A7)&"-"&TEXT(MONTH($A7),"00")&"-"&TEXT(DAY($A7),"00"),history!$M:$M,">=28")),"") | J7: =IFERROR(IF(_xlfn.MINIFS(history!$H:$H,history!$C:$C,"claro",history!$D:$D,"prepaid",history!$A:$A,YEAR($A7)&"-"&TEXT(MONTH($A7),"00")&"-"&TEXT(DAY($A7),"00"),history!$M:$M,">=28")=0,"",_xlfn.MINIFS(history!$H:$H,history!$C:$C,"claro",history!$D:$D,"prepaid",history!$A:$A,YEAR($A7)&"-"&TEXT(MONTH($A7),"00")&"-"&TEXT(DAY($A7),"00"),history!$M:$M,">=28")),"") | K7: =IFERROR(1/MAX(IFERROR(1/_xlfn.MINIFS(history!$H:$H,history!$C:$C,"tim",history!$D:$D,"lite",history!$A:$A,YEAR($A7)&"-"&TEXT(MONTH($A7),"00")&"-"&TEXT(DAY($A7),"00")),0),IFERROR(1/_xlfn.MINIFS(history!$H:$H,history!$C:$C,"tim",history!$D:$D,"flex",history!$A:$A,YEAR($A7)&"-"&TEXT(MONTH($A7),"00")&"-"&TEXT(DAY($A7),"00")),0)),"") | L7: =IFERROR(1/MAX(IFERROR(1/_xlfn.MINIFS(history!$H:$H,history!$C:$C,"vivo",history!$D:$D,"lite",history!$A:$A,YEAR($A7)&"-"&TEXT(MONTH($A7),"00")&"-"&TEXT(DAY($A7),"00")),0),IFERROR(1/_xlfn.MINIFS(history!$H:$H,history!$C:$C,"vivo",history!$D:$D,"flex",history!$A:$A,YEAR($A7)&"-"&TEXT(MONTH($A7),"00")&"-"&TEXT(DAY($A7),"00")),0)),"") | M7: =IFERROR(1/MAX(IFERROR(1/_xlfn.MINIFS(history!$H:$H,history!$C:$C,"claro",history!$D:$D,"lite",history!$A:$A,YEAR($A7)&"-"&TEXT(MONTH($A7),"00")&"-"&TEXT(DAY($A7),"00")),0),IFERROR(1/_xlfn.MINIFS(history!$H:$H,history!$C:$C,"claro",history!$D:$D,"flex",history!$A:$A,YEAR($A7)&"-"&TEXT(MONTH($A7),"00")&"-"&TEXT(DAY($A7),"00")),0)),"")
A8: 46200 | B8: =IFERROR(IF(_xlfn.MINIFS(history!$H:$H,history!$C:$C,"tim",history!$D:$D,"control",history!$A:$A,YEAR($A8)&"-"&TEXT(MONTH($A8),"00")&"-"&TEXT(DAY($A8),"00"))=0,"",_xlfn.MINIFS(history!$H:$H,history!$C:$C,"tim",history!$D:$D,"control",history!$A:$A,YEAR($A8)&"-"&TEXT(MONTH($A8),"00")&"-"&TEXT(DAY($A8),"00"))),"") | C8: =IFERROR(IF(_xlfn.MINIFS(history!$H:$H,history!$C:$C,"vivo",history!$D:$D,"control",history!$A:$A,YEAR($A8)&"-"&TEXT(MONTH($A8),"00")&"-"&TEXT(DAY($A8),"00"))=0,"",_xlfn.MINIFS(history!$H:$H,history!$C:$C,"vivo",history!$D:$D,"control",history!$A:$A,YEAR($A8)&"-"&TEXT(MONTH($A8),"00")&"-"&TEXT(DAY($A8),"00"))),"") | D8: =IFERROR(IF(_xlfn.MINIFS(history!$H:$H,history!$C:$C,"claro",history!$D:$D,"control",history!$A:$A,YEAR($A8)&"-"&TEXT(MONTH($A8),"00")&"-"&TEXT(DAY($A8),"00"))=0,"",_xlfn.MINIFS(history!$H:$H,history!$C:$C,"claro",history!$D:$D,"control",history!$A:$A,YEAR($A8)&"-"&TEXT(MONTH($A8),"00")&"-"&TEXT(DAY($A8),"00"))),"") | E8: =IFERROR(IF(_xlfn.MINIFS(history!$H:$H,history!$C:$C,"tim",history!$D:$D,"postpaid",history!$A:$A,YEAR($A8)&"-"&TEXT(MONTH($A8),"00")&"-"&TEXT(DAY($A8),"00"))=0,"",_xlfn.MINIFS(history!$H:$H,history!$C:$C,"tim",history!$D:$D,"postpaid",history!$A:$A,YEAR($A8)&"-"&TEXT(MONTH($A8),"00")&"-"&TEXT(DAY($A8),"00"))),"") | F8: =IFERROR(IF(_xlfn.MINIFS(history!$H:$H,history!$C:$C,"vivo",history!$D:$D,"postpaid",history!$A:$A,YEAR($A8)&"-"&TEXT(MONTH($A8),"00")&"-"&TEXT(DAY($A8),"00"))=0,"",_xlfn.MINIFS(history!$H:$H,history!$C:$C,"vivo",history!$D:$D,"postpaid",history!$A:$A,YEAR($A8)&"-"&TEXT(MONTH($A8),"00")&"-"&TEXT(DAY($A8),"00"))),"") | G8: =IFERROR(IF(_xlfn.MINIFS(history!$H:$H,history!$C:$C,"claro",history!$D:$D,"postpaid",history!$A:$A,YEAR($A8)&"-"&TEXT(MONTH($A8),"00")&"-"&TEXT(DAY($A8),"00"))=0,"",_xlfn.MINIFS(history!$H:$H,history!$C:$C,"claro",history!$D:$D,"postpaid",history!$A:$A,YEAR($A8)&"-"&TEXT(MONTH($A8),"00")&"-"&TEXT(DAY($A8),"00"))),"") | H8: =IFERROR(IF(_xlfn.MINIFS(history!$H:$H,history!$C:$C,"tim",history!$D:$D,"prepaid",history!$A:$A,YEAR($A8)&"-"&TEXT(MONTH($A8),"00")&"-"&TEXT(DAY($A8),"00"),history!$M:$M,">=28")=0,"",_xlfn.MINIFS(history!$H:$H,history!$C:$C,"tim",history!$D:$D,"prepaid",history!$A:$A,YEAR($A8)&"-"&TEXT(MONTH($A8),"00")&"-"&TEXT(DAY($A8),"00"),history!$M:$M,">=28")),"") | I8: =IFERROR(IF(_xlfn.MINIFS(history!$H:$H,history!$C:$C,"vivo",history!$D:$D,"prepaid",history!$A:$A,YEAR($A8)&"-"&TEXT(MONTH($A8),"00")&"-"&TEXT(DAY($A8),"00"),history!$M:$M,">=28")=0,"",_xlfn.MINIFS(history!$H:$H,history!$C:$C,"vivo",history!$D:$D,"prepaid",history!$A:$A,YEAR($A8)&"-"&TEXT(MONTH($A8),"00")&"-"&TEXT(DAY($A8),"00"),history!$M:$M,">=28")),"") | J8: =IFERROR(IF(_xlfn.MINIFS(history!$H:$H,history!$C:$C,"claro",history!$D:$D,"prepaid",history!$A:$A,YEAR($A8)&"-"&TEXT(MONTH($A8),"00")&"-"&TEXT(DAY($A8),"00"),history!$M:$M,">=28")=0,"",_xlfn.MINIFS(history!$H:$H,history!$C:$C,"claro",history!$D:$D,"prepaid",history!$A:$A,YEAR($A8)&"-"&TEXT(MONTH($A8),"00")&"-"&TEXT(DAY($A8),"00"),history!$M:$M,">=28")),"") | K8: =IFERROR(1/MAX(IFERROR(1/_xlfn.MINIFS(history!$H:$H,history!$C:$C,"tim",history!$D:$D,"lite",history!$A:$A,YEAR($A8)&"-"&TEXT(MONTH($A8),"00")&"-"&TEXT(DAY($A8),"00")),0),IFERROR(1/_xlfn.MINIFS(history!$H:$H,history!$C:$C,"tim",history!$D:$D,"flex",history!$A:$A,YEAR($A8)&"-"&TEXT(MONTH($A8),"00")&"-"&TEXT(DAY($A8),"00")),0)),"") | L8: =IFERROR(1/MAX(IFERROR(1/_xlfn.MINIFS(history!$H:$H,history!$C:$C,"vivo",history!$D:$D,"lite",history!$A:$A,YEAR($A8)&"-"&TEXT(MONTH($A8),"00")&"-"&TEXT(DAY($A8),"00")),0),IFERROR(1/_xlfn.MINIFS(history!$H:$H,history!$C:$C,"vivo",history!$D:$D,"flex",history!$A:$A,YEAR($A8)&"-"&TEXT(MONTH($A8),"00")&"-"&TEXT(DAY($A8),"00")),0)),"") | M8: =IFERROR(1/MAX(IFERROR(1/_xlfn.MINIFS(history!$H:$H,history!$C:$C,"claro",history!$D:$D,"lite",history!$A:$A,YEAR($A8)&"-"&TEXT(MONTH($A8),"00")&"-"&TEXT(DAY($A8),"00")),0),IFERROR(1/_xlfn.MINIFS(history!$H:$H,history!$C:$C,"claro",history!$D:$D,"flex",history!$A:$A,YEAR($A8)&"-"&TEXT(MONTH($A8),"00")&"-"&TEXT(DAY($A8),"00")),0)),"")
A9: 46201 | B9: =IFERROR(IF(_xlfn.MINIFS(history!$H:$H,history!$C:$C,"tim",history!$D:$D,"control",history!$A:$A,YEAR($A9)&"-"&TEXT(MONTH($A9),"00")&"-"&TEXT(DAY($A9),"00"))=0,"",_xlfn.MINIFS(history!$H:$H,history!$C:$C,"tim",history!$D:$D,"control",history!$A:$A,YEAR($A9)&"-"&TEXT(MONTH($A9),"00")&"-"&TEXT(DAY($A9),"00"))),"") | C9: =IFERROR(IF(_xlfn.MINIFS(history!$H:$H,history!$C:$C,"vivo",history!$D:$D,"control",history!$A:$A,YEAR($A9)&"-"&TEXT(MONTH($A9),"00")&"-"&TEXT(DAY($A9),"00"))=0,"",_xlfn.MINIFS(history!$H:$H,history!$C:$C,"vivo",history!$D:$D,"control",history!$A:$A,YEAR($A9)&"-"&TEXT(MONTH($A9),"00")&"-"&TEXT(DAY($A9),"00"))),"") | D9: =IFERROR(IF(_xlfn.MINIFS(history!$H:$H,history!$C:$C,"claro",history!$D:$D,"control",history!$A:$A,YEAR($A9)&"-"&TEXT(MONTH($A9),"00")&"-"&TEXT(DAY($A9),"00"))=0,"",_xlfn.MINIFS(history!$H:$H,history!$C:$C,"claro",history!$D:$D,"control",history!$A:$A,YEAR($A9)&"-"&TEXT(MONTH($A9),"00")&"-"&TEXT(DAY($A9),"00"))),"") | E9: =IFERROR(IF(_xlfn.MINIFS(history!$H:$H,history!$C:$C,"tim",history!$D:$D,"postpaid",history!$A:$A,YEAR($A9)&"-"&TEXT(MONTH($A9),"00")&"-"&TEXT(DAY($A9),"00"))=0,"",_xlfn.MINIFS(history!$H:$H,history!$C:$C,"tim",history!$D:$D,"postpaid",history!$A:$A,YEAR($A9)&"-"&TEXT(MONTH($A9),"00")&"-"&TEXT(DAY($A9),"00"))),"") | F9: =IFERROR(IF(_xlfn.MINIFS(history!$H:$H,history!$C:$C,"vivo",history!$D:$D,"postpaid",history!$A:$A,YEAR($A9)&"-"&TEXT(MONTH($A9),"00")&"-"&TEXT(DAY($A9),"00"))=0,"",_xlfn.MINIFS(history!$H:$H,history!$C:$C,"vivo",history!$D:$D,"postpaid",history!$A:$A,YEAR($A9)&"-"&TEXT(MONTH($A9),"00")&"-"&TEXT(DAY($A9),"00"))),"") | G9: =IFERROR(IF(_xlfn.MINIFS(history!$H:$H,history!$C:$C,"claro",history!$D:$D,"postpaid",history!$A:$A,YEAR($A9)&"-"&TEXT(MONTH($A9),"00")&"-"&TEXT(DAY($A9),"00"))=0,"",_xlfn.MINIFS(history!$H:$H,history!$C:$C,"claro",history!$D:$D,"postpaid",history!$A:$A,YEAR($A9)&"-"&TEXT(MONTH($A9),"00")&"-"&TEXT(DAY($A9),"00"))),"") | H9: =IFERROR(IF(_xlfn.MINIFS(history!$H:$H,history!$C:$C,"tim",history!$D:$D,"prepaid",history!$A:$A,YEAR($A9)&"-"&TEXT(MONTH($A9),"00")&"-"&TEXT(DAY($A9),"00"),history!$M:$M,">=28")=0,"",_xlfn.MINIFS(history!$H:$H,history!$C:$C,"tim",history!$D:$D,"prepaid",history!$A:$A,YEAR($A9)&"-"&TEXT(MONTH($A9),"00")&"-"&TEXT(DAY($A9),"00"),history!$M:$M,">=28")),"") | I9: =IFERROR(IF(_xlfn.MINIFS(history!$H:$H,history!$C:$C,"vivo",history!$D:$D,"prepaid",history!$A:$A,YEAR($A9)&"-"&TEXT(MONTH($A9),"00")&"-"&TEXT(DAY($A9),"00"),history!$M:$M,">=28")=0,"",_xlfn.MINIFS(history!$H:$H,history!$C:$C,"vivo",history!$D:$D,"prepaid",history!$A:$A,YEAR($A9)&"-"&TEXT(MONTH($A9),"00")&"-"&TEXT(DAY($A9),"00"),history!$M:$M,">=28")),"") | J9: =IFERROR(IF(_xlfn.MINIFS(history!$H:$H,history!$C:$C,"claro",history!$D:$D,"prepaid",history!$A:$A,YEAR($A9)&"-"&TEXT(MONTH($A9),"00")&"-"&TEXT(DAY($A9),"00"),history!$M:$M,">=28")=0,"",_xlfn.MINIFS(history!$H:$H,history!$C:$C,"claro",history!$D:$D,"prepaid",history!$A:$A,YEAR($A9)&"-"&TEXT(MONTH($A9),"00")&"-"&TEXT(DAY($A9),"00"),history!$M:$M,">=28")),"") | K9: =IFERROR(1/MAX(IFERROR(1/_xlfn.MINIFS(history!$H:$H,history!$C:$C,"tim",history!$D:$D,"lite",history!$A:$A,YEAR($A9)&"-"&TEXT(MONTH($A9),"00")&"-"&TEXT(DAY($A9),"00")),0),IFERROR(1/_xlfn.MINIFS(history!$H:$H,history!$C:$C,"tim",history!$D:$D,"flex",history!$A:$A,YEAR($A9)&"-"&TEXT(MONTH($A9),"00")&"-"&TEXT(DAY($A9),"00")),0)),"") | L9: =IFERROR(1/MAX(IFERROR(1/_xlfn.MINIFS(history!$H:$H,history!$C:$C,"vivo",history!$D:$D,"lite",history!$A:$A,YEAR($A9)&"-"&TEXT(MONTH($A9),"00")&"-"&TEXT(DAY($A9),"00")),0),IFERROR(1/_xlfn.MINIFS(history!$H:$H,history!$C:$C,"vivo",history!$D:$D,"flex",history!$A:$A,YEAR($A9)&"-"&TEXT(MONTH($A9),"00")&"-"&TEXT(DAY($A9),"00")),0)),"") | M9: =IFERROR(1/MAX(IFERROR(1/_xlfn.MINIFS(history!$H:$H,history!$C:$C,"claro",history!$D:$D,"lite",history!$A:$A,YEAR($A9)&"-"&TEXT(MONTH($A9),"00")&"-"&TEXT(DAY($A9),"00")),0),IFERROR(1/_xlfn.MINIFS(history!$H:$H,history!$C:$C,"claro",history!$D:$D,"flex",history!$A:$A,YEAR($A9)&"-"&TEXT(MONTH($A9),"00")&"-"&TEXT(DAY($A9),"00")),0)),"")
A10: 46202 | B10: =IFERROR(IF(_xlfn.MINIFS(history!$H:$H,history!$C:$C,"tim",history!$D:$D,"control",history!$A:$A,YEAR($A10)&"-"&TEXT(MONTH($A10),"00")&"-"&TEXT(DAY($A10),"00"))=0,"",_xlfn.MINIFS(history!$H:$H,history!$C:$C,"tim",history!$D:$D,"control",history!$A:$A,YEAR($A10)&"-"&TEXT(MONTH($A10),"00")&"-"&TEXT(DAY($A10),"00"))),"") | C10: =IFERROR(IF(_xlfn.MINIFS(history!$H:$H,history!$C:$C,"vivo",history!$D:$D,"control",history!$A:$A,YEAR($A10)&"-"&TEXT(MONTH($A10),"00")&"-"&TEXT(DAY($A10),"00"))=0,"",_xlfn.MINIFS(history!$H:$H,history!$C:$C,"vivo",history!$D:$D,"control",history!$A:$A,YEAR($A10)&"-"&TEXT(MONTH($A10),"00")&"-"&TEXT(DAY($A10),"00"))),"") | D10: =IFERROR(IF(_xlfn.MINIFS(history!$H:$H,history!$C:$C,"claro",history!$D:$D,"control",history!$A:$A,YEAR($A10)&"-"&TEXT(MONTH($A10),"00")&"-"&TEXT(DAY($A10),"00"))=0,"",_xlfn.MINIFS(history!$H:$H,history!$C:$C,"claro",history!$D:$D,"control",history!$A:$A,YEAR($A10)&"-"&TEXT(MONTH($A10),"00")&"-"&TEXT(DAY($A10),"00"))),"") | E10: =IFERROR(IF(_xlfn.MINIFS(history!$H:$H,history!$C:$C,"tim",history!$D:$D,"postpaid",history!$A:$A,YEAR($A10)&"-"&TEXT(MONTH($A10),"00")&"-"&TEXT(DAY($A10),"00"))=0,"",_xlfn.MINIFS(history!$H:$H,history!$C:$C,"tim",history!$D:$D,"postpaid",history!$A:$A,YEAR($A10)&"-"&TEXT(MONTH($A10),"00")&"-"&TEXT(DAY($A10),"00"))),"") | F10: =IFERROR(IF(_xlfn.MINIFS(history!$H:$H,history!$C:$C,"vivo",history!$D:$D,"postpaid",history!$A:$A,YEAR($A10)&"-"&TEXT(MONTH($A10),"00")&"-"&TEXT(DAY($A10),"00"))=0,"",_xlfn.MINIFS(history!$H:$H,history!$C:$C,"vivo",history!$D:$D,"postpaid",history!$A:$A,YEAR($A10)&"-"&TEXT(MONTH($A10),"00")&"-"&TEXT(DAY($A10),"00"))),"") | G10: =IFERROR(IF(_xlfn.MINIFS(history!$H:$H,history!$C:$C,"claro",history!$D:$D,"postpaid",history!$A:$A,YEAR($A10)&"-"&TEXT(MONTH($A10),"00")&"-"&TEXT(DAY($A10),"00"))=0,"",_xlfn.MINIFS(history!$H:$H,history!$C:$C,"claro",history!$D:$D,"postpaid",history!$A:$A,YEAR($A10)&"-"&TEXT(MONTH($A10),"00")&"-"&TEXT(DAY($A10),"00"))),"") | H10: =IFERROR(IF(_xlfn.MINIFS(history!$H:$H,history!$C:$C,"tim",history!$D:$D,"prepaid",history!$A:$A,YEAR($A10)&"-"&TEXT(MONTH($A10),"00")&"-"&TEXT(DAY($A10),"00"),history!$M:$M,">=28")=0,"",_xlfn.MINIFS(history!$H:$H,history!$C:$C,"tim",history!$D:$D,"prepaid",history!$A:$A,YEAR($A10)&"-"&TEXT(MONTH($A10),"00")&"-"&TEXT(DAY($A10),"00"),history!$M:$M,">=28")),"") | I10: =IFERROR(IF(_xlfn.MINIFS(history!$H:$H,history!$C:$C,"vivo",history!$D:$D,"prepaid",history!$A:$A,YEAR($A10)&"-"&TEXT(MONTH($A10),"00")&"-"&TEXT(DAY($A10),"00"),history!$M:$M,">=28")=0,"",_xlfn.MINIFS(history!$H:$H,history!$C:$C,"vivo",history!$D:$D,"prepaid",history!$A:$A,YEAR($A10)&"-"&TEXT(MONTH($A10),"00")&"-"&TEXT(DAY($A10),"00"),history!$M:$M,">=28")),"") | J10: =IFERROR(IF(_xlfn.MINIFS(history!$H:$H,history!$C:$C,"claro",history!$D:$D,"prepaid",history!$A:$A,YEAR($A10)&"-"&TEXT(MONTH($A10),"00")&"-"&TEXT(DAY($A10),"00"),history!$M:$M,">=28")=0,"",_xlfn.MINIFS(history!$H:$H,history!$C:$C,"claro",history!$D:$D,"prepaid",history!$A:$A,YEAR($A10)&"-"&TEXT(MONTH($A10),"00")&"-"&TEXT(DAY($A10),"00"),history!$M:$M,">=28")),"") | K10: =IFERROR(1/MAX(IFERROR(1/_xlfn.MINIFS(history!$H:$H,history!$C:$C,"tim",history!$D:$D,"lite",history!$A:$A,YEAR($A10)&"-"&TEXT(MONTH($A10),"00")&"-"&TEXT(DAY($A10),"00")),0),IFERROR(1/_xlfn.MINIFS(history!$H:$H,history!$C:$C,"tim",history!$D:$D,"flex",history!$A:$A,YEAR($A10)&"-"&TEXT(MONTH($A10),"00")&"-"&TEXT(DAY($A10),"00")),0)),"") | L10: =IFERROR(1/MAX(IFERROR(1/_xlfn.MINIFS(history!$H:$H,history!$C:$C,"vivo",history!$D:$D,"lite",history!$A:$A,YEAR($A10)&"-"&TEXT(MONTH($A10),"00")&"-"&TEXT(DAY($A10),"00")),0),IFERROR(1/_xlfn.MINIFS(history!$H:$H,history!$C:$C,"vivo",history!$D:$D,"flex",history!$A:$A,YEAR($A10)&"-"&TEXT(MONTH($A10),"00")&"-"&TEXT(DAY($A10),"00")),0)),"") | M10: =IFERROR(1/MAX(IFERROR(1/_xlfn.MINIFS(history!$H:$H,history!$C:$C,"claro",history!$D:$D,"lite",history!$A:$A,YEAR($A10)&"-"&TEXT(MONTH($A10),"00")&"-"&TEXT(DAY($A10),"00")),0),IFERROR(1/_xlfn.MINIFS(history!$H:$H,history!$C:$C,"claro",history!$D:$D,"flex",history!$A:$A,YEAR($A10)&"-"&TEXT(MONTH($A10),"00")&"-"&TEXT(DAY($A10),"00")),0)),"")
